Workbook

Sheet 项目驾驶舱
A1: 华能交易中心港口交易平台｜项目管理驾驶舱
A3: 统计日期 | B3: 46268
A5: 总任务数 | B5: 已完成 | C5: 进行中 | D5: 未开始 | E5: 暂停 | F5: 平均进度 | G5: 已延期 | H5: 临近到期 | I5: 高风险 | J5: 未关闭问题 | K5: 待决变更 | L5: 里程碑达成 | M5: 集成完成 | N5: 交付物完成
A6: =COUNTA(项目总控台账!$A$4:$A$203) -> 145 | B6: =COUNTIF(项目总控台账!$G$4:$G$203,"已完成") -> 73 | C6: =COUNTIF(项目总控台账!$G$4:$G$203,"进行中") -> 15 | D6: =COUNTIF(项目总控台账!$G$4:$G$203,"未开始") -> 51 | E6: =COUNTIF(项目总控台账!$G$4:$G$203,"暂停") -> 6 | F6: =AVERAGE(项目总控台账!$AB$4:$AB$203) -> 0.55362069 | G6: =COUNTIF(项目总控台账!$AC$4:$AC$203,"已延期") -> 24 | H6: =COUNTIF(项目总控台账!$AC$4:$AC$203,"临近到期") -> 0 | I6: =COUNTIFS(风险问题台账!$D$4:$D$103,"高",风险问题台账!$K$4:$K$103,"<>已关闭") -> 5 | J6: =COUNTIF(风险问题台账!$K$4:$K$103,"处理中")+COUNTIF(风险问题台账!$K$4:$K$103,"待处理") -> 6 | K6: =COUNTIF(变更台账!$G$4:$G$53,"评估中")+COUNTIF(变更台账!$G$4:$G$53,"待审批") -> 0 | L6: =IFERROR(COUNTIF(里程碑计划!$G$4:$G$23,"已完成")/COUNTA(里程碑计划!$A$4:$A$23),0) -> 0 | M6: =IFERROR(COUNTIF(集成管理!$G$4:$G$53,"已完成")/COUNTA(集成管理!$A$4:$A$53),0) -> 0.33333333 | N6: =IFERROR(COUNTIF(交付物台账!$G$4:$G$53,"已完成")/COUNTA(交付物台账!$A$4:$A$53),0) -> 0
A7: 综合进度 | D7: 任务完成率 | G7: 计划投入人天 | J7: 计划人工成本 | M7: 人日单价
A8: =AVERAGE(项目总控台账!$AB$4:$AB$148) -> 0.55362069 | D8: =COUNTIF(项目总控台账!$G$4:$G$148,"已完成")/COUNTIF(项目总控台账!$A$4:$A$148,"<>") -> 0.50344828 | G8: =SUM(资源计划!$H$5:$H$10)/8 -> 485 | J8: =G8*M8 -> 582000 | M8: 1200
A9: 状态 | B9: 任务数 | D9: 批次 | E9: 任务数 | F9: 已完成 | G9: 完成率
A10: 已完成 | B10: =B6 -> 73 | D10: 第一批次 | E10: =COUNTIF(项目总控台账!$F$4:$F$203,D10) -> 61 | F10: =COUNTIFS(项目总控台账!$F$4:$F$203,D10,项目总控台账!$G$4:$G$203,"已完成") -> 57 | G10: =IFERROR(F10/E10,0) -> 0.93442623
A11: 进行中 | B11: =C6 -> 15 | D11: 第二批次 | E11: =COUNTIF(项目总控台账!$F$4:$F$203,D11) -> 78 | F11: =COUNTIFS(项目总控台账!$F$4:$F$203,D11,项目总控台账!$G$4:$G$203,"已完成") -> 16 | G11: =IFERROR(F11/E11,0) -> 0.20512821
A12: 未开始 | B12: =D6 -> 51 | D12: 其他 | E12: =$A$6-E10-E11 -> 6 | F12: =$B$6-F10-F11 -> 0 | G12: =IFERROR(F12/E12,0) -> 0
A13: 暂停 | B13: =E6 -> 6
A16: 管理关注点
A17: ="截至 "&TEXT($B$3,"yyyy-mm-dd")&"：延期任务 "&G6&" 项，临近到期 "&H6&" 项，高风险 "&I6&" 项。建议优先处理外部系统集成依赖、第二批次未启动任务及无明确上线日期的功能。" -> 截至 2026-09-03：延期任务 24 项，临近到期 0 项，高风险 5 项。建议优先处理外部系统集成依赖、第二批次未启动任务及无明确上线日期的功能。

Sheet 项目总控台账
A1: 华能交易中心港口交易平台｜项目总控台账
A2: 蓝色字段来自原开发计划；黄色字段为管理补充项；进度与延期由公式自动计算。
A3: 任务ID | B3: 一级功能 | C3: 二级功能 | D3: 三级功能 | E3: 四级功能 | F3: 批次 | G3: 总体状态 | H3: 主责人 | I3: 计划开始 | J3: 计划完成 | K3: 计划上线 | L3: 业务负责人 | M3: 业务状态 | N3: 业务开始 | O3: 业务结束 | P3: 后端负责人 | Q3: 后端状态 | R3: 后端开始 | S3: 后端结束 | T3: 前端负责人 | U3: 前端状态 | V3: 前端开始 | W3: 前端结束 | X3: 测试负责人 | Y3: 测试状态 | Z3: 测试开始 | AA3: 测试结束 | AB3: 综合进度 | AC3: 延期状态 | AD3: 当前问题/阻塞 | AE3: 备注
A4: T001 | B4: 基础数据 | C4: 车辆信息维护 | D4: 新增车辆信息 | E4: / | F4: 第一批次 | G4: =IF(OR(M4="挂起",M4="暂停",Q4="挂起",Q4="暂停",U4="挂起",U4="暂停",Y4="挂起",Y4="暂停"),"暂停","已完成") -> 已完成 | H4: =IF(L4<>"",L4,IF(P4<>"",P4,IF(T4<>"",T4,X4))) -> 郑士旺 | I4: =IF(COUNT(N4,R4,V4,Z4)=0,"",MIN(N4,R4,V4,Z4)) -> 46202 | J4: =IF(ISNUMBER(K4),K4,IF(COUNT(O4,S4,W4,AA4)=0,"",MAX(O4,S4,W4,AA4))) -> 46234 | K4: / | L4: 郑士旺 | M4: 已完成 | N4: 46202 | O4: 46206 | P4: 石军磊、刘凯 | Q4: 已完成 | R4: 46209 | S4: 46225 | T4: 贺航 | U4: 已完成 | V4: 46209 | W4: 46225 | X4: 袁丽荣 | Y4: 已完成 | Z4: 46216 | AA4: 46234 | AB4: =(IF(M4="已完成",1,IF(M4="进行中",0.5,0))*15%+IF(Q4="已完成",1,IF(Q4="进行中",0.5,0))*35%+IF(U4="已完成",1,IF(U4="进行中",0.5,0))*30%+IF(Y4="已完成",1,IF(Y4="进行中",0.5,0))*20%) -> 1 | AC4: =IF(G4="已完成","正常",IF(OR(G4="暂停",G4="挂起"),"暂停",IF(J4="","日期缺失",IF(J4<项目驾驶舱!$B$3,"已延期",IF(J4<=项目驾驶舱!$B$3+7,"临近到期","正常"))))) -> 正常 | AD4: 69 | AE4: 69
A5: T002 | B5: 基础数据 | C5: 车辆信息维护 | D5: 修改车辆信息 | E5: / | F5: 第一批次 | G5: =IF(OR(M5="挂起",M5="暂停",Q5="挂起",Q5="暂停",U5="挂起",U5="暂停",Y5="挂起",Y5="暂停"),"暂停","已完成") -> 已完成 | H5: =IF(L5<>"",L5,IF(P5<>"",P5,IF(T5<>"",T5,X5))) -> 郑士旺 | I5: =IF(COUNT(N5,R5,V5,Z5)=0,"",MIN(N5,R5,V5,Z5)) -> 46202 | J5: =IF(ISNUMBER(K5),K5,IF(COUNT(O5,S5,W5,AA5)=0,"",MAX(O5,S5,W5,AA5))) -> 46234 | K5: / | L5: 郑士旺 | M5: 已完成 | N5: 46202 | O5: 46206 | P5: 石军磊、刘凯 | Q5: 已完成 | R5: 46209 | S5: 46225 | T5: 贺航 | U5: 已完成 | V5: 46209 | W5: 46225 | X5: 袁丽荣 | Y5: 已完成 | Z5: 46216 | AA5: 46234 | AB5: =(IF(M5="已完成",1,IF(M5="进行中",0.5,0))*15%+IF(Q5="已完成",1,IF(Q5="进行中",0.5,0))*35%+IF(U5="已完成",1,IF(U5="进行中",0.5,0))*30%+IF(Y5="已完成",1,IF(Y5="进行中",0.5,0))*20%) -> 1 | AC5: =IF(G5="已完成","正常",IF(OR(G5="暂停",G5="挂起"),"暂停",IF(J5="","日期缺失",IF(J5<项目驾驶舱!$B$3,"已延期",IF(J5<=项目驾驶舱!$B$3+7,"临近到期","正常"))))) -> 正常 | AD5: 69 | AE5: 69
A6: T003 | B6: 基础数据 | C6: 车辆信息维护 | D6: 删除车辆信息 | E6: / | F6: 第一批次 | G6: =IF(OR(M6="挂起",M6="暂停",Q6="挂起",Q6="暂停",U6="挂起",U6="暂停",Y6="挂起",Y6="暂停"),"暂停","已完成") -> 已完成 | H6: =IF(L6<>"",L6,IF(P6<>"",P6,IF(T6<>"",T6,X6))) -> 郑士旺 | I6: =IF(COUNT(N6,R6,V6,Z6)=0,"",MIN(N6,R6,V6,Z6)) -> 46202 | J6: =IF(ISNUMBER(K6),K6,IF(COUNT(O6,S6,W6,AA6)=0,"",MAX(O6,S6,W6,AA6))) -> 46234 | K6: / | L6: 郑士旺 | M6: 已完成 | N6: 46202 | O6: 46206 | P6: 石军磊、刘凯 | Q6: 已完成 | R6: 46209 | S6: 46225 | T6: 贺航 | U6: 已完成 | V6: 46209 | W6: 46225 | X6: 袁丽荣 | Y6: 已完成 | Z6: 46216 | AA6: 46234 | AB6: =(IF(M6="已完成",1,IF(M6="进行中",0.5,0))*15%+IF(Q6="已完成",1,IF(Q6="进行中",0.5,0))*35%+IF(U6="已完成",1,IF(U6="进行中",0.5,0))*30%+IF(Y6="已完成",1,IF(Y6="进行中",0.5,0))*20%) -> 1 | AC6: =IF(G6="已完成","正常",IF(OR(G6="暂停",G6="挂起"),"暂停",IF(J6="","日期缺失",IF(J6<项目驾驶舱!$B$3,"已延期",IF(J6<=项目驾驶舱!$B$3+7,"临近到期","正常"))))) -> 正常 | AD6: 69 | AE6: 69
A7: T004 | B7: 基础数据 | C7: 车辆信息维护 | D7: 查询展示车辆信息 | E7: / | F7: 第一批次 | G7: =IF(OR(M7="挂起",M7="暂停",Q7="挂起",Q7="暂停",U7="挂起",U7="暂停",Y7="挂起",Y7="暂停"),"暂停","已完成") -> 已完成 | H7: =IF(L7<>"",L7,IF(P7<>"",P7,IF(T7<>"",T7,X7))) -> 郑士旺 | I7: =IF(COUNT(N7,R7,V7,Z7)=0,"",MIN(N7,R7,V7,Z7)) -> 46202 | J7: =IF(ISNUMBER(K7),K7,IF(COUNT(O7,S7,W7,AA7)=0,"",MAX(O7,S7,W7,AA7))) -> 46234 | K7: / | L7: 郑士旺 | M7: 已完成 | N7: 46202 | O7: 46206 | P7: 石军磊、刘凯 | Q7: 已完成 | R7: 46209 | S7: 46225 | T7: 贺航 | U7: 已完成 | V7: 46209 | W7: 46225 | X7: 袁丽荣 | Y7: 已完成 | Z7: 46216 | AA7: 46234 | AB7: =(IF(M7="已完成",1,IF(M7="进行中",0.5,0))*15%+IF(Q7="已完成",1,IF(Q7="进行中",0.5,0))*35%+IF(U7="已完成",1,IF(U7="进行中",0.5,0))*30%+IF(Y7="已完成",1,IF(Y7="进行中",0.5,0))*20%) -> 1 | AC7: =IF(G7="已完成","正常",IF(OR(G7="暂停",G7="挂起"),"暂停",IF(J7="","日期缺失",IF(J7<项目驾驶舱!$B$3,"已延期",IF(J7<=项目驾驶舱!$B$3+7,"临近到期","正常"))))) -> 正常 | AD7: 69 | AE7: 69
A8: T005 | B8: 基础数据 | C8: 船舶信息维护 | D8: 船舶唯一性校验 | E8: / | F8: 第二批次 | G8: =IF(OR(M8="挂起",M8="暂停",Q8="挂起",Q8="暂停",U8="挂起",U8="暂停",Y8="挂起",Y8="暂停"),"暂停","已完成") -> 已完成 | H8: =IF(L8<>"",L8,IF(P8<>"",P8,IF(T8<>"",T8,X8))) -> 郑士旺 | I8: =IF(COUNT(N8,R8,V8,Z8)=0,"",MIN(N8,R8,V8,Z8)) -> 46230 | J8: =IF(ISNUMBER(K8),K8,IF(COUNT(O8,S8,W8,AA8)=0,"",MAX(O8,S8,W8,AA8))) -> 46353 | K8: / | L8: 郑士旺 | M8: 已完成 | N8: 46230 | O8: 46241 | P8: 石军磊、刘凯 | Q8: 已完成 | R8: 46307 | S8: 46339 | T8: 贺航 | U8: 已完成 | V8: 46307 | W8: 46339 | X8: 袁丽荣 | Y8: 已完成 | Z8: 46342 | AA8: 46353 | AB8: =(IF(M8="已完成",1,IF(M8="进行中",0.5,0))*15%+IF(Q8="已完成",1,IF(Q8="进行中",0.5,0))*35%+IF(U8="已完成",1,IF(U8="进行中",0.5,0))*30%+IF(Y8="已完成",1,IF(Y8="进行中",0.5,0))*20%) -> 1 | AC8: =IF(G8="已完成","正常",IF(OR(G8="暂停",G8="挂起"),"暂停",IF(J8="","日期缺失",IF(J8<项目驾驶舱!$B$3,"已延期",IF(J8<=项目驾驶舱!$B$3+7,"临近到期","正常"))))) -> 正常 | AD8: 69 | AE8: 69
A9: T006 | B9: 基础数据 | C9: 收费标准信息维护 | D9: 优化收费标准（装卸费）新增 | E9: / | F9: 第一批次 | G9: =IF(OR(M9="挂起",M9="暂停",Q9="挂起",Q9="暂停",U9="挂起",U9="暂停",Y9="挂起",Y9="暂停"),"暂停","已完成") -> 已完成 | H9: =IF(L9<>"",L9,IF(P9<>"",P9,IF(T9<>"",T9,X9))) -> 郑士旺 | I9: =IF(COUNT(N9,R9,V9,Z9)=0,"",MIN(N9,R9,V9,Z9)) -> 46202 | J9: =IF(ISNUMBER(K9),K9,IF(COUNT(O9,S9,W9,AA9)=0,"",MAX(O9,S9,W9,AA9))) -> 46224 | K9: 46224 | L9: 郑士旺 | M9: 已完成 | N9: 46202 | O9: 46206 | P9: 石军磊、刘凯 | Q9: 已完成 | R9: 46209 | S9: 46227 | T9: 贺航 | U9: 已完成 | V9: 46209 | W9: 46227 | X9: 袁丽荣 | Y9: 已完成 | Z9: 46216 | AA9: 46234 | AB9: =(IF(M9="已完成",1,IF(M9="进行中",0.5,0))*15%+IF(Q9="已完成",1,IF(Q9="进行中",0.5,0))*35%+IF(U9="已完成",1,IF(U9="进行中",0.5,0))*30%+IF(Y9="已完成",1,IF(Y9="进行中",0.5,0))*20%) -> 1 | AC9: =IF(G9="已完成","正常",IF(OR(G9="暂停",G9="挂起"),"暂停",IF(J9="","日期缺失",IF(J9<项目驾驶舱!$B$3,"已延期",IF(J9<=项目驾驶舱!$B$3+7,"临近到期","正常"))))) -> 正常 | AD9: 69 | AE9: 69
A10: T007 | B10: 基础数据 | C10: 收费标准信息维护 | D10: 优化收费标准（装卸费）编辑 | E10: / | F10: 第一批次 | G10: =IF(OR(M10="挂起",M10="暂停",Q10="挂起",Q10="暂停",U10="挂起",U10="暂停",Y10="挂起",Y10="暂停"),"暂停","已完成") -> 已完成 | H10: =IF(L10<>"",L10,IF(P10<>"",P10,IF(T10<>"",T10,X10))) -> 郑士旺 | I10: =IF(COUNT(N10,R10,V10,Z10)=0,"",MIN(N10,R10,V10,Z10)) -> 46202 | J10: =IF(ISNUMBER(K10),K10,IF(COUNT(O10,S10,W10,AA10)=0,"",MAX(O10,S10,W10,AA10))) -> 46224 | K10: 46224 | L10: 郑士旺 | M10: 已完成 | N10: 46202 | O10: 46206 | P10: 石军磊、刘凯 | Q10: 已完成 | R10: 46209 | S10: 46227 | T10: 贺航 | U10: 已完成 | V10: 46209 | W10: 46227 | X10: 袁丽荣 | Y10: 已完成 | Z10: 46216 | AA10: 46234 | AB10: =(IF(M10="已完成",1,IF(M10="进行中",0.5,0))*15%+IF(Q10="已完成",1,IF(Q10="进行中",0.5,0))*35%+IF(U10="已完成",1,IF(U10="进行中",0.5,0))*30%+IF(Y10="已完成",1,IF(Y10="进行中",0.5,0))*20%) -> 1 | AC10: =IF(G10="已完成","正常",IF(OR(G10="暂停",G10="挂起"),"暂停",IF(J10="","日期缺失",IF(J10<项目驾驶舱!$B$3,"已延期",IF(J10<=项目驾驶舱!$B$3+7,"临近到期","正常"))))) -> 正常 | AD10: 69 | AE10: 69
A11: T008 | B11: 基础数据 | C11: 收费标准信息维护 | D11: 优化收费标准（装卸费）详情 | E11: / | F11: 第一批次 | G11: =IF(OR(M11="挂起",M11="暂停",Q11="挂起",Q11="暂停",U11="挂起",U11="暂停",Y11="挂起",Y11="暂停"),"暂停","已完成") -> 已完成 | H11: =IF(L11<>"",L11,IF(P11<>"",P11,IF(T11<>"",T11,X11))) -> 郑士旺 | I11: =IF(COUNT(N11,R11,V11,Z11)=0,"",MIN(N11,R11,V11,Z11)) -> 46202 | J11: =IF(ISNUMBER(K11),K11,IF(COUNT(O11,S11,W11,AA11)=0,"",MAX(O11,S11,W11,AA11))) -> 46224 | K11: 46224 | L11: 郑士旺 | M11: 已完成 | N11: 46202 | O11: 46206 | P11: 石军磊、刘凯 | Q11: 已完成 | R11: 46209 | S11: 46227 | T11: 贺航 | U11: 已完成 | V11: 46209 | W11: 46227 | X11: 袁丽荣 | Y11: 已完成 | Z11: 46216 | AA11: 46234 | AB11: =(IF(M11="已完成",1,IF(M11="进行中",0.5,0))*15%+IF(Q11="已完成",1,IF(Q11="进行中",0.5,0))*35%+IF(U11="已完成",1,IF(U11="进行中",0.5,0))*30%+IF(Y11="已完成",1,IF(Y11="进行中",0.5,0))*20%) -> 1 | AC11: =IF(G11="已完成","正常",IF(OR(G11="暂停",G11="挂起"),"暂停",IF(J11="","日期缺失",IF(J11<项目驾驶舱!$B$3,"已延期",IF(J11<=项目驾驶舱!$B$3+7,"临近到期","正常"))))) -> 正常 | AD11: 69 | AE11: 69
A12: T009 | B12: 基础数据 | C12: 采样方式信息维护 | D12: 优化采样方式新增 | E12: / | F12: 第一批次 | G12: =IF(OR(M12="挂起",M12="暂停",Q12="挂起",Q12="暂停",U12="挂起",U12="暂停",Y12="挂起",Y12="暂停"),"暂停","已完成") -> 已完成 | H12: =IF(L12<>"",L12,IF(P12<>"",P12,IF(T12<>"",T12,X12))) -> 郑士旺 | I12: =IF(COUNT(N12,R12,V12,Z12)=0,"",MIN(N12,R12,V12,Z12)) -> 46202 | J12: =IF(ISNUMBER(K12),K12,IF(COUNT(O12,S12,W12,AA12)=0,"",MAX(O12,S12,W12,AA12))) -> 46224 | K12: 46224 | L12: 郑士旺 | M12: 已完成 | N12: 46202 | O12: 46206 | P12: 石军磊、刘凯 | Q12: 已完成 | R12: 46209 | S12: 46227 | T12: 贺航 | U12: 已完成 | V12: 46209 | W12: 46227 | X12: 袁丽荣 | Y12: 已完成 | Z12: 46216 | AA12: 46234 | AB12: =(IF(M12="已完成",1,IF(M12="进行中",0.5,0))*15%+IF(Q12="已完成",1,IF(Q12="进行中",0.5,0))*35%+IF(U12="已完成",1,IF(U12="进行中",0.5,0))*30%+IF(Y12="已完成",1,IF(Y12="进行中",0.5,0))*20%) -> 1 | AC12: =IF(G12="已完成","正常",IF(OR(G12="暂停",G12="挂起"),"暂停",IF(J12="","日期缺失",IF(J12<项目驾驶舱!$B$3,"已延期",IF(J12<=项目驾驶舱!$B$3+7,"临近到期","正常"))))) -> 正常 | AD12: 69 | AE12: 69
A13: T010 | B13: 基础数据 | C13: 采样方式信息维护 | D13: 优化采样方式编辑 | E13: / | F13: 第一批次 | G13: =IF(OR(M13="挂起",M13="暂停",Q13="挂起",Q13="暂停",U13="挂起",U13="暂停",Y13="挂起",Y13="暂停"),"暂停","已完成") -> 已完成 | H13: =IF(L13<>"",L13,IF(P13<>"",P13,IF(T13<>"",T13,X13))) -> 郑士旺 | I13: =IF(COUNT(N13,R13,V13,Z13)=0,"",MIN(N13,R13,V13,Z13)) -> 46202 | J13: =IF(ISNUMBER(K13),K13,IF(COUNT(O13,S13,W13,AA13)=0,"",MAX(O13,S13,W13,AA13))) -> 46224 | K13: 46224 | L13: 郑士旺 | M13: 已完成 | N13: 46202 | O13: 46206 | P13: 石军磊、刘凯 | Q13: 已完成 | R13: 46209 | S13: 46227 | T13: 贺航 | U13: 已完成 | V13: 46209 | W13: 46227 | X13: 袁丽荣 | Y13: 已完成 | Z13: 46216 | AA13: 46234 | AB13: =(IF(M13="已完成",1,IF(M13="进行中",0.5,0))*15%+IF(Q13="已完成",1,IF(Q13="进行中",0.5,0))*35%+IF(U13="已完成",1,IF(U13="进行中",0.5,0))*30%+IF(Y13="已完成",1,IF(Y13="进行中",0.5,0))*20%) -> 1 | AC13: =IF(G13="已完成","正常",IF(OR(G13="暂停",G13="挂起"),"暂停",IF(J13="","日期缺失",IF(J13<项目驾驶舱!$B$3,"已延期",IF(J13<=项目驾驶舱!$B$3+7,"临近到期","正常"))))) -> 正常 | AD13: 69 | AE13: 69
A14: T011 | B14: 网上营业厅 | C14: 交易中心报单信息展示及应单入口 | D14: 获取报单数据及展示 | E14: / | F14: 第一批次 | G14: =IF(OR(M14="挂起",M14="暂停",Q14="挂起",Q14="暂停",U14="挂起",U14="暂停",Y14="挂起",Y14="暂停"),"暂停","已完成") -> 已完成 | H14: =IF(L14<>"",L14,IF(P14<>"",P14,IF(T14<>"",T14,X14))) -> 郑士旺 | I14: =IF(COUNT(N14,R14,V14,Z14)=0,"",MIN(N14,R14,V14,Z14)) -> 46202 | J14: =IF(ISNUMBER(K14),K14,IF(COUNT(O14,S14,W14,AA14)=0,"",MAX(O14,S14,W14,AA14))) -> 46224 | K14: 46224 | L14: 郑士旺 | M14: 已完成 | N14: 46202 | O14: 46206 | P14: 石军磊、刘凯 | Q14: 已完成 | R14: 46209 | S14: 46227 | T14: 贺航 | U14: 已完成 | V14: 46209 | W14: 46225 | X14: 袁丽荣 | Y14: 已完成 | Z14: 46216 | AA14: 46234 | AB14: =(IF(M14="已完成",1,IF(M14="进行中",0.5,0))*15%+IF(Q14="已完成",1,IF(Q14="进行中",0.5,0))*35%+IF(U14="已完成",1,IF(U14="进行中",0.5,0))*30%+IF(Y14="已完成",1,IF(Y14="进行中",0.5,0))*20%) -> 1 | AC14: =IF(G14="已完成","正常",IF(OR(G14="暂停",G14="挂起"),"暂停",IF(J14="","日期缺失",IF(J14<项目驾驶舱!$B$3,"已延期",IF(J14<=项目驾驶舱!$B$3+7,"临近到期","正常"))))) -> 正常 | AD14: 69 | AE14: 69
A15: T012 | B15: 网上营业厅 | C15: 交易中心报单信息展示及应单入口 | D15: 应单入口 | E15: / | F15: 第一批次 | G15: =IF(OR(M15="挂起",M15="暂停",Q15="挂起",Q15="暂停",U15="挂起",U15="暂停",Y15="挂起",Y15="暂停"),"暂停","已完成") -> 已完成 | H15: =IF(L15<>"",L15,IF(P15<>"",P15,IF(T15<>"",T15,X15))) -> 郑士旺 | I15: =IF(COUNT(N15,R15,V15,Z15)=0,"",MIN(N15,R15,V15,Z15)) -> 46202 | J15: =IF(ISNUMBER(K15),K15,IF(COUNT(O15,S15,W15,AA15)=0,"",MAX(O15,S15,W15,AA15))) -> 46224 | K15: 46224 | L15: 郑士旺 | M15: 已完成 | N15: 46202 | O15: 46206 | P15: 石军磊、刘凯 | Q15: 已完成 | R15: 46209 | S15: 46227 | T15: 贺航 | U15: 已完成 | V15: 46209 | W15: 46225 | X15: 袁丽荣 | Y15: 已完成 | Z15: 46216 | AA15: 46234 | AB15: =(IF(M15="已完成",1,IF(M15="进行中",0.5,0))*15%+IF(Q15="已完成",1,IF(Q15="进行中",0.5,0))*35%+IF(U15="已完成",1,IF(U15="进行中",0.5,0))*30%+IF(Y15="已完成",1,IF(Y15="进行中",0.5,0))*20%) -> 1 | AC15: =IF(G15="已完成","正常",IF(OR(G15="暂停",G15="挂起"),"暂停",IF(J15="","日期缺失",IF(J15<项目驾驶舱!$B$3,"已延期",IF(J15<=项目驾驶舱!$B$3+7,"临近到期","正常"))))) -> 正常 | AD15: 69 | AE15: 69
A16: T013 | B16: 网上营业厅 | C16: 结算条款管理 | D16: 新增结算条款 | E16: / | F16: 第二批次 | G16: =IF(OR(M16="挂起",M16="暂停",Q16="挂起",Q16="暂停",U16="挂起",U16="暂停",Y16="挂起",Y16="暂停"),"暂停","未开始") -> 未开始 | H16: =IF(L16<>"",L16,IF(P16<>"",P16,IF(T16<>"",T16,X16))) -> 郑士旺 | I16: =IF(COUNT(N16,R16,V16,Z16)=0,"",MIN(N16,R16,V16,Z16)) -> 46223 | J16: =IF(ISNUMBER(K16),K16,IF(COUNT(O16,S16,W16,AA16)=0,"",MAX(O16,S16,W16,AA16))) -> 46318 | L16: 郑士旺 | M16: 未开始 | N16: 46223 | O16: 46227 | P16: 石军磊、刘凯 | Q16: 未开始 | R16: 46272 | S16: 46304 | T16: 贺航 | U16: 未开始 | V16: 46272 | W16: 46304 | X16: 袁丽荣 | Y16: 未开始 | Z16: 46307 | AA16: 46318 | AB16: =(IF(M16="已完成",1,IF(M16="进行中",0.5,0))*15%+IF(Q16="已完成",1,IF(Q16="进行中",0.5,0))*35%+IF(U16="已完成",1,IF(U16="进行中",0.5,0))*30%+IF(Y16="已完成",1,IF(Y16="进行中",0.5,0))*20%) -> 0 | AC16: =IF(G16="已完成","正常",IF(OR(G16="暂停",G16="挂起"),"暂停",IF(J16="","日期缺失",IF(J16<项目驾驶舱!$B$3,"已延期",IF(J16<=项目驾驶舱!$B$3+7,"临近到期","正常"))))) -> 正常 | AD16: 69 | AE16: 69
A17: T014 | B17: 网上营业厅 | C17: 结算条款管理 | D17: 结算条款审批 | E17: / | F17: 第二批次 | G17: =IF(OR(M17="挂起",M17="暂停",Q17="挂起",Q17="暂停",U17="挂起",U17="暂停",Y17="挂起",Y17="暂停"),"暂停","未开始") -> 未开始 | H17: =IF(L17<>"",L17,IF(P17<>"",P17,IF(T17<>"",T17,X17))) -> 郑士旺 | I17: =IF(COUNT(N17,R17,V17,Z17)=0,"",MIN(N17,R17,V17,Z17)) -> 46223 | J17: =IF(ISNUMBER(K17),K17,IF(COUNT(O17,S17,W17,AA17)=0,"",MAX(O17,S17,W17,AA17))) -> 46318 | L17: 郑士旺 | M17: 未开始 | N17: 46223 | O17: 46227 | P17: 石军磊、刘凯 | Q17: 未开始 | R17: 46272 | S17: 46304 | T17: 贺航 | U17: 未开始 | V17: 46272 | W17: 46304 | X17: 袁丽荣 | Y17: 未开始 | Z17: 46307 | AA17: 46318 | AB17: =(IF(M17="已完成",1,IF(M17="进行中",0.5,0))*15%+IF(Q17="已完成",1,IF(Q17="进行中",0.5,0))*35%+IF(U17="已完成",1,IF(U17="进行中",0.5,0))*30%+IF(Y17="已完成",1,IF(Y17="进行中",0.5,0))*20%) -> 0 | AC17: =IF(G17="已完成","正常",IF(OR(G17="暂停",G17="挂起"),"暂停",IF(J17="","日期缺失",IF(J17<项目驾驶舱!$B$3,"已延期",IF(J17<=项目驾驶舱!$B$3+7,"临近到期","正常"))))) -> 正常 | AD17: 69 | AE17: 69
A18: T015 | B18: 网上营业厅 | C18: 结算条款管理 | D18: 修改结算条款 | E18: / | F18: 第二批次 | G18: =IF(OR(M18="挂起",M18="暂停",Q18="挂起",Q18="暂停",U18="挂起",U18="暂停",Y18="挂起",Y18="暂停"),"暂停","未开始") -> 未开始 | H18: =IF(L18<>"",L18,IF(P18<>"",P18,IF(T18<>"",T18,X18))) -> 郑士旺 | I18: =IF(COUNT(N18,R18,V18,Z18)=0,"",MIN(N18,R18,V18,Z18)) -> 46223 | J18: =IF(ISNUMBER(K18),K18,IF(COUNT(O18,S18,W18,AA18)=0,"",MAX(O18,S18,W18,AA18))) -> 46318 | L18: 郑士旺 | M18: 未开始 | N18: 46223 | O18: 46227 | P18: 石军磊、刘凯 | Q18: 未开始 | R18: 46272 | S18: 46304 | T18: 贺航 | U18: 未开始 | V18: 46272 | W18: 46304 | X18: 袁丽荣 | Y18: 未开始 | Z18: 46307 | AA18: 46318 | AB18: =(IF(M18="已完成",1,IF(M18="进行中",0.5,0))*15%+IF(Q18="已完成",1,IF(Q18="进行中",0.5,0))*35%+IF(U18="已完成",1,IF(U18="进行中",0.5,0))*30%+IF(Y18="已完成",1,IF(Y18="进行中",0.5,0))*20%) -> 0 | AC18: =IF(G18="已完成","正常",IF(OR(G18="暂停",G18="挂起"),"暂停",IF(J18="","日期缺失",IF(J18<项目驾驶舱!$B$3,"已延期",IF(J18<=项目驾驶舱!$B$3+7,"临近到期","正常"))))) -> 正常 | AD18: 69 | AE18: 69
A19: T016 | B19: 网上营业厅 | C19: 结算条款管理 | D19: 删除结算条款 | E19: / | F19: 第二批次 | G19: =IF(OR(M19="挂起",M19="暂停",Q19="挂起",Q19="暂停",U19="挂起",U19="暂停",Y19="挂起",Y19="暂停"),"暂停","未开始") -> 未开始 | H19: =IF(L19<>"",L19,IF(P19<>"",P19,IF(T19<>"",T19,X19))) -> 郑士旺 | I19: =IF(COUNT(N19,R19,V19,Z19)=0,"",MIN(N19,R19,V19,Z19)) -> 46223 | J19: =IF(ISNUMBER(K19),K19,IF(COUNT(O19,S19,W19,AA19)=0,"",MAX(O19,S19,W19,AA19))) -> 46318 | L19: 郑士旺 | M19: 未开始 | N19: 46223 | O19: 46227 | P19: 石军磊、刘凯 | Q19: 未开始 | R19: 46272 | S19: 46304 | T19: 贺航 | U19: 未开始 | V19: 46272 | W19: 46304 | X19: 袁丽荣 | Y19: 未开始 | Z19: 46307 | AA19: 46318 | AB19: =(IF(M19="已完成",1,IF(M19="进行中",0.5,0))*15%+IF(Q19="已完成",1,IF(Q19="进行中",0.5,0))*35%+IF(U19="已完成",1,IF(U19="进行中",0.5,0))*30%+IF(Y19="已完成",1,IF(Y19="进行中",0.5,0))*20%) -> 0 | AC19: =IF(G19="已完成","正常",IF(OR(G19="暂停",G19="挂起"),"暂停",IF(J19="","日期缺失",IF(J19<项目驾驶舱!$B$3,"已延期",IF(J19<=项目驾驶舱!$B$3+7,"临近到期","正常"))))) -> 正常 | AD19: 69 | AE19: 69
A20: T017 | B20: 网上营业厅 | C20: 结算条款管理 | D20: 查询展示结算条款 | E20: / | F20: 第二批次 | G20: =IF(OR(M20="挂起",M20="暂停",Q20="挂起",Q20="暂停",U20="挂起",U20="暂停",Y20="挂起",Y20="暂停"),"暂停","未开始") -> 未开始 | H20: =IF(L20<>"",L20,IF(P20<>"",P20,IF(T20<>"",T20,X20))) -> 郑士旺 | I20: =IF(COUNT(N20,R20,V20,Z20)=0,"",MIN(N20,R20,V20,Z20)) -> 46223 | J20: =IF(ISNUMBER(K20),K20,IF(COUNT(O20,S20,W20,AA20)=0,"",MAX(O20,S20,W20,AA20))) -> 46318 | L20: 郑士旺 | M20: 未开始 | N20: 46223 | O20: 46227 | P20: 石军磊、刘凯 | Q20: 未开始 | R20: 46272 | S20: 46304 | T20: 贺航 | U20: 未开始 | V20: 46272 | W20: 46304 | X20: 袁丽荣 | Y20: 未开始 | Z20: 46307 | AA20: 46318 | AB20: =(IF(M20="已完成",1,IF(M20="进行中",0.5,0))*15%+IF(Q20="已完成",1,IF(Q20="进行中",0.5,0))*35%+IF(U20="已完成",1,IF(U20="进行中",0.5,0))*30%+IF(Y20="已完成",1,IF(Y20="进行中",0.5,0))*20%) -> 0 | AC20: =IF(G20="已完成","正常",IF(OR(G20="暂停",G20="挂起"),"暂停",IF(J20="","日期缺失",IF(J20<项目驾驶舱!$B$3,"已延期",IF(J20<=项目驾驶舱!$B$3+7,"临近到期","正常"))))) -> 正常 | AD20: 69 | AE20: 69
A21: T018 | B21: 网上营业厅 | C21: 结算条款管理 | D21: 结算条款推送法务系统 | E21: / | F21: 第二批次 | G21: =IF(OR(M21="挂起",M21="暂停",Q21="挂起",Q21="暂停",U21="挂起",U21="暂停",Y21="挂起",Y21="暂停"),"暂停","未开始") -> 未开始 | H21: =IF(L21<>"",L21,IF(P21<>"",P21,IF(T21<>"",T21,X21))) -> 郑士旺 | I21: =IF(COUNT(N21,R21,V21,Z21)=0,"",MIN(N21,R21,V21,Z21)) -> 46223 | J21: =IF(ISNUMBER(K21),K21,IF(COUNT(O21,S21,W21,AA21)=0,"",MAX(O21,S21,W21,AA21))) -> 46318 | L21: 郑士旺 | M21: 未开始 | N21: 46223 | O21: 46227 | P21: 石军磊、刘凯 | Q21: 未开始 | R21: 46272 | S21: 46304 | T21: 贺航 | U21: 未开始 | V21: 46272 | W21: 46304 | X21: 袁丽荣 | Y21: 未开始 | Z21: 46307 | AA21: 46318 | AB21: =(IF(M21="已完成",1,IF(M21="进行中",0.5,0))*15%+IF(Q21="已完成",1,IF(Q21="进行中",0.5,0))*35%+IF(U21="已完成",1,IF(U21="进行中",0.5,0))*30%+IF(Y21="已完成",1,IF(Y21="进行中",0.5,0))*20%) -> 0 | AC21: =IF(G21="已完成","正常",IF(OR(G21="暂停",G21="挂起"),"暂停",IF(J21="","日期缺失",IF(J21<项目驾驶舱!$B$3,"已延期",IF(J21<=项目驾驶舱!$B$3+7,"临近到期","正常"))))) -> 正常 | AD21: 69 | AE21: 69
A22: T019 | B22: 网上营业厅 | C22: 卸船作业 | D22: 卸船计划 | E22: 对接卸船计划 | F22: 第二批次 | G22: =IF(OR(M22="挂起",M22="暂停",Q22="挂起",Q22="暂停",U22="挂起",U22="暂停",Y22="挂起",Y22="暂停"),"暂停","进行中") -> 进行中 | H22: =IF(L22<>"",L22,IF(P22<>"",P22,IF(T22<>"",T22,X22))) -> 郑士旺 | I22: =IF(COUNT(N22,R22,V22,Z22)=0,"",MIN(N22,R22,V22,Z22)) -> 46230 | J22: =IF(ISNUMBER(K22),K22,IF(COUNT(O22,S22,W22,AA22)=0,"",MAX(O22,S22,W22,AA22))) -> 46353 | L22: 郑士旺 | M22: 已完成 | N22: 46230 | O22: 46241 | P22: 石军磊、刘凯 | Q22: 未开始 | R22: 46307 | S22: 46339 | T22: 贺航 | U22: 未开始 | V22: 46307 | W22: 46339 | X22: 袁丽荣 | Y22: 未开始 | Z22: 46342 | AA22: 46353 | AB22: =(IF(M22="已完成",1,IF(M22="进行中",0.5,0))*15%+IF(Q22="已完成",1,IF(Q22="进行中",0.5,0))*35%+IF(U22="已完成",1,IF(U22="进行中",0.5,0))*30%+IF(Y22="已完成",1,IF(Y22="进行中",0.5,0))*20%) -> 0.15 | AC22: =IF(G22="已完成","正常",IF(OR(G22="暂停",G22="挂起"),"暂停",IF(J22="","日期缺失",IF(J22<项目驾驶舱!$B$3,"已延期",IF(J22<=项目驾驶舱!$B$3+7,"临近到期","正常"))))) -> 正常 | AD22: 69 | AE22: 69
A23: T020 | B23: 网上营业厅 | C23: 卸船作业 | D23: 卸船计划 | E23: 查询卸车计划 | F23: 第二批次 | G23: =IF(OR(M23="挂起",M23="暂停",Q23="挂起",Q23="暂停",U23="挂起",U23="暂停",Y23="挂起",Y23="暂停"),"暂停","进行中") -> 进行中 | H23: =IF(L23<>"",L23,IF(P23<>"",P23,IF(T23<>"",T23,X23))) -> 郑士旺 | I23: =IF(COUNT(N23,R23,V23,Z23)=0,"",MIN(N23,R23,V23,Z23)) -> 46230 | J23: =IF(ISNUMBER(K23),K23,IF(COUNT(O23,S23,W23,AA23)=0,"",MAX(O23,S23,W23,AA23))) -> 46353 | L23: 郑士旺 | M23: 已完成 | N23: 46230 | O23: 46241 | P23: 石军磊、刘凯 | Q23: 进行中 | R23: 46307 | S23: 46339 | T23: 贺航 | U23: 进行中 | V23: 46307 | W23: 46339 | X23: 袁丽荣 | Y23: 未开始 | Z23: 46342 | AA23: 46353 | AB23: =(IF(M23="已完成",1,IF(M23="进行中",0.5,0))*15%+IF(Q23="已完成",1,IF(Q23="进行中",0.5,0))*35%+IF(U23="已完成",1,IF(U23="进行中",0.5,0))*30%+IF(Y23="已完成",1,IF(Y23="进行中",0.5,0))*20%) -> 0.475 | AC23: =IF(G23="已完成","正常",IF(OR(G23="暂停",G23="挂起"),"暂停",IF(J23="","日期缺失",IF(J23<项目驾驶舱!$B$3,"已延期",IF(J23<=项目驾驶舱!$B$3+7,"临近到期","正常"))))) -> 正常 | AD23: 69 | AE23: 69
A24: T021 | B24: 网上营业厅 | C24: 卸船作业 | D24: 卸船计划 | E24: 外部客户确认 | F24: 第二批次 | G24: =IF(OR(M24="挂起",M24="暂停",Q24="挂起",Q24="暂停",U24="挂起",U24="暂停",Y24="挂起",Y24="暂停"),"暂停","进行中") -> 进行中 | H24: =IF(L24<>"",L24,IF(P24<>"",P24,IF(T24<>"",T24,X24))) -> 郑士旺 | I24: =IF(COUNT(N24,R24,V24,Z24)=0,"",MIN(N24,R24,V24,Z24)) -> 46230 | J24: =IF(ISNUMBER(K24),K24,IF(COUNT(O24,S24,W24,AA24)=0,"",MAX(O24,S24,W24,AA24))) -> 46353 | L24: 郑士旺 | M24: 已完成 | N24: 46230 | O24: 46241 | P24: 石军磊、刘凯 | Q24: 进行中 | R24: 46307 | S24: 46339 | T24: 贺航 | U24: 进行中 | V24: 46307 | W24: 46339 | X24: 袁丽荣 | Y24: 未开始 | Z24: 46342 | AA24: 46353 | AB24: =(IF(M24="已完成",1,IF(M24="进行中",0.5,0))*15%+IF(Q24="已完成",1,IF(Q24="进行中",0.5,0))*35%+IF(U24="已完成",1,IF(U24="进行中",0.5,0))*30%+IF(Y24="已完成",1,IF(Y24="进行中",0.5,0))*20%) -> 0.475 | AC24: =IF(G24="已完成","正常",IF(OR(G24="暂停",G24="挂起"),"暂停",IF(J24="","日期缺失",IF(J24<项目驾驶舱!$B$3,"已延期",IF(J24<=项目驾驶舱!$B$3+7,"临近到期","正常"))))) -> 正常 | AD24: 69 | AE24: 69
A25: T022 | B25: 网上营业厅 | C25: 卸船作业 | D25: 卸船作业信息管理 | E25: 对接卸船作业信息 | F25: 第二批次 | G25: =IF(OR(M25="挂起",M25="暂停",Q25="挂起",Q25="暂停",U25="挂起",U25="暂停",Y25="挂起",Y25="暂停"),"暂停","未开始") -> 未开始 | H25: =IF(L25<>"",L25,IF(P25<>"",P25,IF(T25<>"",T25,X25))) -> 郑士旺 | I25: =IF(COUNT(N25,R25,V25,Z25)=0,"",MIN(N25,R25,V25,Z25)) -> 46230 | J25: =IF(ISNUMBER(K25),K25,IF(COUNT(O25,S25,W25,AA25)=0,"",MAX(O25,S25,W25,AA25))) -> 46353 | L25: 郑士旺 | M25: 未开始 | N25: 46230 | O25: 46241 | P25: 石军磊、刘凯 | Q25: 未开始 | R25: 46307 | S25: 46339 | T25: 贺航 | U25: 未开始 | V25: 46307 | W25: 46339 | X25: 袁丽荣 | Y25: 未开始 | Z25: 46342 | AA25: 46353 | AB25: =(IF(M25="已完成",1,IF(M25="进行中",0.5,0))*15%+IF(Q25="已完成",1,IF(Q25="进行中",0.5,0))*35%+IF(U25="已完成",1,IF(U25="进行中",0.5,0))*30%+IF(Y25="已完成",1,IF(Y25="进行中",0.5,0))*20%) -> 0 | AC25: =IF(G25="已完成","正常",IF(OR(G25="暂停",G25="挂起"),"暂停",IF(J25="","日期缺失",IF(J25<项目驾驶舱!$B$3,"已延期",IF(J25<=项目驾驶舱!$B$3+7,"临近到期","正常"))))) -> 正常 | AD25: 69 | AE25: 69
A26: T023 | B26: 网上营业厅 | C26: 卸船作业 | D26: 卸船作业信息管理 | E26: 查询卸船作业信息 | F26: 第二批次 | G26: =IF(OR(M26="挂起",M26="暂停",Q26="挂起",Q26="暂停",U26="挂起",U26="暂停",Y26="挂起",Y26="暂停"),"暂停","未开始") -> 未开始 | H26: =IF(L26<>"",L26,IF(P26<>"",P26,IF(T26<>"",T26,X26))) -> 郑士旺 | I26: =IF(COUNT(N26,R26,V26,Z26)=0,"",MIN(N26,R26,V26,Z26)) -> 46230 | J26: =IF(ISNUMBER(K26),K26,IF(COUNT(O26,S26,W26,AA26)=0,"",MAX(O26,S26,W26,AA26))) -> 46353 | L26: 郑士旺 | M26: 未开始 | N26: 46230 | O26: 46241 | P26: 石军磊、刘凯 | Q26: 未开始 | R26: 46307 | S26: 46339 | T26: 贺航 | U26: 未开始 | V26: 46307 | W26: 46339 | X26: 袁丽荣 | Y26: 未开始 | Z26: 46342 | AA26: 46353 | AB26: =(IF(M26="已完成",1,IF(M26="进行中",0.5,0))*15%+IF(Q26="已完成",1,IF(Q26="进行中",0.5,0))*35%+IF(U26="已完成",1,IF(U26="进行中",0.5,0))*30%+IF(Y26="已完成",1,IF(Y26="进行中",0.5,0))*20%) -> 0 | AC26: =IF(G26="已完成","正常",IF(OR(G26="暂停",G26="挂起"),"暂停",IF(J26="","日期缺失",IF(J26<项目驾驶舱!$B$3,"已延期",IF(J26<=项目驾驶舱!$B$3+7,"临近到期","正常"))))) -> 正常 | AD26: 69 | AE26: 69
A27: T024 | B27: 网上营业厅 | C27: 卸船作业 | D27: 卸船查询 | E27: 卸船查询列表 | F27: 第二批次 | G27: =IF(OR(M27="挂起",M27="暂停",Q27="挂起",Q27="暂停",U27="挂起",U27="暂停",Y27="挂起",Y27="暂停"),"暂停","未开始") -> 未开始 | H27: =IF(L27<>"",L27,IF(P27<>"",P27,IF(T27<>"",T27,X27))) -> 郑士旺 | I27: =IF(COUNT(N27,R27,V27,Z27)=0,"",MIN(N27,R27,V27,Z27)) -> 46230 | J27: =IF(ISNUMBER(K27),K27,IF(COUNT(O27,S27,W27,AA27)=0,"",MAX(O27,S27,W27,AA27))) -> 46353 | L27: 郑士旺 | M27: 未开始 | N27: 46230 | O27: 46241 | P27: 石军磊、刘凯 | Q27: 未开始 | R27: 46307 | S27: 46339 | T27: 贺航 | U27: 未开始 | V27: 46307 | W27: 46339 | X27: 袁丽荣 | Y27: 未开始 | Z27: 46342 | AA27: 46353 | AB27: =(IF(M27="已完成",1,IF(M27="进行中",0.5,0))*15%+IF(Q27="已完成",1,IF(Q27="进行中",0.5,0))*35%+IF(U27="已完成",1,IF(U27="进行中",0.5,0))*30%+IF(Y27="已完成",1,IF(Y27="进行中",0.5,0))*20%) -> 0 | AC27: =IF(G27="已完成","正常",IF(OR(G27="暂停",G27="挂起"),"暂停",IF(J27="","日期缺失",IF(J27<项目驾驶舱!$B$3,"已延期",IF(J27<=项目驾驶舱!$B$3+7,"临近到期","正常"))))) -> 正常 | AD27: 69 | AE27: 69
A28: T025 | B28: 网上营业厅 | C28: 卸船作业 | D28: 卸船查询 | E28: 卸船查询详情 | F28: 第二批次 | G28: =IF(OR(M28="挂起",M28="暂停",Q28="挂起",Q28="暂停",U28="挂起",U28="暂停",Y28="挂起",Y28="暂停"),"暂停","未开始") -> 未开始 | H28: =IF(L28<>"",L28,IF(P28<>"",P28,IF(T28<>"",T28,X28))) -> 郑士旺 | I28: =IF(COUNT(N28,R28,V28,Z28)=0,"",MIN(N28,R28,V28,Z28)) -> 46230 | J28: =IF(ISNUMBER(K28),K28,IF(COUNT(O28,S28,W28,AA28)=0,"",MAX(O28,S28,W28,AA28))) -> 46261 | K28: 46261 | L28: 郑士旺 | M28: 未开始 | N28: 46230 | O28: 46241 | P28: 石军磊、刘凯 | Q28: 未开始 | R28: 46307 | S28: 46339 | T28: 贺航 | U28: 未开始 | V28: 46307 | W28: 46339 | X28: 袁丽荣 | Y28: 未开始 | Z28: 46342 | AA28: 46353 | AB28: =(IF(M28="已完成",1,IF(M28="进行中",0.5,0))*15%+IF(Q28="已完成",1,IF(Q28="进行中",0.5,0))*35%+IF(U28="已完成",1,IF(U28="进行中",0.5,0))*30%+IF(Y28="已完成",1,IF(Y28="进行中",0.5,0))*20%) -> 0 | AC28: =IF(G28="已完成","正常",IF(OR(G28="暂停",G28="挂起"),"暂停",IF(J28="","日期缺失",IF(J28<项目驾驶舱!$B$3,"已延期",IF(J28<=项目驾驶舱!$B$3+7,"临近到期","正常"))))) -> 已延期 | AD28: 69 | AE28: 69
A29: T026 | B29: 网上营业厅 | C29: 卸船作业 | D29: 卸船作业委托 | E29: 创建卸船作业委托信息 | F29: 第二批次 | G29: =IF(OR(M29="挂起",M29="暂停",Q29="挂起",Q29="暂停",U29="挂起",U29="暂停",Y29="挂起",Y29="暂停"),"暂停","进行中") -> 进行中 | H29: =IF(L29<>"",L29,IF(P29<>"",P29,IF(T29<>"",T29,X29))) -> 郑士旺 | I29: =IF(COUNT(N29,R29,V29,Z29)=0,"",MIN(N29,R29,V29,Z29)) -> 46230 | J29: =IF(ISNUMBER(K29),K29,IF(COUNT(O29,S29,W29,AA29)=0,"",MAX(O29,S29,W29,AA29))) -> 46261 | K29: 46261 | L29: 郑士旺 | M29: 已完成 | N29: 46230 | O29: 46241 | P29: 石军磊、刘凯 | Q29: 进行中 | R29: 46307 | S29: 46339 | T29: 贺航 | U29: 进行中 | V29: 46307 | W29: 46339 | X29: 袁丽荣 | Y29: 未开始 | Z29: 46342 | AA29: 46353 | AB29: =(IF(M29="已完成",1,IF(M29="进行中",0.5,0))*15%+IF(Q29="已完成",1,IF(Q29="进行中",0.5,0))*35%+IF(U29="已完成",1,IF(U29="进行中",0.5,0))*30%+IF(Y29="已完成",1,IF(Y29="进行中",0.5,0))*20%) -> 0.475 | AC29: =IF(G29="已完成","正常",IF(OR(G29="暂停",G29="挂起"),"暂停",IF(J29="","日期缺失",IF(J29<项目驾驶舱!$B$3,"已延期",IF(J29<=项目驾驶舱!$B$3+7,"临近到期","正常"))))) -> 已延期 | AD29: 69 | AE29: 69
A30: T027 | B30: 网上营业厅 | C30: 卸船作业 | D30: 卸船作业委托 | E30: 修改卸船作业委托信息 | F30: 第二批次 | G30: =IF(OR(M30="挂起",M30="暂停",Q30="挂起",Q30="暂停",U30="挂起",U30="暂停",Y30="挂起",Y30="暂停"),"暂停","进行中") -> 进行中 | H30: =IF(L30<>"",L30,IF(P30<>"",P30,IF(T30<>"",T30,X30))) -> 郑士旺 | I30: =IF(COUNT(N30,R30,V30,Z30)=0,"",MIN(N30,R30,V30,Z30)) -> 46230 | J30: =IF(ISNUMBER(K30),K30,IF(COUNT(O30,S30,W30,AA30)=0,"",MAX(O30,S30,W30,AA30))) -> 46261 | K30: 46261 | L30: 郑士旺 | M30: 已完成 | N30: 46230 | O30: 46241 | P30: 石军磊、刘凯 | Q30: 进行中 | R30: 46307 | S30: 46339 | T30: 贺航 | U30: 进行中 | V30: 46307 | W30: 46339 | X30: 袁丽荣 | Y30: 未开始 | Z30: 46342 | AA30: 46353 | AB30: =(IF(M30="已完成",1,IF(M30="进行中",0.5,0))*15%+IF(Q30="已完成",1,IF(Q30="进行中",0.5,0))*35%+IF(U30="已完成",1,IF(U30="进行中",0.5,0))*30%+IF(Y30="已完成",1,IF(Y30="进行中",0.5,0))*20%) -> 0.475 | AC30: =IF(G30="已完成","正常",IF(OR(G30="暂停",G30="挂起"),"暂停",IF(J30="","日期缺失",IF(J30<项目驾驶舱!$B$3,"已延期",IF(J30<=项目驾驶舱!$B$3+7,"临近到期","正常"))))) -> 已延期 | AD30: 69 | AE30: 69
A31: T028 | B31: 网上营业厅 | C31: 卸船作业 | D31: 卸船作业委托 | E31: 作废卸船作业委托信息 | F31: 第二批次 | G31: =IF(OR(M31="挂起",M31="暂停",Q31="挂起",Q31="暂停",U31="挂起",U31="暂停",Y31="挂起",Y31="暂停"),"暂停","进行中") -> 进行中 | H31: =IF(L31<>"",L31,IF(P31<>"",P31,IF(T31<>"",T31,X31))) -> 郑士旺 | I31: =IF(COUNT(N31,R31,V31,Z31)=0,"",MIN(N31,R31,V31,Z31)) -> 46230 | J31: =IF(ISNUMBER(K31),K31,IF(COUNT(O31,S31,W31,AA31)=0,"",MAX(O31,S31,W31,AA31))) -> 46261 | K31: 46261 | L31: 郑士旺 | M31: 进行中 | N31: 46230 | O31: 46241 | P31: 石军磊、刘凯 | Q31: 未开始 | R31: 46307 | S31: 46339 | T31: 贺航 | U31: 未开始 | V31: 46307 | W31: 46339 | X31: 袁丽荣 | Y31: 未开始 | Z31: 46342 | AA31: 46353 | AB31: =(IF(M31="已完成",1,IF(M31="进行中",0.5,0))*15%+IF(Q31="已完成",1,IF(Q31="进行中",0.5,0))*35%+IF(U31="已完成",1,IF(U31="进行中",0.5,0))*30%+IF(Y31="已完成",1,IF(Y31="进行中",0.5,0))*20%) -> 0.075 | AC31: =IF(G31="已完成","正常",IF(OR(G31="暂停",G31="挂起"),"暂停",IF(J31="","日期缺失",IF(J31<项目驾驶舱!$B$3,"已延期",IF(J31<=项目驾驶舱!$B$3+7,"临近到期","正常"))))) -> 已延期 | AD31: 69 | AE31: 69
A32: T029 | B32: 网上营业厅 | C32: 卸船作业 | D32: 卸船作业委托 | E32: 推送卸船作业委托信息 | F32: 第二批次 | G32: =IF(OR(M32="挂起",M32="暂停",Q32="挂起",Q32="暂停",U32="挂起",U32="暂停",Y32="挂起",Y32="暂停"),"暂停","进行中") -> 进行中 | H32: =IF(L32<>"",L32,IF(P32<>"",P32,IF(T32<>"",T32,X32))) -> 郑士旺 | I32: =IF(COUNT(N32,R32,V32,Z32)=0,"",MIN(N32,R32,V32,Z32)) -> 46230 | J32: =IF(ISNUMBER(K32),K32,IF(COUNT(O32,S32,W32,AA32)=0,"",MAX(O32,S32,W32,AA32))) -> 46261 | K32: 46261 | L32: 郑士旺 | M32: 进行中 | N32: 46230 | O32: 46241 | P32: 石军磊、刘凯 | Q32: 未开始 | R32: 46307 | S32: 46339 | T32: 贺航 | U32: 未开始 | V32: 46307 | W32: 46339 | X32: 袁丽荣 | Y32: 未开始 | Z32: 46342 | AA32: 46353 | AB32: =(IF(M32="已完成",1,IF(M32="进行中",0.5,0))*15%+IF(Q32="已完成",1,IF(Q32="进行中",0.5,0))*35%+IF(U32="已完成",1,IF(U32="进行中",0.5,0))*30%+IF(Y32="已完成",1,IF(Y32="进行中",0.5,0))*20%) -> 0.075 | AC32: =IF(G32="已完成","正常",IF(OR(G32="暂停",G32="挂起"),"暂停",IF(J32="","日期缺失",IF(J32<项目驾驶舱!$B$3,"已延期",IF(J32<=项目驾驶舱!$B$3+7,"临近到期","正常"))))) -> 已延期 | AD32: 69 | AE32: 69
A33: T030 | B33: 网上营业厅 | C33: 卸船作业 | D33: 卸船作业委托 | E33: 查询卸船作业委托信息 | F33: 第二批次 | G33: =IF(OR(M33="挂起",M33="暂停",Q33="挂起",Q33="暂停",U33="挂起",U33="暂停",Y33="挂起",Y33="暂停"),"暂停","进行中") -> 进行中 | H33: =IF(L33<>"",L33,IF(P33<>"",P33,IF(T33<>"",T33,X33))) -> 郑士旺 | I33: =IF(COUNT(N33,R33,V33,Z33)=0,"",MIN(N33,R33,V33,Z33)) -> 46230 | J33: =IF(ISNUMBER(K33),K33,IF(COUNT(O33,S33,W33,AA33)=0,"",MAX(O33,S33,W33,AA33))) -> 46261 | K33: 46261 | L33: 郑士旺 | M33: 已完成 | N33: 46230 | O33: 46241 | P33: 石军磊、刘凯 | Q33: 进行中 | R33: 46307 | S33: 46339 | T33: 贺航 | U33: 进行中 | V33: 46307 | W33: 46339 | X33: 袁丽荣 | Y33: 未开始 | Z33: 46342 | AA33: 46353 | AB33: =(IF(M33="已完成",1,IF(M33="进行中",0.5,0))*15%+IF(Q33="已完成",1,IF(Q33="进行中",0.5,0))*35%+IF(U33="已完成",1,IF(U33="进行中",0.5,0))*30%+IF(Y33="已完成",1,IF(Y33="进行中",0.5,0))*20%) -> 0.475 | AC33: =IF(G33="已完成","正常",IF(OR(G33="暂停",G33="挂起"),"暂停",IF(J33="","日期缺失",IF(J33<项目驾驶舱!$B$3,"已延期",IF(J33<=项目驾驶舱!$B$3+7,"临近到期","正常"))))) -> 已延期 | AD33: 69 | AE33: 69
A34: T031 | B34: 网上营业厅 | C34: 卸船作业 | D34: 外轮转内贸业务 | E34: 创建外轮转内贸业务信息 | F34: 第二批次 | G34: =IF(OR(M34="挂起",M34="暂停",Q34="挂起",Q34="暂停",U34="挂起",U34="暂停",Y34="挂起",Y34="暂停"),"暂停","未开始") -> 未开始 | H34: =IF(L34<>"",L34,IF(P34<>"",P34,IF(T34<>"",T34,X34))) -> 郑士旺 | I34: =IF(COUNT(N34,R34,V34,Z34)=0,"",MIN(N34,R34,V34,Z34)) -> 46230 | J34: =IF(ISNUMBER(K34),K34,IF(COUNT(O34,S34,W34,AA34)=0,"",MAX(O34,S34,W34,AA34))) -> 46353 | L34: 郑士旺 | M34: 未开始 | N34: 46230 | O34: 46241 | P34: 石军磊、刘凯 | Q34: 未开始 | R34: 46307 | S34: 46339 | T34: 贺航 | U34: 未开始 | V34: 46307 | W34: 46339 | X34: 袁丽荣 | Y34: 未开始 | Z34: 46342 | AA34: 46353 | AB34: =(IF(M34="已完成",1,IF(M34="进行中",0.5,0))*15%+IF(Q34="已完成",1,IF(Q34="进行中",0.5,0))*35%+IF(U34="已完成",1,IF(U34="进行中",0.5,0))*30%+IF(Y34="已完成",1,IF(Y34="进行中",0.5,0))*20%) -> 0 | AC34: =IF(G34="已完成","正常",IF(OR(G34="暂停",G34="挂起"),"暂停",IF(J34="","日期缺失",IF(J34<项目驾驶舱!$B$3,"已延期",IF(J34<=项目驾驶舱!$B$3+7,"临近到期","正常"))))) -> 正常 | AD34: 69 | AE34: 69
A35: T032 | B35: 网上营业厅 | C35: 卸船作业 | D35: 外轮转内贸业务 | E35: 作废外轮转内贸业务信息 | F35: 第二批次 | G35: =IF(OR(M35="挂起",M35="暂停",Q35="挂起",Q35="暂停",U35="挂起",U35="暂停",Y35="挂起",Y35="暂停"),"暂停","未开始") -> 未开始 | H35: =IF(L35<>"",L35,IF(P35<>"",P35,IF(T35<>"",T35,X35))) -> 郑士旺 | I35: =IF(COUNT(N35,R35,V35,Z35)=0,"",MIN(N35,R35,V35,Z35)) -> 46230 | J35: =IF(ISNUMBER(K35),K35,IF(COUNT(O35,S35,W35,AA35)=0,"",MAX(O35,S35,W35,AA35))) -> 46353 | L35: 郑士旺 | M35: 未开始 | N35: 46230 | O35: 46241 | P35: 石军磊、刘凯 | Q35: 未开始 | R35: 46307 | S35: 46339 | T35: 贺航 | U35: 未开始 | V35: 46307 | W35: 46339 | X35: 袁丽荣 | Y35: 未开始 | Z35: 46342 | AA35: 46353 | AB35: =(IF(M35="已完成",1,IF(M35="进行中",0.5,0))*15%+IF(Q35="已完成",1,IF(Q35="进行中",0.5,0))*35%+IF(U35="已完成",1,IF(U35="进行中",0.5,0))*30%+IF(Y35="已完成",1,IF(Y35="进行中",0.5,0))*20%) -> 0 | AC35: =IF(G35="已完成","正常",IF(OR(G35="暂停",G35="挂起"),"暂停",IF(J35="","日期缺失",IF(J35<项目驾驶舱!$B$3,"已延期",IF(J35<=项目驾驶舱!$B$3+7,"临近到期","正常"))))) -> 正常 | AD35: 69 | AE35: 69
A36: T033 | B36: 网上营业厅 | C36: 卸船作业 | D36: 外轮转内贸业务 | E36: 查询外轮转内贸业务信息 | F36: 第二批次 | G36: =IF(OR(M36="挂起",M36="暂停",Q36="挂起",Q36="暂停",U36="挂起",U36="暂停",Y36="挂起",Y36="暂停"),"暂停","未开始") -> 未开始 | H36: =IF(L36<>"",L36,IF(P36<>"",P36,IF(T36<>"",T36,X36))) -> 郑士旺 | I36: =IF(COUNT(N36,R36,V36,Z36)=0,"",MIN(N36,R36,V36,Z36)) -> 46230 | J36: =IF(ISNUMBER(K36),K36,IF(COUNT(O36,S36,W36,AA36)=0,"",MAX(O36,S36,W36,AA36))) -> 46353 | L36: 郑士旺 | M36: 未开始 | N36: 46230 | O36: 46241 | P36: 石军磊、刘凯 | Q36: 未开始 | R36: 46307 | S36: 46339 | T36: 贺航 | U36: 未开始 | V36: 46307 | W36: 46339 | X36: 袁丽荣 | Y36: 未开始 | Z36: 46342 | AA36: 46353 | AB36: =(IF(M36="已完成",1,IF(M36="进行中",0.5,0))*15%+IF(Q36="已完成",1,IF(Q36="进行中",0.5,0))*35%+IF(U36="已完成",1,IF(U36="进行中",0.5,0))*30%+IF(Y36="已完成",1,IF(Y36="进行中",0.5,0))*20%) -> 0 | AC36: =IF(G36="已完成","正常",IF(OR(G36="暂停",G36="挂起"),"暂停",IF(J36="","日期缺失",IF(J36<项目驾驶舱!$B$3,"已延期",IF(J36<=项目驾驶舱!$B$3+7,"临近到期","正常"))))) -> 正常 | AD36: 69 | AE36: 69
A37: T034 | B37: 网上营业厅 | C37: 卸船作业 | D37: 船舶靠泊通知单 | E37: 新增船舶靠泊通知单 | F37: 第二批次 | G37: =IF(OR(M37="挂起",M37="暂停",Q37="挂起",Q37="暂停",U37="挂起",U37="暂停",Y37="挂起",Y37="暂停"),"暂停","进行中") -> 进行中 | H37: =IF(L37<>"",L37,IF(P37<>"",P37,IF(T37<>"",T37,X37))) -> 郑士旺 | I37: =IF(COUNT(N37,R37,V37,Z37)=0,"",MIN(N37,R37,V37,Z37)) -> 46230 | J37: =IF(ISNUMBER(K37),K37,IF(COUNT(O37,S37,W37,AA37)=0,"",MAX(O37,S37,W37,AA37))) -> 46353 | L37: 郑士旺 | M37: 已完成 | N37: 46230 | O37: 46241 | P37: 石军磊、刘凯 | Q37: 进行中 | R37: 46307 | S37: 46339 | T37: 贺航 | U37: 进行中 | V37: 46307 | W37: 46339 | X37: 袁丽荣 | Y37: 未开始 | Z37: 46342 | AA37: 46353 | AB37: =(IF(M37="已完成",1,IF(M37="进行中",0.5,0))*15%+IF(Q37="已完成",1,IF(Q37="进行中",0.5,0))*35%+IF(U37="已完成",1,IF(U37="进行中",0.5,0))*30%+IF(Y37="已完成",1,IF(Y37="进行中",0.5,0))*20%) -> 0.475 | AC37: =IF(G37="已完成","正常",IF(OR(G37="暂停",G37="挂起"),"暂停",IF(J37="","日期缺失",IF(J37<项目驾驶舱!$B$3,"已延期",IF(J37<=项目驾驶舱!$B$3+7,"临近到期","正常"))))) -> 正常 | AD37: 69 | AE37: 69
A38: T035 | B38: 网上营业厅 | C38: 卸船作业 | D38: 船舶靠泊通知单 | E38: 审批船舶靠泊通知单 | F38: 第二批次 | G38: =IF(OR(M38="挂起",M38="暂停",Q38="挂起",Q38="暂停",U38="挂起",U38="暂停",Y38="挂起",Y38="暂停"),"暂停","进行中") -> 进行中 | H38: =IF(L38<>"",L38,IF(P38<>"",P38,IF(T38<>"",T38,X38))) -> 郑士旺 | I38: =IF(COUNT(N38,R38,V38,Z38)=0,"",MIN(N38,R38,V38,Z38)) -> 46230 | J38: =IF(ISNUMBER(K38),K38,IF(COUNT(O38,S38,W38,AA38)=0,"",MAX(O38,S38,W38,AA38))) -> 46353 | L38: 郑士旺 | M38: 已完成 | N38: 46230 | O38: 46241 | P38: 石军磊、刘凯 | Q38: 进行中 | R38: 46307 | S38: 46339 | T38: 贺航 | U38: 进行中 | V38: 46307 | W38: 46339 | X38: 袁丽荣 | Y38: 未开始 | Z38: 46342 | AA38: 46353 | AB38: =(IF(M38="已完成",1,IF(M38="进行中",0.5,0))*15%+IF(Q38="已完成",1,IF(Q38="进行中",0.5,0))*35%+IF(U38="已完成",1,IF(U38="进行中",0.5,0))*30%+IF(Y38="已完成",1,IF(Y38="进行中",0.5,0))*20%) -> 0.475 | AC38: =IF(G38="已完成","正常",IF(OR(G38="暂停",G38="挂起"),"暂停",IF(J38="","日期缺失",IF(J38<项目驾驶舱!$B$3,"已延期",IF(J38<=项目驾驶舱!$B$3+7,"临近到期","正常"))))) -> 正常 | AD38: 69 | AE38: 69
A39: T036 | B39: 网上营业厅 | C39: 卸船作业 | D39: 船舶靠泊通知单 | E39: 查询船舶靠泊通知单 | F39: 第二批次 | G39: =IF(OR(M39="挂起",M39="暂停",Q39="挂起",Q39="暂停",U39="挂起",U39="暂停",Y39="挂起",Y39="暂停"),"暂停","进行中") -> 进行中 | H39: =IF(L39<>"",L39,IF(P39<>"",P39,IF(T39<>"",T39,X39))) -> 郑士旺 | I39: =IF(COUNT(N39,R39,V39,Z39)=0,"",MIN(N39,R39,V39,Z39)) -> 46230 | J39: =IF(ISNUMBER(K39),K39,IF(COUNT(O39,S39,W39,AA39)=0,"",MAX(O39,S39,W39,AA39))) -> 46353 | L39: 郑士旺 | M39: 已完成 | N39: 46230 | O39: 46241 | P39: 石军磊、刘凯 | Q39: 进行中 | R39: 46307 | S39: 46339 | T39: 贺航 | U39: 进行中 | V39: 46307 | W39: 46339 | X39: 袁丽荣 | Y39: 未开始 | Z39: 46342 | AA39: 46353 | AB39: =(IF(M39="已完成",1,IF(M39="进行中",0.5,0))*15%+IF(Q39="已完成",1,IF(Q39="进行中",0.5,0))*35%+IF(U39="已完成",1,IF(U39="进行中",0.5,0))*30%+IF(Y39="已完成",1,IF(Y39="进行中",0.5,0))*20%) -> 0.475 | AC39: =IF(G39="已完成","正常",IF(OR(G39="暂停",G39="挂起"),"暂停",IF(J39="","日期缺失",IF(J39<项目驾驶舱!$B$3,"已延期",IF(J39<=项目驾驶舱!$B$3+7,"临近到期","正常"))))) -> 正常 | AD39: 69 | AE39: 69
A40: T037 | B40: 网上营业厅 | C40: 卸车流程跟踪 | D40: 创建卸车流程 | E40: / | F40: 第一批次 | G40: =IF(OR(M40="挂起",M40="暂停",Q40="挂起",Q40="暂停",U40="挂起",U40="暂停",Y40="挂起",Y40="暂停"),"暂停","已完成") -> 已完成 | H40: =IF(L40<>"",L40,IF(P40<>"",P40,IF(T40<>"",T40,X40))) -> 郑士旺 | I40: =IF(COUNT(N40,R40,V40,Z40)=0,"",MIN(N40,R40,V40,Z40)) -> 46209 | J40: =IF(ISNUMBER(K40),K40,IF(COUNT(O40,S40,W40,AA40)=0,"",MAX(O40,S40,W40,AA40))) -> 46261 | K40: 46261 | L40: 郑士旺 | M40: 已完成 | N40: 46209 | O40: 46213 | P40: 石军磊、刘凯 | Q40: 已完成 | R40: 46230 | S40: 46262 | T40: 贺航 | U40: 已完成 | V40: 46230 | W40: 46262 | X40: 袁丽荣 | Y40: 已完成 | Z40: 46253 | AA40: 46269 | AB40: =(IF(M40="已完成",1,IF(M40="进行中",0.5,0))*15%+IF(Q40="已完成",1,IF(Q40="进行中",0.5,0))*35%+IF(U40="已完成",1,IF(U40="进行中",0.5,0))*30%+IF(Y40="已完成",1,IF(Y40="进行中",0.5,0))*20%) -> 1 | AC40: =IF(G40="已完成","正常",IF(OR(G40="暂停",G40="挂起"),"暂停",IF(J40="","日期缺失",IF(J40<项目驾驶舱!$B$3,"已延期",IF(J40<=项目驾驶舱!$B$3+7,"临近到期","正常"))))) -> 正常 | AD40: 69 | AE40: 69
...

Sheet 资源计划
A1: 资源计划
A2: 汇总业务、后端、前端和测试任务分配。黄色区域用于填写可用工时、任务投入工时和资源调整说明。
A4: 人员 | B4: 角色 | C4: 任务数 | D4: 未完成任务 | E4: 最早开始 | F4: 最晚结束 | G4: 周可用工时 | H4: 计划投入工时 | I4: 负荷率 | J4: 负荷判断 | K4: 资源建议 | L4: 备注
A5: 刘凯 | B5: 后端 | C5: 128 | D5: 128 | E5: 46195 | F5: 46339 | G5: 40 | H5: 840 | I5: 1 | J5: 高负荷 | K5: 确认优先级并预留缓冲
A6: 常浩 | B6: 全栈 | C6: 11 | D6: 11 | E6: 46195 | F6: 46339 | G6: 40 | H6: 600 | I6: 0.71428571 | J6: 正常 | K6: 按计划跟踪
A7: 石军磊 | B7: 后端 | C7: 131 | D7: 131 | E7: 46195 | F7: 46339 | G7: 40 | H7: 840 | I7: 1 | J7: 高负荷 | K7: 确认优先级并预留缓冲
A8: 袁丽荣 | B8: 测试 | C8: 139 | D8: 139 | E8: 46202 | F8: 46353 | G8: 40 | H8: 520 | I8: 0.59090909 | J8: 正常 | K8: 按计划跟踪
A9: 贺航 | B9: 前端 | C9: 131 | D9: 131 | E9: 46195 | F9: 46339 | G9: 40 | H9: 840 | I9: 1 | J9: 高负荷 | K9: 确认优先级并预留缓冲
A10: 郑士旺 | B10: 业务 | C10: 139 | D10: 139 | E10: 46202 | F10: 46241 | G10: 40 | H10: 240 | I10: 1 | J10: 高负荷 | K10: 确认优先级并预留缓冲
A13: 资源周计划
A14: 任务名称、状态和日期直接引用总控台账；新增任务或调整责任人后，重新执行V2更新以扩展明细行。
A15: 人员 | B15: 周开始 | C15: 周结束 | D15: 是否有任务 | E15: 任务数 | F15: 周计划工时 | G15: 负荷率 | H15: 负荷判断 | I15: 任务清单
A16: 刘凯 | B16: 46195 | C16: 46201 | D16: 有 | E16: 3 | F16: 40 | G16: 1 | H16: 高负荷 | I16: T058 OCR识别及编辑；T070 生成报告；T071 装船作业信息录入优化（太仓） | L16: 刘凯
B17: 46202 | C17: 46208 | D17: 有 | E17: 3 | F17: 40 | G17: 1 | H17: 高负荷 | I17: T058 OCR识别及编辑；T070 生成报告；T071 装船作业信息录入优化（太仓） | L17: 刘凯
B18: 46209 | C18: 46215 | D18: 有 | E18: 22 | F18: 40 | G18: 1 | H18: 高负荷 | I18: T001 新增车辆信息；T002 修改车辆信息；T003 删除车辆信息；T004 查询展示车辆信息；T006 优化收费标准（装卸费）新增；T007 优化收费标准（装卸费）编辑；T008 优化收费标准（装卸费）详情；T009 优化采样方式新增；T010 优化采样方式编辑；T011 获取报单数据及展示；T012 应单入口；T060 货权录入；T061 货权修改；T062 获取查询；T063 卸船作业货权跟踪；T064 卸船作业货权跟踪；T065 装船作业货权跟踪；T066 装船作业货权跟踪；T067 装船作业货权跟踪；T068 装船作业货权跟踪；T072 OCR识别；T096 自动生成装船港杂费 | L18: 刘凯
B19: 46216 | C19: 46222 | D19: 有 | E19: 22 | F19: 40 | G19: 1 | H19: 高负荷 | I19: T001 新增车辆信息；T002 修改车辆信息；T003 删除车辆信息；T004 查询展示车辆信息；T006 优化收费标准（装卸费）新增；T007 优化收费标准（装卸费）编辑；T008 优化收费标准（装卸费）详情；T009 优化采样方式新增；T010 优化采样方式编辑；T011 获取报单数据及展示；T012 应单入口；T060 货权录入；T061 货权修改；T062 获取查询；T063 卸船作业货权跟踪；T064 卸船作业货权跟踪；T065 装船作业货权跟踪；T066 装船作业货权跟踪；T067 装船作业货权跟踪；T068 装船作业货权跟踪；T072 OCR识别；T096 自动生成装船港杂费 | L19: 刘凯
B20: 46223 | C20: 46229 | D20: 有 | E20: 30 | F20: 40 | G20: 1 | H20: 高负荷 | I20: T001 新增车辆信息；T002 修改车辆信息；T003 删除车辆信息；T004 查询展示车辆信息；T006 优化收费标准（装卸费）新增；T007 优化收费标准（装卸费）编辑；T008 优化收费标准（装卸费）详情；T009 优化采样方式新增；T010 优化采样方式编辑；T011 获取报单数据及展示；T012 应单入口；T060 货权录入；T061 货权修改；T062 获取查询；T063 卸船作业货权跟踪；T064 卸船作业货权跟踪；T065 装船作业货权跟踪；T066 装船作业货权跟踪；T067 装船作业货权跟踪；T068 装船作业货权跟踪；T072 OCR识别；T096 自动生成装船港杂费；T073 采样作业信息录入新增；T074 采样作业信息录入编辑；T075 采样作业信息录入详情；T076 采样作业信息录入删除；T077 采样作业信息录入列表；T097 自动生成租赁费；T098 优化装卸费新增；T099 优化装卸费编辑 | L20: 刘凯
B21: 46230 | C21: 46236 | D21: 有 | E21: 24 | F21: 40 | G21: 1 | H21: 高负荷 | I21: T037 创建卸车流程；T038 查询卸车流程；T039 修改卸车流程；T040 创建装船流程；T041 查询装船流程；T042 修改装船流程；T043 创建卸船流程；T044 查询卸船流程；T045 修改卸船流程；T059 优化新增装车作业信息；T104 吞吐量统计（曹妃甸）；T105 泊位占用率分析（曹妃甸）；T106 堆存库存统计（曹妃甸）；T107 分货主实时统计表（曹妃甸）；T108 综合装船效率分析（曹妃甸）；T109 综合卸车效率分析（曹妃甸）；T110 综合卸船效率分析（曹妃甸）；T117 经营任务情况分析报告；T118 客户月报报告；T119 月度客户情况报告；T120 商务计划周报；T138 查询卸车流程；T139 查询装船流程；T140 查询卸船流程 | L21: 刘凯
B22: 46237 | C22: 46243 | D22: 有 | E22: 27 | F22: 40 | G22: 1 | H22: 高负荷 | I22: T037 创建卸车流程；T038 查询卸车流程；T039 修改卸车流程；T040 创建装船流程；T041 查询装船流程；T042 修改装船流程；T043 创建卸船流程；T044 查询卸船流程；T045 修改卸船流程；T059 优化新增装车作业信息；T104 吞吐量统计（曹妃甸）；T105 泊位占用率分析（曹妃甸）；T106 堆存库存统计（曹妃甸）；T107 分货主实时统计表（曹妃甸）；T108 综合装船效率分析（曹妃甸）；T109 综合卸车效率分析（曹妃甸）；T110 综合卸船效率分析（曹妃甸）；T117 经营任务情况分析报告；T118 客户月报报告；T119 月度客户情况报告；T120 商务计划周报；T138 查询卸车流程；T139 查询装船流程；T140 查询卸船流程；T143 图片上传；T144 图片上传；T145 图片上传 | L22: 刘凯
B23: 46244 | C23: 46250 | D23: 有 | E23: 26 | F23: 40 | G23: 1 | H23: 高负荷 | I23: T037 创建卸车流程；T038 查询卸车流程；T039 修改卸车流程；T040 创建装船流程；T041 查询装船流程；T042 修改装船流程；T043 创建卸船流程；T044 查询卸船流程；T045 修改卸船流程；T104 吞吐量统计（曹妃甸）；T105 泊位占用率分析（曹妃甸）；T106 堆存库存统计（曹妃甸）；T107 分货主实时统计表（曹妃甸）；T108 综合装船效率分析（曹妃甸）；T109 综合卸车效率分析（曹妃甸）；T110 综合卸船效率分析（曹妃甸）；T117 经营任务情况分析报告；T118 客户月报报告；T119 月度客户情况报告；T120 商务计划周报；T138 查询卸车流程；T139 查询装船流程；T140 查询卸船流程；T143 图片上传；T144 图片上传；T145 图片上传 | L23: 刘凯
B24: 46251 | C24: 46257 | D24: 有 | E24: 26 | F24: 40 | G24: 1 | H24: 高负荷 | I24: T037 创建卸车流程；T038 查询卸车流程；T039 修改卸车流程；T040 创建装船流程；T041 查询装船流程；T042 修改装船流程；T043 创建卸船流程；T044 查询卸船流程；T045 修改卸船流程；T104 吞吐量统计（曹妃甸）；T105 泊位占用率分析（曹妃甸）；T106 堆存库存统计（曹妃甸）；T107 分货主实时统计表（曹妃甸）；T108 综合装船效率分析（曹妃甸）；T109 综合卸车效率分析（曹妃甸）；T110 综合卸船效率分析（曹妃甸）；T117 经营任务情况分析报告；T118 客户月报报告；T119 月度客户情况报告；T120 商务计划周报；T138 查询卸车流程；T139 查询装船流程；T140 查询卸船流程；T143 图片上传；T144 图片上传；T145 图片上传 | L24: 刘凯
B25: 46258 | C25: 46264 | D25: 有 | E25: 23 | F25: 40 | G25: 1 | H25: 高负荷 | I25: T037 创建卸车流程；T038 查询卸车流程；T039 修改卸车流程；T040 创建装船流程；T041 查询装船流程；T042 修改装船流程；T043 创建卸船流程；T044 查询卸船流程；T045 修改卸船流程；T104 吞吐量统计（曹妃甸）；T105 泊位占用率分析（曹妃甸）；T106 堆存库存统计（曹妃甸）；T107 分货主实时统计表（曹妃甸）；T108 综合装船效率分析（曹妃甸）；T109 综合卸车效率分析（曹妃甸）；T110 综合卸船效率分析（曹妃甸）；T117 经营任务情况分析报告；T118 客户月报报告；T119 月度客户情况报告；T120 商务计划周报；T138 查询卸车流程；T139 查询装船流程；T140 查询卸船流程 | L25: 刘凯
B26: 46265 | C26: 46271 | D26: 有 | E26: 5 | F26: 40 | G26: 1 | H26: 高负荷 | I26: T121 船舶供应服务查询；T122 船舶预到（内贸）查询；T123 台账查询；T124 停泊费（内贸）查询；T125 船舶供应服务费（内贸）查询 | L26: 刘凯
B27: 46272 | C27: 46278 | D27: 有 | E27: 12 | F27: 40 | G27: 1 | H27: 高负荷 | I27: T013 新增结算条款；T014 结算条款审批；T015 修改结算条款；T016 删除结算条款；T017 查询展示结算条款；T018 结算条款推送法务系统；T053 接入港口侧视频监控；T054 视频查看权限申请；T055 视频查看权限审批；T056 视频查看权限有效期控制；T057 外网PC端视频监控查询；T141 视频监控查询 | L27: 刘凯
B28: 46279 | C28: 46285 | D28: 有 | E28: 12 | F28: 40 | G28: 1 | H28: 高负荷 | I28: T013 新增结算条款；T014 结算条款审批；T015 修改结算条款；T016 删除结算条款；T017 查询展示结算条款；T018 结算条款推送法务系统；T053 接入港口侧视频监控；T054 视频查看权限申请；T055 视频查看权限审批；T056 视频查看权限有效期控制；T057 外网PC端视频监控查询；T141 视频监控查询 | L28: 刘凯
... B36: 46335 | C36: 46341 | D36: 有 | E36: 51 | F36: 40 | G36: 1 | H36: 高负荷 | I36: T005 船舶唯一性校验；T019 对接卸船计划；T020 查询卸车计划；T021 外部客户确认；T022 对接卸船作业信息；T023 查询卸船作业信息；T024 卸船查询列表；T025 卸船查询详情；T026 创建卸船作业委托信息；T027 修改卸船作业委托信息；T028 作废卸船作业委托信息；T029 推送卸船作业委托信息；T030 查询卸船作业委托信息；T031 创建外轮转内贸业务信息；T032 作废外轮转内贸业务信息；T033 查询外轮转内贸业务信息；T034 新增船舶靠泊通知单；T035 审批船舶靠泊通知单；T036 查询船舶靠泊通知单；T046 新增船舶预到（外贸）；T047 退回船舶预到（外贸）；T048 退回船舶预到（外贸）；T049 申请采样申请（外贸）；T078 业务数据合同签订校验；T079 结算数据合同签订校验；T080 合同校验结果查询；T081 数据对接；T082 数据展示；T083 数据对接；T084 数据产生；T085 数据对接；T086 数据展示；T087 数据对接；T088 数据展示；T089 新增采样服务费（外贸）；T090 审批采样服务费（外贸）；T091 单据签章；T092 数据推送；T093 数据对接；T094 数据展示；T126 停泊费（外贸）查询；T127 锚泊费（外贸）查询；T128 堆存费（外贸）查询；T129 卸船费（外贸）查询；T130 采样服务费（外贸）查询；T131 船舶供应服务费（外贸）查询；T132 新增船舶靠泊通知单；T133 查询船舶靠泊通知单；T136 卸船作业委托；T137 外轮转内贸业务查询；T142 审批船舶靠泊通知单 | L36: 刘凯
B37: 46342 | C37: 46348 | D37: 无 | E37: 0 | F37: 0 | G37: 0 | H37: 无任务 | L37: 刘凯
B38: 46349 | C38: 46355 | D38: 无 | E38: 0 | F38: 0 | G38: 0 | H38: 无任务 | L38: 刘凯
A39: 常浩 | B39: 46195 | C39: 46201 | D39: 有 | E39: 1 | F39: 40 | G39: 1 | H39: 高负荷 | I39: T069 新增、详情、修改页内容调整 | L39: 常浩
B40: 46202 | C40: 46208 | D40: 有 | E40: 1 | F40: 40 | G40: 1 | H40: 高负荷 | I40: T069 新增、详情、修改页内容调整 | L40: 常浩
B41: 46209 | C41: 46215 | D41: 有 | E41: 4 | F41: 40 | G41: 1 | H41: 高负荷 | I41: T050 维护需跟踪船舶清单；T051 根据船舶清单更新第三方系统推送数据船舶清单；T052 船舶轨迹跟踪；T095 自动生成堆存费 | L41: 常浩
B42: 46216 | C42: 46222 | D42: 有 | E42: 4 | F42: 40 | G42: 1 | H42: 高负荷 | I42: T050 维护需跟踪船舶清单；T051 根据船舶清单更新第三方系统推送数据船舶清单；T052 船舶轨迹跟踪；T095 自动生成堆存费 | L42: 常浩
B43: 46223 | C43: 46229 | D43: 有 | E43: 4 | F43: 40 | G43: 1 | H43: 高负荷 | I43: T050 维护需跟踪船舶清单；T051 根据船舶清单更新第三方系统推送数据船舶清单；T052 船舶轨迹跟踪；T095 自动生成堆存费 | L43: 常浩
B44: 46230 | C44: 46236 | D44: 有 | E44: 4 | F44: 40 | G44: 1 | H44: 高负荷 | I44: T100 创建行业资讯数据；T101 修改行业资讯数据；T102 删除行业资讯数据；T103 展示行业资讯数据 | L44: 常浩
B45: 46237 | C45: 46243 | D45: 有 | E45: 4 | F45: 40 | G45: 1 | H45: 高负荷 | I45: T100 创建行业资讯数据；T101 修改行业资讯数据；T102 删除行业资讯数据；T103 展示行业资讯数据 | L45: 常浩
B46: 46244 | C46: 46250 | D46: 有 | E46: 4 | F46: 40 | G46: 1 | H46: 高负荷 | I46: T100 创建行业资讯数据；T101 修改行业资讯数据；T102 删除行业资讯数据；T103 展示行业资讯数据 | L46: 常浩
B47: 46251 | C47: 46257 | D47: 有 | E47: 4 | F47: 40 | G47: 1 | H47: 高负荷 | I47: T100 创建行业资讯数据；T101 修改行业资讯数据；T102 删除行业资讯数据；T103 展示行业资讯数据 | L47: 常浩
B48: 46258 | C48: 46264 | D48: 有 | E48: 4 | F48: 40 | G48: 1 | H48: 高负荷 | I48: T100 创建行业资讯数据；T101 修改行业资讯数据；T102 删除行业资讯数据；T103 展示行业资讯数据 | L48: 常浩
B49: 46265 | C49: 46271 | D49: 无 | E49: 0 | F49: 0 | G49: 0 | H49: 无任务 | L49: 常浩
B50: 46272 | C50: 46278 | D50: 无 | E50: 0 | F50: 0 | G50: 0 | H50: 无任务 | L50: 常浩
...

Sheet 里程碑计划
A1: 里程碑计划与阶段门管理
A3: 里程碑ID | B3: 里程碑名称 | C3: 批次 | D3: 验收/完成标准 | E3: 责任人 | F3: 计划日期 | G3: 状态 | H3: 实际日期 | I3: 偏差天数 | J3: 健康度 | K3: 说明
A4: M01 | B4: 第一批次业务设计完成 | C4: 第一批次 | D4: 第一批次业务设计状态全部完成 | E4: 郑士旺 | F4: 46241 | G4: 未开始 | I4: =IF(H4<>"",H4-F4,MAX(0,项目驾驶舱!$B$3-F4)) -> 27 | J4: =IF(G4="已完成","绿",IF(F4<项目驾驶舱!$B$3,"红",IF(F4<=项目驾驶舱!$B$3+7,"黄","绿"))) -> 红 | K4: 69
A5: M02 | B5: 第一批次前后端开发完成 | C5: 第一批次 | D5: 第一批次前端、后端状态全部完成 | E5: 开发组 | F5: 46262 | G5: 未开始 | I5: =IF(H5<>"",H5-F5,MAX(0,项目驾驶舱!$B$3-F5)) -> 6 | J5: =IF(G5="已完成","绿",IF(F5<项目驾驶舱!$B$3,"红",IF(F5<=项目驾驶舱!$B$3+7,"黄","绿"))) -> 红 | K5: 69
A6: M03 | B6: 第一批次测试完成 | C6: 第一批次 | D6: 第一批次测试状态全部完成且无阻断缺陷 | E6: 袁丽荣 | F6: 46318 | G6: 未开始 | I6: =IF(H6<>"",H6-F6,MAX(0,项目驾驶舱!$B$3-F6)) -> 0 | J6: =IF(G6="已完成","绿",IF(F6<项目驾驶舱!$B$3,"红",IF(F6<=项目驾驶舱!$B$3+7,"黄","绿"))) -> 绿 | K6: 69
A7: M04 | B7: 第一批次上线 | C7: 第一批次 | D7: 完成上线审批、部署及回归验证 | E7: 项目经理 | F7: 46261 | G7: 未开始 | I7: =IF(H7<>"",H7-F7,MAX(0,项目驾驶舱!$B$3-F7)) -> 7 | J7: =IF(G7="已完成","绿",IF(F7<项目驾驶舱!$B$3,"红",IF(F7<=项目驾驶舱!$B$3+7,"黄","绿"))) -> 红 | K7: 69
A8: M05 | B8: 第二批次业务设计完成 | C8: 第二批次 | D8: 第二批次业务设计状态全部完成 | E8: 郑士旺 | F8: 46241 | G8: 未开始 | I8: =IF(H8<>"",H8-F8,MAX(0,项目驾驶舱!$B$3-F8)) -> 27 | J8: =IF(G8="已完成","绿",IF(F8<项目驾驶舱!$B$3,"红",IF(F8<=项目驾驶舱!$B$3+7,"黄","绿"))) -> 红 | K8: 69
A9: M06 | B9: 第二批次前后端开发完成 | C9: 第二批次 | D9: 第二批次前端、后端状态全部完成 | E9: 开发组 | F9: 46339 | G9: 未开始 | I9: =IF(H9<>"",H9-F9,MAX(0,项目驾驶舱!$B$3-F9)) -> 0 | J9: =IF(G9="已完成","绿",IF(F9<项目驾驶舱!$B$3,"红",IF(F9<=项目驾驶舱!$B$3+7,"黄","绿"))) -> 绿 | K9: 69
A10: M07 | B10: 第二批次测试完成 | C10: 第二批次 | D10: 第二批次测试状态全部完成且无阻断缺陷 | E10: 袁丽荣 | F10: 46353 | G10: 未开始 | I10: =IF(H10<>"",H10-F10,MAX(0,项目驾驶舱!$B$3-F10)) -> 0 | J10: =IF(G10="已完成","绿",IF(F10<项目驾驶舱!$B$3,"红",IF(F10<=项目驾驶舱!$B$3+7,"黄","绿"))) -> 绿 | K10: 69
A11: M08 | B11: 第二批次上线 | C11: 第二批次 | D11: 完成上线审批、部署及回归验证 | E11: 项目经理 | F11: 46261 | G11: 未开始 | I11: =IF(H11<>"",H11-F11,MAX(0,项目驾驶舱!$B$3-F11)) -> 7 | J11: =IF(G11="已完成","绿",IF(F11<项目驾驶舱!$B$3,"红",IF(F11<=项目驾驶舱!$B$3+7,"黄","绿"))) -> 红 | K11: 69
A12: M09 | B12: 外部系统集成联调完成 | C12: 全项目 | D12: 6个外部系统均完成联调确认 | E12: 集成负责人 | F12: 46346 | G12: 未开始 | I12: =IF(H12<>"",H12-F12,MAX(0,项目驾驶舱!$B$3-F12)) -> 0 | J12: =IF(G12="已完成","绿",IF(F12<项目驾驶舱!$B$3,"红",IF(F12<=项目驾驶舱!$B$3+7,"黄","绿"))) -> 绿 | K12: 69
A13: M10 | B13: 项目验收 | C13: 全项目 | D13: 完成用户验收并签署验收材料 | E13: 项目经理 | F13: 46356 | G13: 未开始 | I13: =IF(H13<>"",H13-F13,MAX(0,项目驾驶舱!$B$3-F13)) -> 0 | J13: =IF(G13="已完成","绿",IF(F13<项目驾驶舱!$B$3,"红",IF(F13<=项目驾驶舱!$B$3+7,"黄","绿"))) -> 绿 | K13: 69

Sheet 周迭代计划
A1: 周迭代计划与完成跟踪
A3: 迭代周 | B3: 开始日期 | C3: 结束日期 | D3: 功能设计 | E3: 前端开发 | F3: 后端开发 | G3: 功能测试 | H3: 本周完成率 | I3: 复盘说明
A4: 1 | B4: 46195 | C4: 46199 | D4: 装船计划编制及推送、卸船作业信息录入优化（太仓）、装船作业信息录入优化（太仓） | E4: 装船计划编制及推送、卸船作业信息录入优化（太仓）、装船作业信息录入优化（太仓） | F4: 装船计划编制及推送、卸船作业信息录入优化（太仓）、装船作业信息录入优化（太仓） | G4: / | H4: =IF(COUNTA(D4:G4)=0,0,(IF(AND(D4<>"",D4<>"/"),1,0)+IF(AND(E4<>"",E4<>"/"),1,0)+IF(AND(F4<>"",F4<>"/"),1,0)+IF(AND(G4<>"",G4<>"/"),1,0))/4) -> 0.75
A5: 2 | B5: 46202 | C5: 46206 | D5: 车辆信息维护、交易中心报单信息展示及应单入口、船舶轨迹跟踪、货权跟踪、货权提醒、船舶预到优化（太仓）、堆存费优化（太仓）、港杂费优化(太仓）、收费标准信息维护、采样方式信息维护、装卸费结算、租赁费结算、采样作业信息录入 | G5: 装船计划编制及推送、卸船作业信息录入优化（太仓）、装船作业信息录入优化（太仓） | H5: =IF(COUNTA(D5:G5)=0,0,(IF(AND(D5<>"",D5<>"/"),1,0)+IF(AND(E5<>"",E5<>"/"),1,0)+IF(AND(F5<>"",F5<>"/"),1,0)+IF(AND(G5<>"",G5<>"/"),1,0))/4) -> 0.5
A6: 3 | B6: 46209 | C6: 46213 | D6: 卸车流程跟踪、装船流程跟踪、卸船流程跟踪、行业资讯、统计分析 | E6: 车辆信息维护、交易中心报单信息展示及应单入口、船舶轨迹跟踪、货权跟踪、货权提醒、船舶预到优化（太仓）、堆存费优化（太仓）、港杂费优化(太仓）、收费标准信息维护、采样方式信息维护、装卸费结算、租赁费结算、采样作业信息录入 | F6: 车辆信息维护、交易中心报单信息展示及应单入口、船舶轨迹跟踪、货权跟踪、货权提醒、船舶预到优化（太仓）、堆存费优化（太仓）、港杂费优化(太仓）、收费标准信息维护、采样方式信息维护、装卸费结算、租赁费结算、采样作业信息录入 | H6: =IF(COUNTA(D6:G6)=0,0,(IF(AND(D6<>"",D6<>"/"),1,0)+IF(AND(E6<>"",E6<>"/"),1,0)+IF(AND(F6<>"",F6<>"/"),1,0)+IF(AND(G6<>"",G6<>"/"),1,0))/4) -> 0.75
A7: 4 | B7: 46216 | C7: 46220 | D7: APP：船舶供应服务查询、船舶预到（内贸）查询、台账查询、停泊费（内贸）查询、船舶供应服务费（内贸）查询 | G7: 车辆信息维护、交易中心报单信息展示及应单入口、船舶轨迹跟踪、货权跟踪、货权提醒、船舶预到优化（太仓）、堆存费优化（太仓）、港杂费优化（太仓）、收费标准信息维护、采样方式信息维护、装卸费结算、租赁费结算、采样作业信息录入 | H7: =IF(COUNTA(D7:G7)=0,0,(IF(AND(D7<>"",D7<>"/"),1,0)+IF(AND(E7<>"",E7<>"/"),1,0)+IF(AND(F7<>"",F7<>"/"),1,0)+IF(AND(G7<>"",G7<>"/"),1,0))/4) -> 0.5
A8: 5 | B8: 46223 | C8: 46227 | D8: 结算条款管理、协同视览、费用合同签订校验 | H8: =IF(COUNTA(D8:G8)=0,0,(IF(AND(D8<>"",D8<>"/"),1,0)+IF(AND(E8<>"",E8<>"/"),1,0)+IF(AND(F8<>"",F8<>"/"),1,0)+IF(AND(G8<>"",G8<>"/"),1,0))/4) -> 0.25
A9: 6 | B9: 46230 | C9: 46234 | D9: 船舶唯一性校验、卸船作业、船舶预到（外贸）、退回船舶预到（外贸）、采样申请（外贸）、停泊费（外贸）、锚泊费（外贸）、堆存费（外贸）、卸船费（外贸）、采样服务费（外贸）、船舶供应服务费（外贸） | E9: 卸车流程跟踪、装船流程跟踪、卸船流程跟踪、行业资讯、统计分析、自动报告 | F9: 卸车流程跟踪、装船流程跟踪、卸船流程跟踪、行业资讯、统计分析、自动报告 | H9: =IF(COUNTA(D9:G9)=0,0,(IF(AND(D9<>"",D9<>"/"),1,0)+IF(AND(E9<>"",E9<>"/"),1,0)+IF(AND(F9<>"",F9<>"/"),1,0)+IF(AND(G9<>"",G9<>"/"),1,0))/4) -> 0.75
A10: 7 | B10: 46237 | C10: 46241 | H10: =IF(COUNTA(D10:G10)=0,0,(IF(AND(D10<>"",D10<>"/"),1,0)+IF(AND(E10<>"",E10<>"/"),1,0)+IF(AND(F10<>"",F10<>"/"),1,0)+IF(AND(G10<>"",G10<>"/"),1,0))/4) -> 0
A11: 8 | B11: 46244 | C11: 46248 | H11: =IF(COUNTA(D11:G11)=0,0,(IF(AND(D11<>"",D11<>"/"),1,0)+IF(AND(E11<>"",E11<>"/"),1,0)+IF(AND(F11<>"",F11<>"/"),1,0)+IF(AND(G11<>"",G11<>"/"),1,0))/4) -> 0
A12: 9 | B12: 46251 | C12: 46255 | G12: 卸车流程跟踪、装船流程跟踪、卸船流程跟踪、行业资讯、统计分析、自动报告 | H12: =IF(COUNTA(D12:G12)=0,0,(IF(AND(D12<>"",D12<>"/"),1,0)+IF(AND(E12<>"",E12<>"/"),1,0)+IF(AND(F12<>"",F12<>"/"),1,0)+IF(AND(G12<>"",G12<>"/"),1,0))/4) -> 0.25
A13: 10 | B13: 46258 | C13: 46262 | H13: =IF(COUNTA(D13:G13)=0,0,(IF(AND(D13<>"",D13<>"/"),1,0)+IF(AND(E13<>"",E13<>"/"),1,0)+IF(AND(F13<>"",F13<>"/"),1,0)+IF(AND(G13<>"",G13<>"/"),1,0))/4) -> 0
A14: 11 | B14: 46265 | C14: 46269 | E14: APP：船舶供应服务查询、船舶预到（内贸）查询、台账查询、停泊费（内贸）查询、船舶供应服务费（内贸）查询 | F14: APP：船舶供应服务查询、船舶预到（内贸）查询、台账查询、停泊费（内贸）查询、船舶供应服务费（内贸）查询 | H14: =IF(COUNTA(D14:G14)=0,0,(IF(AND(D14<>"",D14<>"/"),1,0)+IF(AND(E14<>"",E14<>"/"),1,0)+IF(AND(F14<>"",F14<>"/"),1,0)+IF(AND(G14<>"",G14<>"/"),1,0))/4) -> 0.5
A15: 12 | B15: 46272 | C15: 46276 | E15: 结算条款管理、协同视览、费用合同签订校验 | F15: 结算条款管理、协同视览、费用合同签订校验 | G15: APP：船舶供应服务查询、船舶预到（内贸）查询、台账查询、停泊费（内贸）查询、船舶供应服务费（内贸）查询 | H15: =IF(COUNTA(D15:G15)=0,0,(IF(AND(D15<>"",D15<>"/"),1,0)+IF(AND(E15<>"",E15<>"/"),1,0)+IF(AND(F15<>"",F15<>"/"),1,0)+IF(AND(G15<>"",G15<>"/"),1,0))/4) -> 0.75
A16: 13 | B16: 46279 | C16: 46283 | H16: =IF(COUNTA(D16:G16)=0,0,(IF(AND(D16<>"",D16<>"/"),1,0)+IF(AND(E16<>"",E16<>"/"),1,0)+IF(AND(F16<>"",F16<>"/"),1,0)+IF(AND(G16<>"",G16<>"/"),1,0))/4) -> 0
A17: 14 | B17: 46286 | C17: 46290 | H17: =IF(COUNTA(D17:G17)=0,0,(IF(AND(D17<>"",D17<>"/"),1,0)+IF(AND(E17<>"",E17<>"/"),1,0)+IF(AND(F17<>"",F17<>"/"),1,0)+IF(AND(G17<>"",G17<>"/"),1,0))/4) -> 0
A18: 15 | B18: 46293 | C18: 46297 | H18: =IF(COUNTA(D18:G18)=0,0,(IF(AND(D18<>"",D18<>"/"),1,0)+IF(AND(E18<>"",E18<>"/"),1,0)+IF(AND(F18<>"",F18<>"/"),1,0)+IF(AND(G18<>"",G18<>"/"),1,0))/4) -> 0
A19: 16 | B19: 46300 | C19: 46304 | H19: =IF(COUNTA(D19:G19)=0,0,(IF(AND(D19<>"",D19<>"/"),1,0)+IF(AND(E19<>"",E19<>"/"),1,0)+IF(AND(F19<>"",F19<>"/"),1,0)+IF(AND(G19<>"",G19<>"/"),1,0))/4) -> 0
A20: 17 | B20: 46307 | C20: 46311 | E20: 船舶唯一性校验、卸船作业、船舶预到（外贸）、退回船舶预到（外贸）、采样申请（外贸）、停泊费（外贸）、锚泊费（外贸）、堆存费（外贸）、卸船费（外贸）、采样服务费（外贸）、船舶供应服务费（外贸） | F20: 船舶唯一性校验、卸船作业、船舶预到（外贸）、退回船舶预到（外贸）、采样申请（外贸）、停泊费（外贸）、锚泊费（外贸）、堆存费（外贸）、卸船费（外贸）、采样服务费（外贸）、船舶供应服务费（外贸） | G20: 结算条款管理、协同视览、费用合同签订校验 | H20: =IF(COUNTA(D20:G20)=0,0,(IF(AND(D20<>"",D20<>"/"),1,0)+IF(AND(E20<>"",E20<>"/"),1,0)+IF(AND(F20<>"",F20<>"/"),1,0)+IF(AND(G20<>"",G20<>"/"),1,0))/4) -> 0.75
A21: 18 | B21: 46314 | C21: 46318 | H21: =IF(COUNTA(D21:G21)=0,0,(IF(AND(D21<>"",D21<>"/"),1,0)+IF(AND(E21<>"",E21<>"/"),1,0)+IF(AND(F21<>"",F21<>"/"),1,0)+IF(AND(G21<>"",G21<>"/"),1,0))/4) -> 0
A22: 19 | B22: 46321 | C22: 46325 | H22: =IF(COUNTA(D22:G22)=0,0,(IF(AND(D22<>"",D22<>"/"),1,0)+IF(AND(E22<>"",E22<>"/"),1,0)+IF(AND(F22<>"",F22<>"/"),1,0)+IF(AND(G22<>"",G22<>"/"),1,0))/4) -> 0
A23: 20 | B23: 46328 | C23: 46332 | H23: =IF(COUNTA(D23:G23)=0,0,(IF(AND(D23<>"",D23<>"/"),1,0)+IF(AND(E23<>"",E23<>"/"),1,0)+IF(AND(F23<>"",F23<>"/"),1,0)+IF(AND(G23<>"",G23<>"/"),1,0))/4) -> 0
A24: 21 | B24: 46335 | C24: 46339 | H24: =IF(COUNTA(D24:G24)=0,0,(IF(AND(D24<>"",D24<>"/"),1,0)+IF(AND(E24<>"",E24<>"/"),1,0)+IF(AND(F24<>"",F24<>"/"),1,0)+IF(AND(G24<>"",G24<>"/"),1,0))/4) -> 0
A25: 22 | B25: 46342 | C25: 46346 | G25: 船舶唯一性校验、卸船作业、船舶预到（外贸）、退回船舶预到（外贸）、采样申请（外贸）、停泊费（外贸）、锚泊费（外贸）、堆存费（外贸）、卸船费（外贸）、采样服务费（外贸）、船舶供应服务费（外贸） | H25: =IF(COUNTA(D25:G25)=0,0,(IF(AND(D25<>"",D25<>"/"),1,0)+IF(AND(E25<>"",E25<>"/"),1,0)+IF(AND(F25<>"",F25<>"/"),1,0)+IF(AND(G25<>"",G25<>"/"),1,0))/4) -> 0.25
A26: 23 | B26: 46349 | C26: 46353 | H26: =IF(COUNTA(D26:G26)=0,0,(IF(AND(D26<>"",D26<>"/"),1,0)+IF(AND(E26<>"",E26<>"/"),1,0)+IF(AND(F26<>"",F26<>"/"),1,0)+IF(AND(G26<>"",G26<>"/"),1,0))/4) -> 0

Sheet 集成管理
A1: 外部系统集成管理
A3: 集成ID | B3: 集成系统 | C3: 交互方式 | D3: 对接人 | E3: 集成内容 | F3: 原计划进展 | G3: 管理状态 | H3: 计划完成 | I3: 实际完成 | J3: 依赖事项 | K3: 风险等级 | L3: 风险/备注
A4: INT-01 | B4: 调运系统 | C4: 接入 | D4: 佘万明 | E4: 船舶轨迹位置、船舶档案、海图信息 | F4: 已完成 | G4: 已完成 | K4: 中
A5: INT-02 | B5: 法治平台 | C5: 接入 | D5: 许祥 | E5: 曹妃甸港、太仓港合同信息 | F5: 已初步对接，对方已提供接口文档，数据清单 | G5: 进行中 | K5: 高 | L5: 1.进度风险：法制平台7月上线试点运行，会在10月份全面上线，相关功能应用需在10月份后才能上线； 2.功能风险：企法部要求法制平台咱不提供接收合同接口，无法满足客户在本系统录入合同的需求，已与用户反馈，用户内部需进行评估
A6: INT-03 | B6: 集团大模型服务 | C6: 接入 | D6: 李超来 | E6: OCR能力 | F6: 已完成 | G6: 已完成 | K6: 高 | L6: 1.效率风险：文件识别效率偏低，需1分钟左右
A7: INT-04 | B7: 港航部科技项目系统 | C7: 接入 | E7: 曹妃甸港、太仓港视频监控数据 | F7: 已初步对接，对方预计10月份具备接口联调条件 | G7: 进行中 | K7: 高 | L7: 1.科技项目不会对接全部生产作业视频监控数据，需确认科技项目对接范围后确认是否满足用户需求
A8: INT-05 | B8: 曹妃甸管控一体化系统 | C8: 接入、推送 | D8: 张应龙 | E8: 基础数据、业务数据、结算数据 | F8: 未对接 | G8: 未开始 | K8: 中 | L8: 暂无
A9: INT-06 | B9: 太仓港管控一体化系统 | C9: 接入、推送 | D9: / | E9: 基础数据、业务数据、结算数据 | F9: 未对接 | G9: 未开始 | K9: 高 | L9: 1.太仓港管控一体化系统刚立项，集成工作暂时无法开展

Sheet 风险问题台账
A1: 风险与问题闭环台账
A3: 编号 | B3: 类型 | C3: 风险/问题描述 | D3: 等级 | E3: 影响范围 | F3: 责任人 | G3: 应对措施 | H3: 计划关闭 | I3: 实际关闭 | J3: 触发条件/根因 | K3: 状态 | L3: 剩余天数 | M3: 是否逾期 | N3: 跟踪记录
A4: R-001 | B4: 风险 | C4: 法治平台全面上线时间影响相关功能投产 | D4: 高 | E4: 合同信息集成 | F4: 集成负责人 | G4: 确认对方正式上线窗口，制定模拟数据和延期切换方案 | H4: 46310 | J4: 对方10月后方可正式支撑 | K4: 处理中 | L4: =IF(H4="","",H4-项目驾驶舱!$B$3) -> 42 | M4: =IF(OR(K4="已关闭",H4=""),"否",IF(H4<项目驾驶舱!$B$3,"是","否")) -> 否 | N4: 来源：原计划-集成工作
A5: R-002 | B5: 风险 | C5: 法治平台不提供合同接收接口，可能无法满足本系统录入合同需求 | D5: 高 | E5: 合同业务闭环 | F5: 项目经理 | G5: 推动用户决策，形成接口边界与替代方案确认单 | H5: 46283 | J5: 接口能力与业务诉求不一致 | K5: 待处理 | L5: =IF(H5="","",H5-项目驾驶舱!$B$3) -> 15 | M5: =IF(OR(K5="已关闭",H5=""),"否",IF(H5<项目驾驶舱!$B$3,"是","否")) -> 否 | N5: 来源：原计划-集成工作
A6: R-003 | B6: 风险 | C6: OCR识别耗时约1分钟，影响业务效率 | D6: 中 | E6: OCR能力 | F6: 技术负责人 | G6: 压测典型文件，确定超时阈值、异步处理与结果回调方案 | H6: 46290 | J6: 外部大模型服务性能 | K6: 处理中 | L6: =IF(H6="","",H6-项目驾驶舱!$B$3) -> 22 | M6: =IF(OR(K6="已关闭",H6=""),"否",IF(H6<项目驾驶舱!$B$3,"是","否")) -> 否 | N6: 来源：原计划-集成工作
A7: R-004 | B7: 风险 | C7: 视频监控数据对接范围尚未明确 | D7: 高 | E7: 视频监控 | F7: 集成负责人 | G7: 确认科技项目覆盖清单并补充缺口方案 | H7: 46280 | J7: 上游系统范围不确定 | K7: 待处理 | L7: =IF(H7="","",H7-项目驾驶舱!$B$3) -> 12 | M7: =IF(OR(K7="已关闭",H7=""),"否",IF(H7<项目驾驶舱!$B$3,"是","否")) -> 否 | N7: 来源：原计划-集成工作
A8: R-005 | B8: 风险 | C8: 太仓港管控一体化系统刚立项，集成工作无法按期开展 | D8: 高 | E8: 太仓港数据集成 | F8: 项目经理 | G8: 拆分依赖与非依赖工作，设立外部条件就绪门槛 | H8: 46326 | J8: 外部项目未形成可对接环境 | K8: 处理中 | L8: =IF(H8="","",H8-项目驾驶舱!$B$3) -> 58 | M8: =IF(OR(K8="已关闭",H8=""),"否",IF(H8<项目驾驶舱!$B$3,"是","否")) -> 否 | N8: 来源：原计划-集成工作
A9: R-006 | B9: 风险 | C9: 第二批次存在大量未开始任务，后续开发测试窗口集中 | D9: 高 | E9: 第二批次 | F9: 开发负责人 | G9: 按关键路径重排优先级，按周跟踪启动率与完成率 | H9: 46276 | J9: 资源与工作量集中 | K9: 待处理 | L9: =IF(H9="","",H9-项目驾驶舱!$B$3) -> 8 | M9: =IF(OR(K9="已关闭",H9=""),"否",IF(H9<项目驾驶舱!$B$3,"是","否")) -> 否 | N9: 基于开发计划识别
L10: =IF(H10="","",H10-项目驾驶舱!$B$3) | M10: =IF(OR(K10="已关闭",H10=""),"否",IF(H10<项目驾驶舱!$B$3,"是","否")) -> 否
L11: =IF(H11="","",H11-项目驾驶舱!$B$3) | M11: =IF(OR(K11="已关闭",H11=""),"否",IF(H11<项目驾驶舱!$B$3,"是","否")) -> 否
L12: =IF(H12="","",H12-项目驾驶舱!$B$3) | M12: =IF(OR(K12="已关闭",H12=""),"否",IF(H12<项目驾驶舱!$B$3,"是","否")) -> 否
L13: =IF(H13="","",H13-项目驾驶舱!$B$3) | M13: =IF(OR(K13="已关闭",H13=""),"否",IF(H13<项目驾驶舱!$B$3,"是","否")) -> 否
L14: =IF(H14="","",H14-项目驾驶舱!$B$3) | M14: =IF(OR(K14="已关闭",H14=""),"否",IF(H14<项目驾驶舱!$B$3,"是","否")) -> 否
L15: =IF(H15="","",H15-项目驾驶舱!$B$3) | M15: =IF(OR(K15="已关闭",H15=""),"否",IF(H15<项目驾驶舱!$B$3,"是","否")) -> 否
L16: =IF(H16="","",H16-项目驾驶舱!$B$3) | M16: =IF(OR(K16="已关闭",H16=""),"否",IF(H16<项目驾驶舱!$B$3,"是","否")) -> 否
L17: =IF(H17="","",H17-项目驾驶舱!$B$3) | M17: =IF(OR(K17="已关闭",H17=""),"否",IF(H17<项目驾驶舱!$B$3,"是","否")) -> 否
L18: =IF(H18="","",H18-项目驾驶舱!$B$3) | M18: =IF(OR(K18="已关闭",H18=""),"否",IF(H18<项目驾驶舱!$B$3,"是","否")) -> 否
L19: =IF(H19="","",H19-项目驾驶舱!$B$3) | M19: =IF(OR(K19="已关闭",H19=""),"否",IF(H19<项目驾驶舱!$B$3,"是","否")) -> 否
L20: =IF(H20="","",H20-项目驾驶舱!$B$3) | M20: =IF(OR(K20="已关闭",H20=""),"否",IF(H20<项目驾驶舱!$B$3,"是","否")) -> 否
L21: =IF(H21="","",H21-项目驾驶舱!$B$3) | M21: =IF(OR(K21="已关闭",H21=""),"否",IF(H21<项目驾驶舱!$B$3,"是","否")) -> 否
... L103: =IF(H103="","",H103-项目驾驶舱!$B$3) | M103: =IF(OR(K103="已关闭",H103=""),"否",IF(H103<项目驾驶舱!$B$3,"是","否")) -> 否

Sheet 变更台账
A1: 项目变更台账
A3: 变更编号 | B3: 提出日期 | C3: 提出人 | D3: 变更内容 | E3: 变更原因 | F3: 优先级 | G3: 审批状态 | H3: 范围影响 | I3: 工期影响(天) | J3: 成本影响 | K3: 评估人 | L3: 批准人 | M3: 实施日期 | N3: 关闭说明

Sheet 交付物台账
A1: 项目交付物与质量门禁
A3: 交付物ID | B3: 交付物名称 | C3: 类别 | D3: 责任人 | E3: 计划完成 | F3: 实际完成 | G3: 状态 | H3: 评审人 | I3: 评审结论 | J3: 版本/存放位置 | K3: 备注
A4: D-001 | B4: 项目管理计划 | C4: 管理 | D4: 项目经理 | E4: 46192 | G4: 进行中 | H4: 项目负责人 | I4: 待评审 | J4: 69 | K4: 69
A5: D-002 | B5: 业务需求规格说明书 | C5: 需求 | D5: 郑士旺 | E5: 46241 | G5: 进行中 | H5: 业务负责人 | I5: 待评审 | J5: 69 | K5: 69
A6: D-003 | B6: 系统总体设计说明书 | C6: 设计 | D6: 技术负责人 | E6: 46248 | G6: 进行中 | H6: 架构负责人 | I6: 待评审 | J6: 69 | K6: 69
A7: D-004 | B7: 接口清单及接口设计说明 | C7: 集成 | D7: 集成负责人 | E7: 46283 | G7: 进行中 | H7: 技术负责人 | I7: 待评审 | J7: 69 | K7: 69
A8: D-005 | B8: 第一批次测试报告 | C8: 测试 | D8: 袁丽荣 | E8: 46318 | G8: 进行中 | H8: 项目经理 | I8: 待评审 | J8: 69 | K8: 69
A9: D-006 | B9: 第二批次测试报告 | C9: 测试 | D9: 袁丽荣 | E9: 46353 | G9: 未开始 | H9: 项目经理 | I9: 待评审 | J9: 69 | K9: 69
A10: D-007 | B10: 上线方案及回退方案 | C10: 上线 | D10: 运维负责人 | E10: 46346 | G10: 未开始 | H10: 项目经理 | I10: 待评审 | J10: 69 | K10: 69
A11: D-008 | B11: 用户操作手册 | C11: 培训 | D11: 实施负责人 | E11: 46349 | G11: 未开始 | H11: 业务负责人 | I11: 待评审 | J11: 69 | K11: 69
A12: D-009 | B12: 用户验收报告 | C12: 验收 | D12: 项目经理 | E12: 46356 | G12: 未开始 | H12: 项目负责人 | I12: 待评审 | J12: 69 | K12: 69
A13: D-010 | B13: 项目总结与移交清单 | C13: 收尾 | D13: 项目经理 | E13: 46360 | G13: 未开始 | H13: 项目负责人 | I13: 待评审 | J13: 69 | K13: 69

Sheet 会议行动项
A1: 会议纪要与行动项跟踪
A3: 行动项ID | B3: 会议日期 | C3: 会议主题 | D3: 决策/行动事项 | E3: 责任人 | F3: 协同人 | G3: 截止日期 | H3: 状态 | I3: 完成日期 | J3: 逾期天数 | K3: 优先级 | L3: 结果说明
J4: =IF(OR(G4="",H4="已完成"),0,MAX(0,项目驾驶舱!$B$3-G4)) -> 0
J5: =IF(OR(G5="",H5="已完成"),0,MAX(0,项目驾驶舱!$B$3-G5)) -> 0
