Workbook

Sheet 使用说明
A1: 计划与进度管理-20260921-V1 使用说明
A2: 维护里程碑、总控任务、资源周计划和迭代承诺。
A4: 项目 | B4: 能源行业合同全生命周期管理系统
A5: 适用对象 | B5: 项目集经理、项目经理、各工作流负责人
A6: 更新频率 | B6: 每周滚动更新；里程碑和基线变化须同步评审。
A7: 版本日期 | B7: 46288
A8: 颜色约定 | B8: 浅蓝表头；黄色为人工输入区；白色/灰色通常为公式、说明或系统数据。
A10: 推荐使用流程
A11: 1 | B11: 先维护里程碑基线
A12: 2 | B12: 细化总控台账任务和责任人
A13: 3 | B13: 按人员核对每周40小时资源负荷
A14: 4 | B14: 按接口清单落实外部系统责任人、联调窗口和前置条件
A15: 5 | B15: 复核延期、挂起、暂停和阻塞项
A18: 工作表导航
A19: 顺序 | B19: 工作表 | C19: 用途
A20: 1 | B20: 里程碑计划 | C20: 维护阶段里程碑、计划与实际日期。
A21: 2 | B21: 项目总控台账 | C21: 原始维护页；按层级合并展示，不建议直接筛选或排序。
A22: 3 | B22: 资源计划 | C22: 按人员查看每周任务和工时负荷。
A23: 4 | B23: 周迭代计划 | C23: 管理当周承诺、执行结果和滚动安排。
A24: 5 | B24: _数据接口 | C24: 供AI PMO和跨文件联动使用的内部数据
A26: 维护与检查规则
A27: 1 | B27: 先维护唯一编号、责任人、计划日期和状态，再补充说明与证据。
A28: 2 | B28: 状态变化时同步更新实际日期、完成比例、阻塞原因或验证结果。
A29: 3 | B29: 涉及基线、预算、范围、合同或上线门禁的变化，须先履行评审或审批。
A30: 4 | B30: 不要覆盖公式、汇总区、图表数据区和“_数据接口”中的系统字段。
A31: 5 | B31: 每周检查空责任人、逾期未完成、状态与日期矛盾、缺少证据和公式错误。
A32: 6 | B32: 文件升级后，将被替换版本移入本模块_archive目录，不在正式目录保留多个现行版本。
A33: 系统集成联动 | B33: 总控台账T096-T135保留40个系统/阶段工作包；470项实施明细在系统集成管理V1维护
A34: 资源同步规则 | B34: 系统集成建议资源按人员和总控任务同步到资源计划；多人并行时共享个人当周40小时，具体任务工时在说明列展示
A35: 文件边界 | B35: 计划文件负责里程碑与总控；系统集成文件负责规格、实施、联调、测试和上线证据
A36: 总控筛选视图 | B36: 只读公式联动页；用于筛选、排序和快速定位任务，所有业务数据仍在项目总控台账维护。
A37: 迭代周生成 | B37: 在项目总控台账AF列"迭代周"填 ISO 周（如 2026-W40）人工指定迭代；留空不纳入。填写后运行 automation/scripts/generate_iteration_plan.py --apply 生成周迭代计划明细（任务ID联动，改总控自动跟随）。
A38: 总体状态回算 | B38: G列"总体状态"由公式按四专业状态（M/Q/U/Y列）自动回算：暂停/挂起→暂停，全部完成→已完成，有进行中→进行中，有待确认→待确认，其余→未开始，无责任人→未分配。人工只维护四专业状态列，勿改G列公式。
A39: 预测完成日期 | B39: AG列人工维护：每次迭代评审后刷新该任务的当前预测完成日期，留空表示尚未评估。
A40: 基线偏差天数 | B40: AH列公式自动计算＝预测完成日期－基线计划完成（J列），负数表示预计早于基线。

Sheet 里程碑计划
A1: 能源行业合同全生命周期管理系统｜里程碑计划
A3: 里程碑ID | B3: 阶段 | C3: 里程碑名称 | D3: 验收/完成标准 | E3: 负责人 | F3: 配合人 | G3: 计划开始日期 | H3: 计划结束日期 | I3: 实际开始日期 | J3: 实际结束日期 | K3: 状态 | L3: 偏差天数 | M3: 健康度 | N3: 交付物
A4: MS001 | B4: 可研与原业务梳理 | C4: 可研工作启动 | D4: 范围、负责人和调研计划确认 | E4: 项目经理 | F4: 项目集经理、产品经理 | G4: 46054 | H4: 46063 | I4: 46054 | J4: 46063 | K4: 已完成 | L4: =IF(J4<>"",J4-H4,MAX(0,DATE(2026,9,16)-H4)) -> 0 | M4: =IF(K4="已完成","绿",IF(H4<DATE(2026,9,16),"红",IF(H4<=DATE(2026,9,23),"黄","绿"))) -> 绿 | N4: 可研工作方案
A5: MS002 | C5: 可行性研究完成 | D5: 业务、技术、投资和实施可行性完成评审 | E5: 项目经理 | F5: 技术经理、产品经理 | G5: 46054 | H5: 46283 | I5: 46054 | J5: 46283 | K5: 已完成 | L5: =IF(J5<>"",J5-H5,MAX(0,DATE(2026,9,16)-H5)) -> 0 | M5: =IF(K5="已完成","绿",IF(H5<DATE(2026,9,16),"红",IF(H5<=DATE(2026,9,23),"黄","绿"))) -> 绿 | N5: 项目可行性研究报告
A6: MS003 | C6: 原业务梳理完成 | D6: 核心业务部门确认现状基线 | E6: 产品经理 | F6: 项目经理、业务代表 | G6: 46153 | H6: 46295 | I6: 46153 | K6: 进行中 | L6: =IF(J6<>"",J6-H6,MAX(0,DATE(2026,9,16)-H6)) -> 0 | M6: =IF(K6="已完成","绿",IF(H6<DATE(2026,9,16),"红",IF(H6<=DATE(2026,9,23),"黄","绿"))) -> 绿 | N6: 现状流程、问题及改进机会清单
A7: MS004 | B7: 项目规范梳理与技术架构搭建 | C7: 项目规范基线确认 | D7: 计划、需求、质量、变更和配置规范通过评审 | E7: 项目经理 | F7: 项目集经理、技术经理、产品经理、高级测试人员、中级测试人员、配置人员 | G7: 46204 | H7: 46265 | I7: 46204 | J7: 46265 | K7: 已完成 | L7: =IF(J7<>"",J7-H7,MAX(0,DATE(2026,9,16)-H7)) -> 0 | M7: =IF(K7="已完成","绿",IF(H7<DATE(2026,9,16),"红",IF(H7<=DATE(2026,9,23),"黄","绿"))) -> 绿 | N7: 项目管理与研发规范
A8: MS005 | C8: 技术架构基线确认 | D8: 应用、数据、集成、安全和部署架构通过评审 | E8: 技术经理 | F8: 高级开发人员、配置人员 | G8: 46204 | H8: 46295 | I8: 46204 | K8: 进行中 | L8: =IF(J8<>"",J8-H8,MAX(0,DATE(2026,9,16)-H8)) -> 0 | M8: =IF(K8="已完成","绿",IF(H8<DATE(2026,9,16),"红",IF(H8<=DATE(2026,9,23),"黄","绿"))) -> 绿 | N8: 总体技术架构和环境基础
A9: MS017 | C9: 外部产品POC验证完成 | D9: CA完成证书签发、身份认证、电子签名及验签验证；电子文档完成模板生成、在线预览、格式转换、水印和归档验证；BI报表完成核心经营指标、权限控制、钻取导出及性能验证；三类产品形成问题清单、适配结论和选型建议并通过评审 | E9: 技术经理 | F9: 项目经理、产品经理、高级开发人员、高级测试人员、中级测试人员、外部产品厂商 | G9: 46249 | H9: 46320 | I9: 46249 | K9: 进行中 | L9: =IF(J9<>"",J9-H9,MAX(0,DATE(2026,9,16)-H9)) -> 0 | M9: =IF(K9="已完成","绿",IF(H9<DATE(2026,9,16),"红",IF(H9<=DATE(2026,9,23),"黄","绿"))) -> 绿 | N9: CA、电子文档、BI报表POC报告、量化评分表、联合评审记录及产品选型建议
A10: MS006 | B10: 正式启动准备 | C10: 启动准备评审通过 | D10: 范围、组织、预算、计划和治理机制具备启动条件 | E10: 项目集经理 | F10: 项目经理、技术经理、产品经理 | G10: 46296 | H10: 46311 | K10: 未开始 | L10: =IF(J10<>"",J10-H10,MAX(0,DATE(2026,9,16)-H10)) -> 0 | M10: =IF(K10="已完成","绿",IF(H10<DATE(2026,9,16),"红",IF(H10<=DATE(2026,9,23),"黄","绿"))) -> 绿 | N10: 项目章程、整体管理计划、启动门禁清单及评审结论
A11: MS007 | B11: 正式实施与上线准备 | C11: 项目正式启动 | D11: 项目组织到位、职责明确、计划发布 | E11: 项目集经理 | F11: 项目经理、技术经理、产品经理 | G11: 46315 | H11: 46315 | K11: 未开始 | L11: =IF(J11<>"",J11-H11,MAX(0,DATE(2026,9,16)-H11)) -> 0 | M11: =IF(K11="已完成","绿",IF(H11<DATE(2026,9,16),"红",IF(H11<=DATE(2026,9,23),"黄","绿"))) -> 绿 | N11: 启动会纪要与行动项
A12: MS008 | C12: 需求基线确认 | D12: P0/P1/P2范围、验收标准和变更机制确认 | E12: 产品经理 | F12: 项目经理、业务代表、技术经理 | G12: 46316 | H12: 46356 | K12: 未开始 | L12: =IF(J12<>"",J12-H12,MAX(0,DATE(2026,9,16)-H12)) -> 0 | M12: =IF(K12="已完成","绿",IF(H12<DATE(2026,9,16),"红",IF(H12<=DATE(2026,9,23),"黄","绿"))) -> 绿 | N12: 需求规格说明书与跟踪矩阵
A13: MS009 | C13: 详细设计完成 | D13: 核心模块、数据、权限和安全设计通过评审；94条P0接口完成规格编制并获得合同系统、外部系统、业务和测试联合批准 | E13: 技术经理 | F13: 产品经理、高级开发人员、配置人员 | G13: 46341 | H13: 46387 | K13: 未开始 | L13: =IF(J13<>"",J13-H13,MAX(0,DATE(2026,9,16)-H13)) -> 0 | M13: =IF(K13="已完成","绿",IF(H13<DATE(2026,9,16),"红",IF(H13<=DATE(2026,9,23),"黄","绿"))) -> 绿 | N13: 详细设计、数据设计、94条P0接口批准版规格及评审记录
A14: MS010 | C14: 核心功能开发完成 | D14: P0功能完成且单元测试通过 | E14: 高级开发人员 | F14: 技术经理、中级开发人员、高级测试人员、中级测试人员 | G14: 46357 | H14: 46461 | K14: 未开始 | L14: =IF(J14<>"",J14-H14,MAX(0,DATE(2026,9,16)-H14)) -> 0 | M14: =IF(K14="已完成","绿",IF(H14<DATE(2026,9,16),"红",IF(H14<=DATE(2026,9,23),"黄","绿"))) -> 绿 | N14: 可测试版本
A15: MS011 | C15: 内部系统集成完成 | D15: 合同起草、审批、履约、收付款、变更、归档、权限和数据流端到端贯通 | E15: 技术经理 | F15: 高级开发人员、中级开发人员、高级测试人员、中级测试人员、配置人员 | G15: 46419 | H15: 46456 | K15: 未开始 | L15: =IF(J15<>"",J15-H15,MAX(0,DATE(2026,9,16)-H15)) -> 0 | M15: =IF(K15="已完成","绿",IF(H15<DATE(2026,9,16),"红",IF(H15<=DATE(2026,9,23),"黄","绿"))) -> 绿 | N15: 内部集成测试报告
A16: MS012 | C16: 外部系统集成完成 | D16: 接口范围分级经联合评审批准；P0 94条接口完成规格、责任、环境、联调、异常补偿和对账验证；P1/P2形成后续排期 | E16: 技术经理 | F16: 高级开发人员、中级开发人员、高级测试人员、中级测试人员、外部接口负责人 | G16: 46433 | H16: 46466 | K16: 未开始 | L16: =IF(J16<>"",J16-H16,MAX(0,DATE(2026,9,16)-H16)) -> 0 | M16: =IF(K16="已完成","绿",IF(H16<DATE(2026,9,16),"红",IF(H16<=DATE(2026,9,23),"黄","绿"))) -> 绿 | N16: 接口分级评审记录、范围基线、接口规格、联调与对账报告
A17: MS013 | C17: 系统测试完成 | D17: 阻断及严重缺陷关闭，内部与外部集成回归通过 | E17: 高级测试人员、中级测试人员 | F17: 技术经理、高级开发人员、中级开发人员、产品经理 | G17: 46447 | H17: 46492 | K17: 未开始 | L17: =IF(J17<>"",J17-H17,MAX(0,DATE(2026,9,16)-H17)) -> 0 | M17: =IF(K17="已完成","绿",IF(H17<DATE(2026,9,16),"红",IF(H17<=DATE(2026,9,23),"黄","绿"))) -> 绿 | N17: 系统测试报告
A18: MS014 | C18: UAT验收完成 | D18: P0场景验收通过，遗留事项获得批准 | E18: 产品经理 | F18: 业务代表、高级测试人员、中级测试人员、项目经理 | G18: 46493 | H18: 46517 | K18: 未开始 | L18: =IF(J18<>"",J18-H18,MAX(0,DATE(2026,9,16)-H18)) -> 0 | M18: =IF(K18="已完成","绿",IF(H18<DATE(2026,9,16),"红",IF(H18<=DATE(2026,9,23),"黄","绿"))) -> 绿 | N18: UAT报告与业务确认单
A19: MS015 | C19: 上线准入评审通过 | D19: 数据、接口、权限、回退、培训和运维准备就绪 | E19: 项目集经理 | F19: 项目经理、技术经理、产品经理、高级测试人员、中级测试人员、配置人员 | G19: 46518 | H19: 46531 | K19: 未开始 | L19: =IF(J19<>"",J19-H19,MAX(0,DATE(2026,9,16)-H19)) -> 0 | M19: =IF(K19="已完成","绿",IF(H19<DATE(2026,9,16),"红",IF(H19<=DATE(2026,9,23),"黄","绿"))) -> 绿 | N19: 上线检查表和批准记录
A20: MS016 | B20: 系统上线与试运行 | C20: 生产上线并进入试运行 | D20: 生产验证通过、监控启用、支持机制生效 | E20: 技术经理 | F20: 项目集经理、项目经理、配置人员、高级测试人员、中级测试人员 | G20: 46538 | H20: 46538 | K20: 未开始 | L20: =IF(J20<>"",J20-H20,MAX(0,DATE(2026,9,16)-H20)) -> 0 | M20: =IF(K20="已完成","绿",IF(H20<DATE(2026,9,16),"红",IF(H20<=DATE(2026,9,23),"黄","绿"))) -> 绿 | N20: 上线确认单和试运行计划

Sheet 项目总控台账
A1: 能源行业合同全生命周期管理系统｜项目总控台账
A2: 蓝色字段为计划分解项；黄色字段为执行维护项；进度与延期由公式自动计算。
A3: 任务ID | B3: 一级功能 | C3: 二级功能 | D3: 三级功能 | E3: 四级功能 | F3: 批次 | G3: 总体状态 | H3: 主责人 | I3: 计划开始 | J3: 计划完成 | K3: 计划上线 | L3: 业务负责人 | M3: 业务状态 | N3: 业务开始 | O3: 业务结束 | P3: 后端负责人 | Q3: 后端状态 | R3: 后端开始 | S3: 后端结束 | T3: 前端负责人 | U3: 前端状态 | V3: 前端开始 | W3: 前端结束 | X3: 测试负责人 | Y3: 测试状态 | Z3: 测试开始 | AA3: 测试结束 | AB3: 综合进度 | AC3: 延期状态 | AD3: 当前问题/阻塞 | AE3: 备注 | AF3: 迭代周 | AG3: 预测完成日期 | AH3: 基线偏差天数
A4: T001 | B4: 可研与原业务梳理 | C4: 可研工作启动 | D4: 可研启动 | E4: 明确可研目标、范围与边界 | F4: MS001 | G4: =IF(OR(M4="暂停",M4="挂起",Q4="暂停",Q4="挂起",U4="暂停",U4="挂起",Y4="暂停",Y4="挂起"),"暂停",IF(COUNTA(L4,P4,T4,X4)=0,"未分配",IF(IF(L4<>"",M4="已完成",0)+IF(P4<>"",Q4="已完成",0)+IF(T4<>"",U4="已完成",0)+IF(X4<>"",Y4="已完成",0)=COUNTA(L4,P4,T4,X4),"已完成",IF(IF(L4<>"",M4="进行中",0)+IF(P4<>"",Q4="进行中",0)+IF(T4<>"",U4="进行中",0)+IF(X4<>"",Y4="进行中",0)>0,"进行中",IF(IF(L4<>"",M4="待确认",0)+IF(P4<>"",Q4="待确认",0)+IF(T4<>"",U4="待确认",0)+IF(X4<>"",Y4="待确认",0)>0,"待确认","未开始"))))) -> 已完成 | H4: =IF(L4<>"",L4,IF(P4<>"",P4,IF(T4<>"",T4,X4))) -> 项目经理 | I4: =IF(COUNT(N4,R4,V4,Z4)=0,"",MIN(N4,R4,V4,Z4)) -> 46054 | J4: =IF(COUNT(O4,S4,W4,AA4)=0,"",MAX(O4,S4,W4,AA4)) -> 46056 | K4: 46063 | L4: 项目经理 | M4: 已完成 | N4: 46054 | O4: 46056 | AB4: =IFERROR((IF(L4<>"",IF(M4="已完成",1,IF(M4="进行中",0.5,0))*15%,0)+IF(P4<>"",IF(Q4="已完成",1,IF(Q4="进行中",0.5,0))*35%,0)+IF(T4<>"",IF(U4="已完成",1,IF(U4="进行中",0.5,0))*30%,0)+IF(X4<>"",IF(Y4="已完成",1,IF(Y4="进行中",0.5,0))*20%,0))/(IF(L4<>"",15%,0)+IF(P4<>"",35%,0)+IF(T4<>"",30%,0)+IF(X4<>"",20%,0)),0) -> 1 | AC4: =IF($A4="","",IF(G4="已完成","正常",IF(G4="暂停","暂停",IF(J4="","日期缺失",IF(J4<_数据接口!$B$7,"已延期",IF(J4<=_数据接口!$B$7+7,"临近到期","正常")))))) -> 正常 | AH4: =IF(OR($A4="",J4="",AG4=""),"",AG4-J4)
A5: T002 | E5: 建立相关方清单与访谈计划 | F5: MS001 | G5: =IF(OR(M5="暂停",M5="挂起",Q5="暂停",Q5="挂起",U5="暂停",U5="挂起",Y5="暂停",Y5="挂起"),"暂停",IF(COUNTA(L5,P5,T5,X5)=0,"未分配",IF(IF(L5<>"",M5="已完成",0)+IF(P5<>"",Q5="已完成",0)+IF(T5<>"",U5="已完成",0)+IF(X5<>"",Y5="已完成",0)=COUNTA(L5,P5,T5,X5),"已完成",IF(IF(L5<>"",M5="进行中",0)+IF(P5<>"",Q5="进行中",0)+IF(T5<>"",U5="进行中",0)+IF(X5<>"",Y5="进行中",0)>0,"进行中",IF(IF(L5<>"",M5="待确认",0)+IF(P5<>"",Q5="待确认",0)+IF(T5<>"",U5="待确认",0)+IF(X5<>"",Y5="待确认",0)>0,"待确认","未开始"))))) -> 已完成 | H5: =IF(L5<>"",L5,IF(P5<>"",P5,IF(T5<>"",T5,X5))) -> 产品经理 | I5: =IF(COUNT(N5,R5,V5,Z5)=0,"",MIN(N5,R5,V5,Z5)) -> 46057 | J5: =IF(COUNT(O5,S5,W5,AA5)=0,"",MAX(O5,S5,W5,AA5)) -> 46059 | K5: 46063 | L5: 产品经理 | M5: 已完成 | N5: 46057 | O5: 46059 | AB5: =IFERROR((IF(L5<>"",IF(M5="已完成",1,IF(M5="进行中",0.5,0))*15%,0)+IF(P5<>"",IF(Q5="已完成",1,IF(Q5="进行中",0.5,0))*35%,0)+IF(T5<>"",IF(U5="已完成",1,IF(U5="进行中",0.5,0))*30%,0)+IF(X5<>"",IF(Y5="已完成",1,IF(Y5="进行中",0.5,0))*20%,0))/(IF(L5<>"",15%,0)+IF(P5<>"",35%,0)+IF(T5<>"",30%,0)+IF(X5<>"",20%,0)),0) -> 1 | AC5: =IF($A5="","",IF(G5="已完成","正常",IF(G5="暂停","暂停",IF(J5="","日期缺失",IF(J5<_数据接口!$B$7,"已延期",IF(J5<=_数据接口!$B$7+7,"临近到期","正常")))))) -> 正常 | AH5: =IF(OR($A5="",J5="",AG5=""),"",AG5-J5)
A6: T003 | E6: 评审并发布可研工作方案 | F6: MS001 | G6: =IF(OR(M6="暂停",M6="挂起",Q6="暂停",Q6="挂起",U6="暂停",U6="挂起",Y6="暂停",Y6="挂起"),"暂停",IF(COUNTA(L6,P6,T6,X6)=0,"未分配",IF(IF(L6<>"",M6="已完成",0)+IF(P6<>"",Q6="已完成",0)+IF(T6<>"",U6="已完成",0)+IF(X6<>"",Y6="已完成",0)=COUNTA(L6,P6,T6,X6),"已完成",IF(IF(L6<>"",M6="进行中",0)+IF(P6<>"",Q6="进行中",0)+IF(T6<>"",U6="进行中",0)+IF(X6<>"",Y6="进行中",0)>0,"进行中",IF(IF(L6<>"",M6="待确认",0)+IF(P6<>"",Q6="待确认",0)+IF(T6<>"",U6="待确认",0)+IF(X6<>"",Y6="待确认",0)>0,"待确认","未开始"))))) -> 已完成 | H6: =IF(L6<>"",L6,IF(P6<>"",P6,IF(T6<>"",T6,X6))) -> 项目集经理 | I6: =IF(COUNT(N6,R6,V6,Z6)=0,"",MIN(N6,R6,V6,Z6)) -> 46060 | J6: =IF(COUNT(O6,S6,W6,AA6)=0,"",MAX(O6,S6,W6,AA6)) -> 46063 | K6: 46063 | L6: 项目集经理 | M6: 已完成 | N6: 46060 | O6: 46063 | AB6: =IFERROR((IF(L6<>"",IF(M6="已完成",1,IF(M6="进行中",0.5,0))*15%,0)+IF(P6<>"",IF(Q6="已完成",1,IF(Q6="进行中",0.5,0))*35%,0)+IF(T6<>"",IF(U6="已完成",1,IF(U6="进行中",0.5,0))*30%,0)+IF(X6<>"",IF(Y6="已完成",1,IF(Y6="进行中",0.5,0))*20%,0))/(IF(L6<>"",15%,0)+IF(P6<>"",35%,0)+IF(T6<>"",30%,0)+IF(X6<>"",20%,0)),0) -> 1 | AC6: =IF($A6="","",IF(G6="已完成","正常",IF(G6="暂停","暂停",IF(J6="","日期缺失",IF(J6<_数据接口!$B$7,"已延期",IF(J6<=_数据接口!$B$7+7,"临近到期","正常")))))) -> 正常 | AH6: =IF(OR($A6="",J6="",AG6=""),"",AG6-J6)
A7: T004 | C7: 可行性研究完成 | D7: 可行性研究 | E7: 完成业务可行性与需求价值分析 | F7: MS002 | G7: =IF(OR(M7="暂停",M7="挂起",Q7="暂停",Q7="挂起",U7="暂停",U7="挂起",Y7="暂停",Y7="挂起"),"暂停",IF(COUNTA(L7,P7,T7,X7)=0,"未分配",IF(IF(L7<>"",M7="已完成",0)+IF(P7<>"",Q7="已完成",0)+IF(T7<>"",U7="已完成",0)+IF(X7<>"",Y7="已完成",0)=COUNTA(L7,P7,T7,X7),"已完成",IF(IF(L7<>"",M7="进行中",0)+IF(P7<>"",Q7="进行中",0)+IF(T7<>"",U7="进行中",0)+IF(X7<>"",Y7="进行中",0)>0,"进行中",IF(IF(L7<>"",M7="待确认",0)+IF(P7<>"",Q7="待确认",0)+IF(T7<>"",U7="待确认",0)+IF(X7<>"",Y7="待确认",0)>0,"待确认","未开始"))))) -> 已完成 | H7: =IF(L7<>"",L7,IF(P7<>"",P7,IF(T7<>"",T7,X7))) -> 产品经理 | I7: =IF(COUNT(N7,R7,V7,Z7)=0,"",MIN(N7,R7,V7,Z7)) -> 46054 | J7: =IF(COUNT(O7,S7,W7,AA7)=0,"",MAX(O7,S7,W7,AA7)) -> 46099 | K7: 46283 | L7: 产品经理 | M7: 已完成 | N7: 46054 | O7: 46099 | AB7: =IFERROR((IF(L7<>"",IF(M7="已完成",1,IF(M7="进行中",0.5,0))*15%,0)+IF(P7<>"",IF(Q7="已完成",1,IF(Q7="进行中",0.5,0))*35%,0)+IF(T7<>"",IF(U7="已完成",1,IF(U7="进行中",0.5,0))*30%,0)+IF(X7<>"",IF(Y7="已完成",1,IF(Y7="进行中",0.5,0))*20%,0))/(IF(L7<>"",15%,0)+IF(P7<>"",35%,0)+IF(T7<>"",30%,0)+IF(X7<>"",20%,0)),0) -> 1 | AC7: =IF($A7="","",IF(G7="已完成","正常",IF(G7="暂停","暂停",IF(J7="","日期缺失",IF(J7<_数据接口!$B$7,"已延期",IF(J7<=_数据接口!$B$7+7,"临近到期","正常")))))) -> 正常 | AH7: =IF(OR($A7="",J7="",AG7=""),"",AG7-J7)
A8: T005 | E8: 完成技术路线与系统边界论证 | F8: MS002 | G8: =IF(OR(M8="暂停",M8="挂起",Q8="暂停",Q8="挂起",U8="暂停",U8="挂起",Y8="暂停",Y8="挂起"),"暂停",IF(COUNTA(L8,P8,T8,X8)=0,"未分配",IF(IF(L8<>"",M8="已完成",0)+IF(P8<>"",Q8="已完成",0)+IF(T8<>"",U8="已完成",0)+IF(X8<>"",Y8="已完成",0)=COUNTA(L8,P8,T8,X8),"已完成",IF(IF(L8<>"",M8="进行中",0)+IF(P8<>"",Q8="进行中",0)+IF(T8<>"",U8="进行中",0)+IF(X8<>"",Y8="进行中",0)>0,"进行中",IF(IF(L8<>"",M8="待确认",0)+IF(P8<>"",Q8="待确认",0)+IF(T8<>"",U8="待确认",0)+IF(X8<>"",Y8="待确认",0)>0,"待确认","未开始"))))) -> 已完成 | H8: =IF(L8<>"",L8,IF(P8<>"",P8,IF(T8<>"",T8,X8))) -> 技术经理 | I8: =IF(COUNT(N8,R8,V8,Z8)=0,"",MIN(N8,R8,V8,Z8)) -> 46100 | J8: =IF(COUNT(O8,S8,W8,AA8)=0,"",MAX(O8,S8,W8,AA8)) -> 46145 | K8: 46283 | M8: 已完成 | P8: 技术经理 | Q8: 已完成 | R8: 46100 | S8: 46145 | AB8: =IFERROR((IF(L8<>"",IF(M8="已完成",1,IF(M8="进行中",0.5,0))*15%,0)+IF(P8<>"",IF(Q8="已完成",1,IF(Q8="进行中",0.5,0))*35%,0)+IF(T8<>"",IF(U8="已完成",1,IF(U8="进行中",0.5,0))*30%,0)+IF(X8<>"",IF(Y8="已完成",1,IF(Y8="进行中",0.5,0))*20%,0))/(IF(L8<>"",15%,0)+IF(P8<>"",35%,0)+IF(T8<>"",30%,0)+IF(X8<>"",20%,0)),0) -> 1 | AC8: =IF($A8="","",IF(G8="已完成","正常",IF(G8="暂停","暂停",IF(J8="","日期缺失",IF(J8<_数据接口!$B$7,"已延期",IF(J8<=_数据接口!$B$7+7,"临近到期","正常")))))) -> 正常 | AH8: =IF(OR($A8="",J8="",AG8=""),"",AG8-J8)
A9: T006 | E9: 测算投资、成本与预期收益 | F9: MS002 | G9: =IF(OR(M9="暂停",M9="挂起",Q9="暂停",Q9="挂起",U9="暂停",U9="挂起",Y9="暂停",Y9="挂起"),"暂停",IF(COUNTA(L9,P9,T9,X9)=0,"未分配",IF(IF(L9<>"",M9="已完成",0)+IF(P9<>"",Q9="已完成",0)+IF(T9<>"",U9="已完成",0)+IF(X9<>"",Y9="已完成",0)=COUNTA(L9,P9,T9,X9),"已完成",IF(IF(L9<>"",M9="进行中",0)+IF(P9<>"",Q9="进行中",0)+IF(T9<>"",U9="进行中",0)+IF(X9<>"",Y9="进行中",0)>0,"进行中",IF(IF(L9<>"",M9="待确认",0)+IF(P9<>"",Q9="待确认",0)+IF(T9<>"",U9="待确认",0)+IF(X9<>"",Y9="待确认",0)>0,"待确认","未开始"))))) -> 已完成 | H9: =IF(L9<>"",L9,IF(P9<>"",P9,IF(T9<>"",T9,X9))) -> 项目经理 | I9: =IF(COUNT(N9,R9,V9,Z9)=0,"",MIN(N9,R9,V9,Z9)) -> 46146 | J9: =IF(COUNT(O9,S9,W9,AA9)=0,"",MAX(O9,S9,W9,AA9)) -> 46191 | K9: 46283 | L9: 项目经理 | M9: 已完成 | N9: 46146 | O9: 46191 | AB9: =IFERROR((IF(L9<>"",IF(M9="已完成",1,IF(M9="进行中",0.5,0))*15%,0)+IF(P9<>"",IF(Q9="已完成",1,IF(Q9="进行中",0.5,0))*35%,0)+IF(T9<>"",IF(U9="已完成",1,IF(U9="进行中",0.5,0))*30%,0)+IF(X9<>"",IF(Y9="已完成",1,IF(Y9="进行中",0.5,0))*20%,0))/(IF(L9<>"",15%,0)+IF(P9<>"",35%,0)+IF(T9<>"",30%,0)+IF(X9<>"",20%,0)),0) -> 1 | AC9: =IF($A9="","",IF(G9="已完成","正常",IF(G9="暂停","暂停",IF(J9="","日期缺失",IF(J9<_数据接口!$B$7,"已延期",IF(J9<=_数据接口!$B$7+7,"临近到期","正常")))))) -> 正常 | AH9: =IF(OR($A9="",J9="",AG9=""),"",AG9-J9)
A10: T007 | E10: 形成实施路径、资源与风险建议 | F10: MS002 | G10: =IF(OR(M10="暂停",M10="挂起",Q10="暂停",Q10="挂起",U10="暂停",U10="挂起",Y10="暂停",Y10="挂起"),"暂停",IF(COUNTA(L10,P10,T10,X10)=0,"未分配",IF(IF(L10<>"",M10="已完成",0)+IF(P10<>"",Q10="已完成",0)+IF(T10<>"",U10="已完成",0)+IF(X10<>"",Y10="已完成",0)=COUNTA(L10,P10,T10,X10),"已完成",IF(IF(L10<>"",M10="进行中",0)+IF(P10<>"",Q10="进行中",0)+IF(T10<>"",U10="进行中",0)+IF(X10<>"",Y10="进行中",0)>0,"进行中",IF(IF(L10<>"",M10="待确认",0)+IF(P10<>"",Q10="待确认",0)+IF(T10<>"",U10="待确认",0)+IF(X10<>"",Y10="待确认",0)>0,"待确认","未开始"))))) -> 已完成 | H10: =IF(L10<>"",L10,IF(P10<>"",P10,IF(T10<>"",T10,X10))) -> 项目经理 | I10: =IF(COUNT(N10,R10,V10,Z10)=0,"",MIN(N10,R10,V10,Z10)) -> 46192 | J10: =IF(COUNT(O10,S10,W10,AA10)=0,"",MAX(O10,S10,W10,AA10)) -> 46237 | K10: 46283 | L10: 项目经理 | M10: 已完成 | N10: 46192 | O10: 46237 | AB10: =IFERROR((IF(L10<>"",IF(M10="已完成",1,IF(M10="进行中",0.5,0))*15%,0)+IF(P10<>"",IF(Q10="已完成",1,IF(Q10="进行中",0.5,0))*35%,0)+IF(T10<>"",IF(U10="已完成",1,IF(U10="进行中",0.5,0))*30%,0)+IF(X10<>"",IF(Y10="已完成",1,IF(Y10="进行中",0.5,0))*20%,0))/(IF(L10<>"",15%,0)+IF(P10<>"",35%,0)+IF(T10<>"",30%,0)+IF(X10<>"",20%,0)),0) -> 1 | AC10: =IF($A10="","",IF(G10="已完成","正常",IF(G10="暂停","暂停",IF(J10="","日期缺失",IF(J10<_数据接口!$B$7,"已延期",IF(J10<=_数据接口!$B$7+7,"临近到期","正常")))))) -> 正常 | AH10: =IF(OR($A10="",J10="",AG10=""),"",AG10-J10)
A11: T008 | E11: 汇编可研报告并组织评审 | F11: MS002 | G11: =IF(OR(M11="暂停",M11="挂起",Q11="暂停",Q11="挂起",U11="暂停",U11="挂起",Y11="暂停",Y11="挂起"),"暂停",IF(COUNTA(L11,P11,T11,X11)=0,"未分配",IF(IF(L11<>"",M11="已完成",0)+IF(P11<>"",Q11="已完成",0)+IF(T11<>"",U11="已完成",0)+IF(X11<>"",Y11="已完成",0)=COUNTA(L11,P11,T11,X11),"已完成",IF(IF(L11<>"",M11="进行中",0)+IF(P11<>"",Q11="进行中",0)+IF(T11<>"",U11="进行中",0)+IF(X11<>"",Y11="进行中",0)>0,"进行中",IF(IF(L11<>"",M11="待确认",0)+IF(P11<>"",Q11="待确认",0)+IF(T11<>"",U11="待确认",0)+IF(X11<>"",Y11="待确认",0)>0,"待确认","未开始"))))) -> 已完成 | H11: =IF(L11<>"",L11,IF(P11<>"",P11,IF(T11<>"",T11,X11))) -> 项目经理 | I11: =IF(COUNT(N11,R11,V11,Z11)=0,"",MIN(N11,R11,V11,Z11)) -> 46238 | J11: =IF(COUNT(O11,S11,W11,AA11)=0,"",MAX(O11,S11,W11,AA11)) -> 46283 | K11: 46283 | L11: 项目经理 | M11: 已完成 | N11: 46238 | O11: 46283 | AB11: =IFERROR((IF(L11<>"",IF(M11="已完成",1,IF(M11="进行中",0.5,0))*15%,0)+IF(P11<>"",IF(Q11="已完成",1,IF(Q11="进行中",0.5,0))*35%,0)+IF(T11<>"",IF(U11="已完成",1,IF(U11="进行中",0.5,0))*30%,0)+IF(X11<>"",IF(Y11="已完成",1,IF(Y11="进行中",0.5,0))*20%,0))/(IF(L11<>"",15%,0)+IF(P11<>"",35%,0)+IF(T11<>"",30%,0)+IF(X11<>"",20%,0)),0) -> 1 | AC11: =IF($A11="","",IF(G11="已完成","正常",IF(G11="暂停","暂停",IF(J11="","日期缺失",IF(J11<_数据接口!$B$7,"已延期",IF(J11<=_数据接口!$B$7+7,"临近到期","正常")))))) -> 正常 | AF11: 2026-W40 | AH11: =IF(OR($A11="",J11="",AG11=""),"",AG11-J11)
A12: T009 | C12: 原业务梳理完成 | D12: 现状调研 | E12: 梳理合同业务组织与职责 | F12: MS003 | G12: =IF(OR(M12="暂停",M12="挂起",Q12="暂停",Q12="挂起",U12="暂停",U12="挂起",Y12="暂停",Y12="挂起"),"暂停",IF(COUNTA(L12,P12,T12,X12)=0,"未分配",IF(IF(L12<>"",M12="已完成",0)+IF(P12<>"",Q12="已完成",0)+IF(T12<>"",U12="已完成",0)+IF(X12<>"",Y12="已完成",0)=COUNTA(L12,P12,T12,X12),"已完成",IF(IF(L12<>"",M12="进行中",0)+IF(P12<>"",Q12="进行中",0)+IF(T12<>"",U12="进行中",0)+IF(X12<>"",Y12="进行中",0)>0,"进行中",IF(IF(L12<>"",M12="待确认",0)+IF(P12<>"",Q12="待确认",0)+IF(T12<>"",U12="待确认",0)+IF(X12<>"",Y12="待确认",0)>0,"待确认","未开始"))))) -> 已完成 | H12: =IF(L12<>"",L12,IF(P12<>"",P12,IF(T12<>"",T12,X12))) -> 产品经理 | I12: =IF(COUNT(N12,R12,V12,Z12)=0,"",MIN(N12,R12,V12,Z12)) -> 46064 | J12: =IF(COUNT(O12,S12,W12,AA12)=0,"",MAX(O12,S12,W12,AA12)) -> 46091 | K12: 46203 | L12: 产品经理 | M12: 已完成 | N12: 46064 | O12: 46091 | AB12: =IFERROR((IF(L12<>"",IF(M12="已完成",1,IF(M12="进行中",0.5,0))*15%,0)+IF(P12<>"",IF(Q12="已完成",1,IF(Q12="进行中",0.5,0))*35%,0)+IF(T12<>"",IF(U12="已完成",1,IF(U12="进行中",0.5,0))*30%,0)+IF(X12<>"",IF(Y12="已完成",1,IF(Y12="进行中",0.5,0))*20%,0))/(IF(L12<>"",15%,0)+IF(P12<>"",35%,0)+IF(T12<>"",30%,0)+IF(X12<>"",20%,0)),0) -> 1 | AC12: =IF($A12="","",IF(G12="已完成","正常",IF(G12="暂停","暂停",IF(J12="","日期缺失",IF(J12<_数据接口!$B$7,"已延期",IF(J12<=_数据接口!$B$7+7,"临近到期","正常")))))) -> 正常 | AH12: =IF(OR($A12="",J12="",AG12=""),"",AG12-J12)
A13: T010 | E13: 盘点合同全生命周期业务流程 | F13: MS003 | G13: =IF(OR(M13="暂停",M13="挂起",Q13="暂停",Q13="挂起",U13="暂停",U13="挂起",Y13="暂停",Y13="挂起"),"暂停",IF(COUNTA(L13,P13,T13,X13)=0,"未分配",IF(IF(L13<>"",M13="已完成",0)+IF(P13<>"",Q13="已完成",0)+IF(T13<>"",U13="已完成",0)+IF(X13<>"",Y13="已完成",0)=COUNTA(L13,P13,T13,X13),"已完成",IF(IF(L13<>"",M13="进行中",0)+IF(P13<>"",Q13="进行中",0)+IF(T13<>"",U13="进行中",0)+IF(X13<>"",Y13="进行中",0)>0,"进行中",IF(IF(L13<>"",M13="待确认",0)+IF(P13<>"",Q13="待确认",0)+IF(T13<>"",U13="待确认",0)+IF(X13<>"",Y13="待确认",0)>0,"待确认","未开始"))))) -> 已完成 | H13: =IF(L13<>"",L13,IF(P13<>"",P13,IF(T13<>"",T13,X13))) -> 产品经理 | I13: =IF(COUNT(N13,R13,V13,Z13)=0,"",MIN(N13,R13,V13,Z13)) -> 46092 | J13: =IF(COUNT(O13,S13,W13,AA13)=0,"",MAX(O13,S13,W13,AA13)) -> 46119 | K13: 46203 | L13: 产品经理 | M13: 已完成 | N13: 46092 | O13: 46119 | AB13: =IFERROR((IF(L13<>"",IF(M13="已完成",1,IF(M13="进行中",0.5,0))*15%,0)+IF(P13<>"",IF(Q13="已完成",1,IF(Q13="进行中",0.5,0))*35%,0)+IF(T13<>"",IF(U13="已完成",1,IF(U13="进行中",0.5,0))*30%,0)+IF(X13<>"",IF(Y13="已完成",1,IF(Y13="进行中",0.5,0))*20%,0))/(IF(L13<>"",15%,0)+IF(P13<>"",35%,0)+IF(T13<>"",30%,0)+IF(X13<>"",20%,0)),0) -> 1 | AC13: =IF($A13="","",IF(G13="已完成","正常",IF(G13="暂停","暂停",IF(J13="","日期缺失",IF(J13<_数据接口!$B$7,"已延期",IF(J13<=_数据接口!$B$7+7,"临近到期","正常")))))) -> 正常 | AH13: =IF(OR($A13="",J13="",AG13=""),"",AG13-J13)
A14: T011 | E14: 盘点既有系统、接口与数据 | F14: MS003 | G14: =IF(OR(M14="暂停",M14="挂起",Q14="暂停",Q14="挂起",U14="暂停",U14="挂起",Y14="暂停",Y14="挂起"),"暂停",IF(COUNTA(L14,P14,T14,X14)=0,"未分配",IF(IF(L14<>"",M14="已完成",0)+IF(P14<>"",Q14="已完成",0)+IF(T14<>"",U14="已完成",0)+IF(X14<>"",Y14="已完成",0)=COUNTA(L14,P14,T14,X14),"已完成",IF(IF(L14<>"",M14="进行中",0)+IF(P14<>"",Q14="进行中",0)+IF(T14<>"",U14="进行中",0)+IF(X14<>"",Y14="进行中",0)>0,"进行中",IF(IF(L14<>"",M14="待确认",0)+IF(P14<>"",Q14="待确认",0)+IF(T14<>"",U14="待确认",0)+IF(X14<>"",Y14="待确认",0)>0,"待确认","未开始"))))) -> 进行中 | H14: =IF(L14<>"",L14,IF(P14<>"",P14,IF(T14<>"",T14,X14))) -> 技术经理 | I14: =IF(COUNT(N14,R14,V14,Z14)=0,"",MIN(N14,R14,V14,Z14)) -> 46120 | J14: =IF(COUNT(O14,S14,W14,AA14)=0,"",MAX(O14,S14,W14,AA14)) -> 46147 | K14: 46203 | M14: 进行中 | P14: 技术经理 | Q14: 进行中 | R14: 46120 | S14: 46147 | AB14: =IFERROR((IF(L14<>"",IF(M14="已完成",1,IF(M14="进行中",0.5,0))*15%,0)+IF(P14<>"",IF(Q14="已完成",1,IF(Q14="进行中",0.5,0))*35%,0)+IF(T14<>"",IF(U14="已完成",1,IF(U14="进行中",0.5,0))*30%,0)+IF(X14<>"",IF(Y14="已完成",1,IF(Y14="进行中",0.5,0))*20%,0))/(IF(L14<>"",15%,0)+IF(P14<>"",35%,0)+IF(T14<>"",30%,0)+IF(X14<>"",20%,0)),0) -> 0.5 | AC14: =IF($A14="","",IF(G14="已完成","正常",IF(G14="暂停","暂停",IF(J14="","日期缺失",IF(J14<_数据接口!$B$7,"已延期",IF(J14<=_数据接口!$B$7+7,"临近到期","正常")))))) -> 已延期 | AF14: 2026-W40 | AH14: =IF(OR($A14="",J14="",AG14=""),"",AG14-J14)
A15: T012 | D15: 问题分析 | E15: 访谈业务部门并形成痛点清单 | F15: MS003 | G15: =IF(OR(M15="暂停",M15="挂起",Q15="暂停",Q15="挂起",U15="暂停",U15="挂起",Y15="暂停",Y15="挂起"),"暂停",IF(COUNTA(L15,P15,T15,X15)=0,"未分配",IF(IF(L15<>"",M15="已完成",0)+IF(P15<>"",Q15="已完成",0)+IF(T15<>"",U15="已完成",0)+IF(X15<>"",Y15="已完成",0)=COUNTA(L15,P15,T15,X15),"已完成",IF(IF(L15<>"",M15="进行中",0)+IF(P15<>"",Q15="进行中",0)+IF(T15<>"",U15="进行中",0)+IF(X15<>"",Y15="进行中",0)>0,"进行中",IF(IF(L15<>"",M15="待确认",0)+IF(P15<>"",Q15="待确认",0)+IF(T15<>"",U15="待确认",0)+IF(X15<>"",Y15="待确认",0)>0,"待确认","未开始"))))) -> 已完成 | H15: =IF(L15<>"",L15,IF(P15<>"",P15,IF(T15<>"",T15,X15))) -> 产品经理 | I15: =IF(COUNT(N15,R15,V15,Z15)=0,"",MIN(N15,R15,V15,Z15)) -> 46148 | J15: =IF(COUNT(O15,S15,W15,AA15)=0,"",MAX(O15,S15,W15,AA15)) -> 46175 | K15: 46203 | L15: 产品经理 | M15: 已完成 | N15: 46148 | O15: 46175 | AB15: =IFERROR((IF(L15<>"",IF(M15="已完成",1,IF(M15="进行中",0.5,0))*15%,0)+IF(P15<>"",IF(Q15="已完成",1,IF(Q15="进行中",0.5,0))*35%,0)+IF(T15<>"",IF(U15="已完成",1,IF(U15="进行中",0.5,0))*30%,0)+IF(X15<>"",IF(Y15="已完成",1,IF(Y15="进行中",0.5,0))*20%,0))/(IF(L15<>"",15%,0)+IF(P15<>"",35%,0)+IF(T15<>"",30%,0)+IF(X15<>"",20%,0)),0) -> 1 | AC15: =IF($A15="","",IF(G15="已完成","正常",IF(G15="暂停","暂停",IF(J15="","日期缺失",IF(J15<_数据接口!$B$7,"已延期",IF(J15<=_数据接口!$B$7+7,"临近到期","正常")))))) -> 正常 | AH15: =IF(OR($A15="",J15="",AG15=""),"",AG15-J15)
A16: T013 | D16: 现状基线 | E16: 确认现状流程、问题与改进机会基线 | F16: MS003 | G16: =IF(OR(M16="暂停",M16="挂起",Q16="暂停",Q16="挂起",U16="暂停",U16="挂起",Y16="暂停",Y16="挂起"),"暂停",IF(COUNTA(L16,P16,T16,X16)=0,"未分配",IF(IF(L16<>"",M16="已完成",0)+IF(P16<>"",Q16="已完成",0)+IF(T16<>"",U16="已完成",0)+IF(X16<>"",Y16="已完成",0)=COUNTA(L16,P16,T16,X16),"已完成",IF(IF(L16<>"",M16="进行中",0)+IF(P16<>"",Q16="进行中",0)+IF(T16<>"",U16="进行中",0)+IF(X16<>"",Y16="进行中",0)>0,"进行中",IF(IF(L16<>"",M16="待确认",0)+IF(P16<>"",Q16="待确认",0)+IF(T16<>"",U16="待确认",0)+IF(X16<>"",Y16="待确认",0)>0,"待确认","未开始"))))) -> 已完成 | H16: =IF(L16<>"",L16,IF(P16<>"",P16,IF(T16<>"",T16,X16))) -> 项目经理 | I16: =IF(COUNT(N16,R16,V16,Z16)=0,"",MIN(N16,R16,V16,Z16)) -> 46176 | J16: =IF(COUNT(O16,S16,W16,AA16)=0,"",MAX(O16,S16,W16,AA16)) -> 46203 | K16: 46203 | L16: 项目经理 | M16: 已完成 | N16: 46176 | O16: 46203 | AB16: =IFERROR((IF(L16<>"",IF(M16="已完成",1,IF(M16="进行中",0.5,0))*15%,0)+IF(P16<>"",IF(Q16="已完成",1,IF(Q16="进行中",0.5,0))*35%,0)+IF(T16<>"",IF(U16="已完成",1,IF(U16="进行中",0.5,0))*30%,0)+IF(X16<>"",IF(Y16="已完成",1,IF(Y16="进行中",0.5,0))*20%,0))/(IF(L16<>"",15%,0)+IF(P16<>"",35%,0)+IF(T16<>"",30%,0)+IF(X16<>"",20%,0)),0) -> 1 | AC16: =IF($A16="","",IF(G16="已完成","正常",IF(G16="暂停","暂停",IF(J16="","日期缺失",IF(J16<_数据接口!$B$7,"已延期",IF(J16<=_数据接口!$B$7+7,"临近到期","正常")))))) -> 正常 | AH16: =IF(OR($A16="",J16="",AG16=""),"",AG16-J16)
A17: T014 | B17: 项目规范梳理与技术架构搭建 | C17: 项目规范基线确认 | D17: 项目规范 | E17: 制定项目治理、会议与报告机制 | F17: MS004 | G17: =IF(OR(M17="暂停",M17="挂起",Q17="暂停",Q17="挂起",U17="暂停",U17="挂起",Y17="暂停",Y17="挂起"),"暂停",IF(COUNTA(L17,P17,T17,X17)=0,"未分配",IF(IF(L17<>"",M17="已完成",0)+IF(P17<>"",Q17="已完成",0)+IF(T17<>"",U17="已完成",0)+IF(X17<>"",Y17="已完成",0)=COUNTA(L17,P17,T17,X17),"已完成",IF(IF(L17<>"",M17="进行中",0)+IF(P17<>"",Q17="进行中",0)+IF(T17<>"",U17="进行中",0)+IF(X17<>"",Y17="进行中",0)>0,"进行中",IF(IF(L17<>"",M17="待确认",0)+IF(P17<>"",Q17="待确认",0)+IF(T17<>"",U17="待确认",0)+IF(X17<>"",Y17="待确认",0)>0,"待确认","未开始"))))) -> 待确认 | H17: =IF(L17<>"",L17,IF(P17<>"",P17,IF(T17<>"",T17,X17))) -> 项目经理 | I17: =IF(COUNT(N17,R17,V17,Z17)=0,"",MIN(N17,R17,V17,Z17)) -> 46204 | J17: =IF(COUNT(O17,S17,W17,AA17)=0,"",MAX(O17,S17,W17,AA17)) -> 46215 | K17: 46265 | L17: 项目经理 | M17: 待确认 | N17: 46204 | O17: 46215 | AB17: =IFERROR((IF(L17<>"",IF(M17="已完成",1,IF(M17="进行中",0.5,0))*15%,0)+IF(P17<>"",IF(Q17="已完成",1,IF(Q17="进行中",0.5,0))*35%,0)+IF(T17<>"",IF(U17="已完成",1,IF(U17="进行中",0.5,0))*30%,0)+IF(X17<>"",IF(Y17="已完成",1,IF(Y17="进行中",0.5,0))*20%,0))/(IF(L17<>"",15%,0)+IF(P17<>"",35%,0)+IF(T17<>"",30%,0)+IF(X17<>"",20%,0)),0) -> 0 | AC17: =IF($A17="","",IF(G17="已完成","正常",IF(G17="暂停","暂停",IF(J17="","日期缺失",IF(J17<_数据接口!$B$7,"已延期",IF(J17<=_数据接口!$B$7+7,"临近到期","正常")))))) -> 已延期 | AH17: =IF(OR($A17="",J17="",AG17=""),"",AG17-J17)
A18: T015 | D18: 需求规范 | E18: 制定需求分级、跟踪与变更规范 | F18: MS004 | G18: =IF(OR(M18="暂停",M18="挂起",Q18="暂停",Q18="挂起",U18="暂停",U18="挂起",Y18="暂停",Y18="挂起"),"暂停",IF(COUNTA(L18,P18,T18,X18)=0,"未分配",IF(IF(L18<>"",M18="已完成",0)+IF(P18<>"",Q18="已完成",0)+IF(T18<>"",U18="已完成",0)+IF(X18<>"",Y18="已完成",0)=COUNTA(L18,P18,T18,X18),"已完成",IF(IF(L18<>"",M18="进行中",0)+IF(P18<>"",Q18="进行中",0)+IF(T18<>"",U18="进行中",0)+IF(X18<>"",Y18="进行中",0)>0,"进行中",IF(IF(L18<>"",M18="待确认",0)+IF(P18<>"",Q18="待确认",0)+IF(T18<>"",U18="待确认",0)+IF(X18<>"",Y18="待确认",0)>0,"待确认","未开始"))))) -> 待确认 | H18: =IF(L18<>"",L18,IF(P18<>"",P18,IF(T18<>"",T18,X18))) -> 产品经理 | I18: =IF(COUNT(N18,R18,V18,Z18)=0,"",MIN(N18,R18,V18,Z18)) -> 46216 | J18: =IF(COUNT(O18,S18,W18,AA18)=0,"",MAX(O18,S18,W18,AA18)) -> 46227 | K18: 46265 | L18: 产品经理 | M18: 待确认 | N18: 46216 | O18: 46227 | AB18: =IFERROR((IF(L18<>"",IF(M18="已完成",1,IF(M18="进行中",0.5,0))*15%,0)+IF(P18<>"",IF(Q18="已完成",1,IF(Q18="进行中",0.5,0))*35%,0)+IF(T18<>"",IF(U18="已完成",1,IF(U18="进行中",0.5,0))*30%,0)+IF(X18<>"",IF(Y18="已完成",1,IF(Y18="进行中",0.5,0))*20%,0))/(IF(L18<>"",15%,0)+IF(P18<>"",35%,0)+IF(T18<>"",30%,0)+IF(X18<>"",20%,0)),0) -> 0 | AC18: =IF($A18="","",IF(G18="已完成","正常",IF(G18="暂停","暂停",IF(J18="","日期缺失",IF(J18<_数据接口!$B$7,"已延期",IF(J18<=_数据接口!$B$7+7,"临近到期","正常")))))) -> 已延期 | AH18: =IF(OR($A18="",J18="",AG18=""),"",AG18-J18)
A19: T016 | D19: 研发规范 | E19: 制定设计、编码与代码评审规范 | F19: MS004 | G19: =IF(OR(M19="暂停",M19="挂起",Q19="暂停",Q19="挂起",U19="暂停",U19="挂起",Y19="暂停",Y19="挂起"),"暂停",IF(COUNTA(L19,P19,T19,X19)=0,"未分配",IF(IF(L19<>"",M19="已完成",0)+IF(P19<>"",Q19="已完成",0)+IF(T19<>"",U19="已完成",0)+IF(X19<>"",Y19="已完成",0)=COUNTA(L19,P19,T19,X19),"已完成",IF(IF(L19<>"",M19="进行中",0)+IF(P19<>"",Q19="进行中",0)+IF(T19<>"",U19="进行中",0)+IF(X19<>"",Y19="进行中",0)>0,"进行中",IF(IF(L19<>"",M19="待确认",0)+IF(P19<>"",Q19="待确认",0)+IF(T19<>"",U19="待确认",0)+IF(X19<>"",Y19="待确认",0)>0,"待确认","未开始"))))) -> 待确认 | H19: =IF(L19<>"",L19,IF(P19<>"",P19,IF(T19<>"",T19,X19))) -> 技术经理 | I19: =IF(COUNT(N19,R19,V19,Z19)=0,"",MIN(N19,R19,V19,Z19)) -> 46228 | J19: =IF(COUNT(O19,S19,W19,AA19)=0,"",MAX(O19,S19,W19,AA19)) -> 46240 | K19: 46265 | P19: 技术经理 | Q19: 待确认 | R19: 46228 | S19: 46240 | AB19: =IFERROR((IF(L19<>"",IF(M19="已完成",1,IF(M19="进行中",0.5,0))*15%,0)+IF(P19<>"",IF(Q19="已完成",1,IF(Q19="进行中",0.5,0))*35%,0)+IF(T19<>"",IF(U19="已完成",1,IF(U19="进行中",0.5,0))*30%,0)+IF(X19<>"",IF(Y19="已完成",1,IF(Y19="进行中",0.5,0))*20%,0))/(IF(L19<>"",15%,0)+IF(P19<>"",35%,0)+IF(T19<>"",30%,0)+IF(X19<>"",20%,0)),0) -> 0 | AC19: =IF($A19="","",IF(G19="已完成","正常",IF(G19="暂停","暂停",IF(J19="","日期缺失",IF(J19<_数据接口!$B$7,"已延期",IF(J19<=_数据接口!$B$7+7,"临近到期","正常")))))) -> 已延期 | AH19: =IF(OR($A19="",J19="",AG19=""),"",AG19-J19)
A20: T017 | D20: 质量规范 | E20: 制定测试、缺陷与质量门禁规范 | F20: MS004 | G20: =IF(OR(M20="暂停",M20="挂起",Q20="暂停",Q20="挂起",U20="暂停",U20="挂起",Y20="暂停",Y20="挂起"),"暂停",IF(COUNTA(L20,P20,T20,X20)=0,"未分配",IF(IF(L20<>"",M20="已完成",0)+IF(P20<>"",Q20="已完成",0)+IF(T20<>"",U20="已完成",0)+IF(X20<>"",Y20="已完成",0)=COUNTA(L20,P20,T20,X20),"已完成",IF(IF(L20<>"",M20="进行中",0)+IF(P20<>"",Q20="进行中",0)+IF(T20<>"",U20="进行中",0)+IF(X20<>"",Y20="进行中",0)>0,"进行中",IF(IF(L20<>"",M20="待确认",0)+IF(P20<>"",Q20="待确认",0)+IF(T20<>"",U20="待确认",0)+IF(X20<>"",Y20="待确认",0)>0,"待确认","未开始"))))) -> 待确认 | H20: =IF(L20<>"",L20,IF(P20<>"",P20,IF(T20<>"",T20,X20))) -> 高级测试人员、中级测试人员 | I20: =IF(COUNT(N20,R20,V20,Z20)=0,"",MIN(N20,R20,V20,Z20)) -> 46241 | J20: =IF(COUNT(O20,S20,W20,AA20)=0,"",MAX(O20,S20,W20,AA20)) -> 46252 | K20: 46265 | X20: 高级测试人员、中级测试人员 | Y20: 待确认 | Z20: 46241 | AA20: 46252 | AB20: =IFERROR((IF(L20<>"",IF(M20="已完成",1,IF(M20="进行中",0.5,0))*15%,0)+IF(P20<>"",IF(Q20="已完成",1,IF(Q20="进行中",0.5,0))*35%,0)+IF(T20<>"",IF(U20="已完成",1,IF(U20="进行中",0.5,0))*30%,0)+IF(X20<>"",IF(Y20="已完成",1,IF(Y20="进行中",0.5,0))*20%,0))/(IF(L20<>"",15%,0)+IF(P20<>"",35%,0)+IF(T20<>"",30%,0)+IF(X20<>"",20%,0)),0) -> 0 | AC20: =IF($A20="","",IF(G20="已完成","正常",IF(G20="暂停","暂停",IF(J20="","日期缺失",IF(J20<_数据接口!$B$7,"已延期",IF(J20<=_数据接口!$B$7+7,"临近到期","正常")))))) -> 已延期 | AH20: =IF(OR($A20="",J20="",AG20=""),"",AG20-J20)
A21: T018 | D21: 配置规范 | E21: 制定配置、发布与文档归档规范 | F21: MS004 | G21: =IF(OR(M21="暂停",M21="挂起",Q21="暂停",Q21="挂起",U21="暂停",U21="挂起",Y21="暂停",Y21="挂起"),"暂停",IF(COUNTA(L21,P21,T21,X21)=0,"未分配",IF(IF(L21<>"",M21="已完成",0)+IF(P21<>"",Q21="已完成",0)+IF(T21<>"",U21="已完成",0)+IF(X21<>"",Y21="已完成",0)=COUNTA(L21,P21,T21,X21),"已完成",IF(IF(L21<>"",M21="进行中",0)+IF(P21<>"",Q21="进行中",0)+IF(T21<>"",U21="进行中",0)+IF(X21<>"",Y21="进行中",0)>0,"进行中",IF(IF(L21<>"",M21="待确认",0)+IF(P21<>"",Q21="待确认",0)+IF(T21<>"",U21="待确认",0)+IF(X21<>"",Y21="待确认",0)>0,"待确认","未开始"))))) -> 待确认 | H21: =IF(L21<>"",L21,IF(P21<>"",P21,IF(T21<>"",T21,X21))) -> 配置人员 | I21: =IF(COUNT(N21,R21,V21,Z21)=0,"",MIN(N21,R21,V21,Z21)) -> 46253 | J21: =IF(COUNT(O21,S21,W21,AA21)=0,"",MAX(O21,S21,W21,AA21)) -> 46265 | K21: 46265 | P21: 配置人员 | Q21: 待确认 | R21: 46253 | S21: 46265 | AB21: =IFERROR((IF(L21<>"",IF(M21="已完成",1,IF(M21="进行中",0.5,0))*15%,0)+IF(P21<>"",IF(Q21="已完成",1,IF(Q21="进行中",0.5,0))*35%,0)+IF(T21<>"",IF(U21="已完成",1,IF(U21="进行中",0.5,0))*30%,0)+IF(X21<>"",IF(Y21="已完成",1,IF(Y21="进行中",0.5,0))*20%,0))/(IF(L21<>"",15%,0)+IF(P21<>"",35%,0)+IF(T21<>"",30%,0)+IF(X21<>"",20%,0)),0) -> 0 | AC21: =IF($A21="","",IF(G21="已完成","正常",IF(G21="暂停","暂停",IF(J21="","日期缺失",IF(J21<_数据接口!$B$7,"已延期",IF(J21<=_数据接口!$B$7+7,"临近到期","正常")))))) -> 已延期 | AH21: =IF(OR($A21="",J21="",AG21=""),"",AG21-J21)
A22: T019 | C22: 技术架构基线确认 | D22: 应用架构 | E22: 完成系统分层、模块与服务边界设计 | F22: MS005 | G22: =IF(OR(M22="暂停",M22="挂起",Q22="暂停",Q22="挂起",U22="暂停",U22="挂起",Y22="暂停",Y22="挂起"),"暂停",IF(COUNTA(L22,P22,T22,X22)=0,"未分配",IF(IF(L22<>"",M22="已完成",0)+IF(P22<>"",Q22="已完成",0)+IF(T22<>"",U22="已完成",0)+IF(X22<>"",Y22="已完成",0)=COUNTA(L22,P22,T22,X22),"已完成",IF(IF(L22<>"",M22="进行中",0)+IF(P22<>"",Q22="进行中",0)+IF(T22<>"",U22="进行中",0)+IF(X22<>"",Y22="进行中",0)>0,"进行中",IF(IF(L22<>"",M22="待确认",0)+IF(P22<>"",Q22="待确认",0)+IF(T22<>"",U22="待确认",0)+IF(X22<>"",Y22="待确认",0)>0,"待确认","未开始"))))) -> 待确认 | H22: =IF(L22<>"",L22,IF(P22<>"",P22,IF(T22<>"",T22,X22))) -> 技术经理 | I22: =IF(COUNT(N22,R22,V22,Z22)=0,"",MIN(N22,R22,V22,Z22)) -> 46204 | J22: =IF(COUNT(O22,S22,W22,AA22)=0,"",MAX(O22,S22,W22,AA22)) -> 46218 | K22: 46295 | P22: 技术经理 | Q22: 待确认 | R22: 46204 | S22: 46218 | AB22: =IFERROR((IF(L22<>"",IF(M22="已完成",1,IF(M22="进行中",0.5,0))*15%,0)+IF(P22<>"",IF(Q22="已完成",1,IF(Q22="进行中",0.5,0))*35%,0)+IF(T22<>"",IF(U22="已完成",1,IF(U22="进行中",0.5,0))*30%,0)+IF(X22<>"",IF(Y22="已完成",1,IF(Y22="进行中",0.5,0))*20%,0))/(IF(L22<>"",15%,0)+IF(P22<>"",35%,0)+IF(T22<>"",30%,0)+IF(X22<>"",20%,0)),0) -> 0 | AC22: =IF($A22="","",IF(G22="已完成","正常",IF(G22="暂停","暂停",IF(J22="","日期缺失",IF(J22<_数据接口!$B$7,"已延期",IF(J22<=_数据接口!$B$7+7,"临近到期","正常")))))) -> 已延期 | AH22: =IF(OR($A22="",J22="",AG22=""),"",AG22-J22)
A23: T020 | D23: 数据架构 | E23: 完成主数据、交易数据与分析数据架构 | F23: MS005 | G23: =IF(OR(M23="暂停",M23="挂起",Q23="暂停",Q23="挂起",U23="暂停",U23="挂起",Y23="暂停",Y23="挂起"),"暂停",IF(COUNTA(L23,P23,T23,X23)=0,"未分配",IF(IF(L23<>"",M23="已完成",0)+IF(P23<>"",Q23="已完成",0)+IF(T23<>"",U23="已完成",0)+IF(X23<>"",Y23="已完成",0)=COUNTA(L23,P23,T23,X23),"已完成",IF(IF(L23<>"",M23="进行中",0)+IF(P23<>"",Q23="进行中",0)+IF(T23<>"",U23="进行中",0)+IF(X23<>"",Y23="进行中",0)>0,"进行中",IF(IF(L23<>"",M23="待确认",0)+IF(P23<>"",Q23="待确认",0)+IF(T23<>"",U23="待确认",0)+IF(X23<>"",Y23="待确认",0)>0,"待确认","未开始"))))) -> 待确认 | H23: =IF(L23<>"",L23,IF(P23<>"",P23,IF(T23<>"",T23,X23))) -> 技术经理 | I23: =IF(COUNT(N23,R23,V23,Z23)=0,"",MIN(N23,R23,V23,Z23)) -> 46219 | J23: =IF(COUNT(O23,S23,W23,AA23)=0,"",MAX(O23,S23,W23,AA23)) -> 46233 | K23: 46295 | P23: 技术经理 | Q23: 待确认 | R23: 46219 | S23: 46233 | AB23: =IFERROR((IF(L23<>"",IF(M23="已完成",1,IF(M23="进行中",0.5,0))*15%,0)+IF(P23<>"",IF(Q23="已完成",1,IF(Q23="进行中",0.5,0))*35%,0)+IF(T23<>"",IF(U23="已完成",1,IF(U23="进行中",0.5,0))*30%,0)+IF(X23<>"",IF(Y23="已完成",1,IF(Y23="进行中",0.5,0))*20%,0))/(IF(L23<>"",15%,0)+IF(P23<>"",35%,0)+IF(T23<>"",30%,0)+IF(X23<>"",20%,0)),0) -> 0 | AC23: =IF($A23="","",IF(G23="已完成","正常",IF(G23="暂停","暂停",IF(J23="","日期缺失",IF(J23<_数据接口!$B$7,"已延期",IF(J23<=_数据接口!$B$7+7,"临近到期","正常")))))) -> 已延期 | AH23: =IF(OR($A23="",J23="",AG23=""),"",AG23-J23)
A24: T021 | D24: 集成架构 | E24: 完成内部及外部接口总体架构 | F24: MS005 | G24: =IF(OR(M24="暂停",M24="挂起",Q24="暂停",Q24="挂起",U24="暂停",U24="挂起",Y24="暂停",Y24="挂起"),"暂停",IF(COUNTA(L24,P24,T24,X24)=0,"未分配",IF(IF(L24<>"",M24="已完成",0)+IF(P24<>"",Q24="已完成",0)+IF(T24<>"",U24="已完成",0)+IF(X24<>"",Y24="已完成",0)=COUNTA(L24,P24,T24,X24),"已完成",IF(IF(L24<>"",M24="进行中",0)+IF(P24<>"",Q24="进行中",0)+IF(T24<>"",U24="进行中",0)+IF(X24<>"",Y24="进行中",0)>0,"进行中",IF(IF(L24<>"",M24="待确认",0)+IF(P24<>"",Q24="待确认",0)+IF(T24<>"",U24="待确认",0)+IF(X24<>"",Y24="待确认",0)>0,"待确认","未开始"))))) -> 待确认 | H24: =IF(L24<>"",L24,IF(P24<>"",P24,IF(T24<>"",T24,X24))) -> 高级开发人员 | I24: =IF(COUNT(N24,R24,V24,Z24)=0,"",MIN(N24,R24,V24,Z24)) -> 46234 | J24: =IF(COUNT(O24,S24,W24,AA24)=0,"",MAX(O24,S24,W24,AA24)) -> 46249 | K24: 46295 | P24: 高级开发人员 | Q24: 待确认 | R24: 46234 | S24: 46249 | AB24: =IFERROR((IF(L24<>"",IF(M24="已完成",1,IF(M24="进行中",0.5,0))*15%,0)+IF(P24<>"",IF(Q24="已完成",1,IF(Q24="进行中",0.5,0))*35%,0)+IF(T24<>"",IF(U24="已完成",1,IF(U24="进行中",0.5,0))*30%,0)+IF(X24<>"",IF(Y24="已完成",1,IF(Y24="进行中",0.5,0))*20%,0))/(IF(L24<>"",15%,0)+IF(P24<>"",35%,0)+IF(T24<>"",30%,0)+IF(X24<>"",20%,0)),0) -> 0 | AC24: =IF($A24="","",IF(G24="已完成","正常",IF(G24="暂停","暂停",IF(J24="","日期缺失",IF(J24<_数据接口!$B$7,"已延期",IF(J24<=_数据接口!$B$7+7,"临近到期","正常")))))) -> 已延期 | AH24: =IF(OR($A24="",J24="",AG24=""),"",AG24-J24)
A25: T022 | D25: 安全架构 | E25: 完成身份、权限、审计与数据安全设计 | F25: MS005 | G25: =IF(OR(M25="暂停",M25="挂起",Q25="暂停",Q25="挂起",U25="暂停",U25="挂起",Y25="暂停",Y25="挂起"),"暂停",IF(COUNTA(L25,P25,T25,X25)=0,"未分配",IF(IF(L25<>"",M25="已完成",0)+IF(P25<>"",Q25="已完成",0)+IF(T25<>"",U25="已完成",0)+IF(X25<>"",Y25="已完成",0)=COUNTA(L25,P25,T25,X25),"已完成",IF(IF(L25<>"",M25="进行中",0)+IF(P25<>"",Q25="进行中",0)+IF(T25<>"",U25="进行中",0)+IF(X25<>"",Y25="进行中",0)>0,"进行中",IF(IF(L25<>"",M25="待确认",0)+IF(P25<>"",Q25="待确认",0)+IF(T25<>"",U25="待确认",0)+IF(X25<>"",Y25="待确认",0)>0,"待确认","未开始"))))) -> 待确认 | H25: =IF(L25<>"",L25,IF(P25<>"",P25,IF(T25<>"",T25,X25))) -> 技术经理 | I25: =IF(COUNT(N25,R25,V25,Z25)=0,"",MIN(N25,R25,V25,Z25)) -> 46250 | J25: =IF(COUNT(O25,S25,W25,AA25)=0,"",MAX(O25,S25,W25,AA25)) -> 46264 | K25: 46295 | P25: 技术经理 | Q25: 待确认 | R25: 46250 | S25: 46264 | AB25: =IFERROR((IF(L25<>"",IF(M25="已完成",1,IF(M25="进行中",0.5,0))*15%,0)+IF(P25<>"",IF(Q25="已完成",1,IF(Q25="进行中",0.5,0))*35%,0)+IF(T25<>"",IF(U25="已完成",1,IF(U25="进行中",0.5,0))*30%,0)+IF(X25<>"",IF(Y25="已完成",1,IF(Y25="进行中",0.5,0))*20%,0))/(IF(L25<>"",15%,0)+IF(P25<>"",35%,0)+IF(T25<>"",30%,0)+IF(X25<>"",20%,0)),0) -> 0 | AC25: =IF($A25="","",IF(G25="已完成","正常",IF(G25="暂停","暂停",IF(J25="","日期缺失",IF(J25<_数据接口!$B$7,"已延期",IF(J25<=_数据接口!$B$7+7,"临近到期","正常")))))) -> 已延期 | AH25: =IF(OR($A25="",J25="",AG25=""),"",AG25-J25)
A26: T023 | D26: 部署架构 | E26: 完成环境、网络、容灾和DevOps设计 | F26: MS005 | G26: =IF(OR(M26="暂停",M26="挂起",Q26="暂停",Q26="挂起",U26="暂停",U26="挂起",Y26="暂停",Y26="挂起"),"暂停",IF(COUNTA(L26,P26,T26,X26)=0,"未分配",IF(IF(L26<>"",M26="已完成",0)+IF(P26<>"",Q26="已完成",0)+IF(T26<>"",U26="已完成",0)+IF(X26<>"",Y26="已完成",0)=COUNTA(L26,P26,T26,X26),"已完成",IF(IF(L26<>"",M26="进行中",0)+IF(P26<>"",Q26="进行中",0)+IF(T26<>"",U26="进行中",0)+IF(X26<>"",Y26="进行中",0)>0,"进行中",IF(IF(L26<>"",M26="待确认",0)+IF(P26<>"",Q26="待确认",0)+IF(T26<>"",U26="待确认",0)+IF(X26<>"",Y26="待确认",0)>0,"待确认","未开始"))))) -> 待确认 | H26: =IF(L26<>"",L26,IF(P26<>"",P26,IF(T26<>"",T26,X26))) -> 配置人员 | I26: =IF(COUNT(N26,R26,V26,Z26)=0,"",MIN(N26,R26,V26,Z26)) -> 46265 | J26: =IF(COUNT(O26,S26,W26,AA26)=0,"",MAX(O26,S26,W26,AA26)) -> 46279 | K26: 46295 | P26: 配置人员 | Q26: 待确认 | R26: 46265 | S26: 46279 | AB26: =IFERROR((IF(L26<>"",IF(M26="已完成",1,IF(M26="进行中",0.5,0))*15%,0)+IF(P26<>"",IF(Q26="已完成",1,IF(Q26="进行中",0.5,0))*35%,0)+IF(T26<>"",IF(U26="已完成",1,IF(U26="进行中",0.5,0))*30%,0)+IF(X26<>"",IF(Y26="已完成",1,IF(Y26="进行中",0.5,0))*20%,0))/(IF(L26<>"",15%,0)+IF(P26<>"",35%,0)+IF(T26<>"",30%,0)+IF(X26<>"",20%,0)),0) -> 0 | AC26: =IF($A26="","",IF(G26="已完成","正常",IF(G26="暂停","暂停",IF(J26="","日期缺失",IF(J26<_数据接口!$B$7,"已延期",IF(J26<=_数据接口!$B$7+7,"临近到期","正常")))))) -> 已延期 | AH26: =IF(OR($A26="",J26="",AG26=""),"",AG26-J26)
A27: T024 | D27: 架构评审 | E27: 汇编总体技术架构并完成基线评审 | F27: MS005 | G27: =IF(OR(M27="暂停",M27="挂起",Q27="暂停",Q27="挂起",U27="暂停",U27="挂起",Y27="暂停",Y27="挂起"),"暂停",IF(COUNTA(L27,P27,T27,X27)=0,"未分配",IF(IF(L27<>"",M27="已完成",0)+IF(P27<>"",Q27="已完成",0)+IF(T27<>"",U27="已完成",0)+IF(X27<>"",Y27="已完成",0)=COUNTA(L27,P27,T27,X27),"已完成",IF(IF(L27<>"",M27="进行中",0)+IF(P27<>"",Q27="进行中",0)+IF(T27<>"",U27="进行中",0)+IF(X27<>"",Y27="进行中",0)>0,"进行中",IF(IF(L27<>"",M27="待确认",0)+IF(P27<>"",Q27="待确认",0)+IF(T27<>"",U27="待确认",0)+IF(X27<>"",Y27="待确认",0)>0,"待确认","未开始"))))) -> 进行中 | H27: =IF(L27<>"",L27,IF(P27<>"",P27,IF(T27<>"",T27,X27))) -> 技术经理 | I27: =IF(COUNT(N27,R27,V27,Z27)=0,"",MIN(N27,R27,V27,Z27)) -> 46280 | J27: =IF(COUNT(O27,S27,W27,AA27)=0,"",MAX(O27,S27,W27,AA27)) -> 46295 | K27: 46295 | P27: 技术经理 | Q27: 进行中 | R27: 46280 | S27: 46295 | AB27: =IFERROR((IF(L27<>"",IF(M27="已完成",1,IF(M27="进行中",0.5,0))*15%,0)+IF(P27<>"",IF(Q27="已完成",1,IF(Q27="进行中",0.5,0))*35%,0)+IF(T27<>"",IF(U27="已完成",1,IF(U27="进行中",0.5,0))*30%,0)+IF(X27<>"",IF(Y27="已完成",1,IF(Y27="进行中",0.5,0))*20%,0))/(IF(L27<>"",15%,0)+IF(P27<>"",35%,0)+IF(T27<>"",30%,0)+IF(X27<>"",20%,0)),0) -> 0.5 | AC27: =IF($A27="","",IF(G27="已完成","正常",IF(G27="暂停","暂停",IF(J27="","日期缺失",IF(J27<_数据接口!$B$7,"已延期",IF(J27<=_数据接口!$B$7+7,"临近到期","正常")))))) -> 正常 | AF27: 2026-W40 | AH27: =IF(OR($A27="",J27="",AG27=""),"",AG27-J27)
A28: T025 | C28: 外部产品POC验证完成 | D28: POC准备 | E28: 编制CA、电子文档、BI报表POC方案与评分标准 | F28: MS017 | G28: =IF(OR(M28="暂停",M28="挂起",Q28="暂停",Q28="挂起",U28="暂停",U28="挂起",Y28="暂停",Y28="挂起"),"暂停",IF(COUNTA(L28,P28,T28,X28)=0,"未分配",IF(IF(L28<>"",M28="已完成",0)+IF(P28<>"",Q28="已完成",0)+IF(T28<>"",U28="已完成",0)+IF(X28<>"",Y28="已完成",0)=COUNTA(L28,P28,T28,X28),"已完成",IF(IF(L28<>"",M28="进行中",0)+IF(P28<>"",Q28="进行中",0)+IF(T28<>"",U28="进行中",0)+IF(X28<>"",Y28="进行中",0)>0,"进行中",IF(IF(L28<>"",M28="待确认",0)+IF(P28<>"",Q28="待确认",0)+IF(T28<>"",U28="待确认",0)+IF(X28<>"",Y28="待确认",0)>0,"待确认","未开始"))))) -> 待确认 | H28: =IF(L28<>"",L28,IF(P28<>"",P28,IF(T28<>"",T28,X28))) -> 技术经理 | I28: =IF(COUNT(N28,R28,V28,Z28)=0,"",MIN(N28,R28,V28,Z28)) -> 46249 | J28: =IF(COUNT(O28,S28,W28,AA28)=0,"",MAX(O28,S28,W28,AA28)) -> 46253 | K28: 46290 | P28: 技术经理 | Q28: 待确认 | R28: 46249 | S28: 46253 | AB28: =IFERROR((IF(L28<>"",IF(M28="已完成",1,IF(M28="进行中",0.5,0))*15%,0)+IF(P28<>"",IF(Q28="已完成",1,IF(Q28="进行中",0.5,0))*35%,0)+IF(T28<>"",IF(U28="已完成",1,IF(U28="进行中",0.5,0))*30%,0)+IF(X28<>"",IF(Y28="已完成",1,IF(Y28="进行中",0.5,0))*20%,0))/(IF(L28<>"",15%,0)+IF(P28<>"",35%,0)+IF(T28<>"",30%,0)+IF(X28<>"",20%,0)),0) -> 0 | AC28: =IF($A28="","",IF(G28="已完成","正常",IF(G28="暂停","暂停",IF(J28="","日期缺失",IF(J28<_数据接口!$B$7,"已延期",IF(J28<=_数据接口!$B$7+7,"临近到期","正常")))))) -> 已延期 | AE28: 执行工具：项目启动与治理/POC评分表；评分标准完成后由联合评审组确认。 | AH28: =IF(OR($A28="",J28="",AG28=""),"",AG28-J28)
A29: T026 | D29: CA验证 | E29: 验证证书签发、身份认证和证书管理 | F29: MS017 | G29: =IF(OR(M29="暂停",M29="挂起",Q29="暂停",Q29="挂起",U29="暂停",U29="挂起",Y29="暂停",Y29="挂起"),"暂停",IF(COUNTA(L29,P29,T29,X29)=0,"未分配",IF(IF(L29<>"",M29="已完成",0)+IF(P29<>"",Q29="已完成",0)+IF(T29<>"",U29="已完成",0)+IF(X29<>"",Y29="已完成",0)=COUNTA(L29,P29,T29,X29),"已完成",IF(IF(L29<>"",M29="进行中",0)+IF(P29<>"",Q29="进行中",0)+IF(T29<>"",U29="进行中",0)+IF(X29<>"",Y29="进行中",0)>0,"进行中",IF(IF(L29<>"",M29="待确认",0)+IF(P29<>"",Q29="待确认",0)+IF(T29<>"",U29="待确认",0)+IF(X29<>"",Y29="待确认",0)>0,"待确认","未开始"))))) -> 待确认 | H29: =IF(L29<>"",L29,IF(P29<>"",P29,IF(T29<>"",T29,X29))) -> 高级开发人员 | I29: =IF(COUNT(N29,R29,V29,Z29)=0,"",MIN(N29,R29,V29,Z29)) -> 46254 | J29: =IF(COUNT(O29,S29,W29,AA29)=0,"",MAX(O29,S29,W29,AA29)) -> 46258 | K29: 46290 | P29: 高级开发人员 | Q29: 待确认 | R29: 46254 | S29: 46258 | AB29: =IFERROR((IF(L29<>"",IF(M29="已完成",1,IF(M29="进行中",0.5,0))*15%,0)+IF(P29<>"",IF(Q29="已完成",1,IF(Q29="进行中",0.5,0))*35%,0)+IF(T29<>"",IF(U29="已完成",1,IF(U29="进行中",0.5,0))*30%,0)+IF(X29<>"",IF(Y29="已完成",1,IF(Y29="进行中",0.5,0))*20%,0))/(IF(L29<>"",15%,0)+IF(P29<>"",35%,0)+IF(T29<>"",30%,0)+IF(X29<>"",20%,0)),0) -> 0 | AC29: =IF($A29="","",IF(G29="已完成","正常",IF(G29="暂停","暂停",IF(J29="","日期缺失",IF(J29<_数据接口!$B$7,"已延期",IF(J29<=_数据接口!$B$7+7,"临近到期","正常")))))) -> 已延期 | AH29: =IF(OR($A29="",J29="",AG29=""),"",AG29-J29)
A30: T027 | E30: 验证电子签名、验签、时间戳和审计追溯 | F30: MS017 | G30: =IF(OR(M30="暂停",M30="挂起",Q30="暂停",Q30="挂起",U30="暂停",U30="挂起",Y30="暂停",Y30="挂起"),"暂停",IF(COUNTA(L30,P30,T30,X30)=0,"未分配",IF(IF(L30<>"",M30="已完成",0)+IF(P30<>"",Q30="已完成",0)+IF(T30<>"",U30="已完成",0)+IF(X30<>"",Y30="已完成",0)=COUNTA(L30,P30,T30,X30),"已完成",IF(IF(L30<>"",M30="进行中",0)+IF(P30<>"",Q30="进行中",0)+IF(T30<>"",U30="进行中",0)+IF(X30<>"",Y30="进行中",0)>0,"进行中",IF(IF(L30<>"",M30="待确认",0)+IF(P30<>"",Q30="待确认",0)+IF(T30<>"",U30="待确认",0)+IF(X30<>"",Y30="待确认",0)>0,"待确认","未开始"))))) -> 待确认 | H30: =IF(L30<>"",L30,IF(P30<>"",P30,IF(T30<>"",T30,X30))) -> 高级测试人员、中级测试人员 | I30: =IF(COUNT(N30,R30,V30,Z30)=0,"",MIN(N30,R30,V30,Z30)) -> 46259 | J30: =IF(COUNT(O30,S30,W30,AA30)=0,"",MAX(O30,S30,W30,AA30)) -> 46263 | K30: 46290 | X30: 高级测试人员、中级测试人员 | Y30: 待确认 | Z30: 46259 | AA30: 46263 | AB30: =IFERROR((IF(L30<>"",IF(M30="已完成",1,IF(M30="进行中",0.5,0))*15%,0)+IF(P30<>"",IF(Q30="已完成",1,IF(Q30="进行中",0.5,0))*35%,0)+IF(T30<>"",IF(U30="已完成",1,IF(U30="进行中",0.5,0))*30%,0)+IF(X30<>"",IF(Y30="已完成",1,IF(Y30="进行中",0.5,0))*20%,0))/(IF(L30<>"",15%,0)+IF(P30<>"",35%,0)+IF(T30<>"",30%,0)+IF(X30<>"",20%,0)),0) -> 0 | AC30: =IF($A30="","",IF(G30="已完成","正常",IF(G30="暂停","暂停",IF(J30="","日期缺失",IF(J30<_数据接口!$B$7,"已延期",IF(J30<=_数据接口!$B$7+7,"临近到期","正常")))))) -> 已延期 | AH30: =IF(OR($A30="",J30="",AG30=""),"",AG30-J30)
A31: T028 | D31: 电子文档验证 | E31: 验证模板生成、在线预览和格式转换 | F31: MS017 | G31: =IF(OR(M31="暂停",M31="挂起",Q31="暂停",Q31="挂起",U31="暂停",U31="挂起",Y31="暂停",Y31="挂起"),"暂停",IF(COUNTA(L31,P31,T31,X31)=0,"未分配",IF(IF(L31<>"",M31="已完成",0)+IF(P31<>"",Q31="已完成",0)+IF(T31<>"",U31="已完成",0)+IF(X31<>"",Y31="已完成",0)=COUNTA(L31,P31,T31,X31),"已完成",IF(IF(L31<>"",M31="进行中",0)+IF(P31<>"",Q31="进行中",0)+IF(T31<>"",U31="进行中",0)+IF(X31<>"",Y31="进行中",0)>0,"进行中",IF(IF(L31<>"",M31="待确认",0)+IF(P31<>"",Q31="待确认",0)+IF(T31<>"",U31="待确认",0)+IF(X31<>"",Y31="待确认",0)>0,"待确认","未开始"))))) -> 待确认 | H31: =IF(L31<>"",L31,IF(P31<>"",P31,IF(T31<>"",T31,X31))) -> 中级开发人员 | I31: =IF(COUNT(N31,R31,V31,Z31)=0,"",MIN(N31,R31,V31,Z31)) -> 46264 | J31: =IF(COUNT(O31,S31,W31,AA31)=0,"",MAX(O31,S31,W31,AA31)) -> 46269 | K31: 46290 | T31: 中级开发人员 | U31: 待确认 | V31: 46264 | W31: 46269 | AB31: =IFERROR((IF(L31<>"",IF(M31="已完成",1,IF(M31="进行中",0.5,0))*15%,0)+IF(P31<>"",IF(Q31="已完成",1,IF(Q31="进行中",0.5,0))*35%,0)+IF(T31<>"",IF(U31="已完成",1,IF(U31="进行中",0.5,0))*30%,0)+IF(X31<>"",IF(Y31="已完成",1,IF(Y31="进行中",0.5,0))*20%,0))/(IF(L31<>"",15%,0)+IF(P31<>"",35%,0)+IF(T31<>"",30%,0)+IF(X31<>"",20%,0)),0) -> 0 | AC31: =IF($A31="","",IF(G31="已完成","正常",IF(G31="暂停","暂停",IF(J31="","日期缺失",IF(J31<_数据接口!$B$7,"已延期",IF(J31<=_数据接口!$B$7+7,"临近到期","正常")))))) -> 已延期 | AH31: =IF(OR($A31="",J31="",AG31=""),"",AG31-J31)
A32: T029 | E32: 验证水印、权限控制、归档和大文件性能 | F32: MS017 | G32: =IF(OR(M32="暂停",M32="挂起",Q32="暂停",Q32="挂起",U32="暂停",U32="挂起",Y32="暂停",Y32="挂起"),"暂停",IF(COUNTA(L32,P32,T32,X32)=0,"未分配",IF(IF(L32<>"",M32="已完成",0)+IF(P32<>"",Q32="已完成",0)+IF(T32<>"",U32="已完成",0)+IF(X32<>"",Y32="已完成",0)=COUNTA(L32,P32,T32,X32),"已完成",IF(IF(L32<>"",M32="进行中",0)+IF(P32<>"",Q32="进行中",0)+IF(T32<>"",U32="进行中",0)+IF(X32<>"",Y32="进行中",0)>0,"进行中",IF(IF(L32<>"",M32="待确认",0)+IF(P32<>"",Q32="待确认",0)+IF(T32<>"",U32="待确认",0)+IF(X32<>"",Y32="待确认",0)>0,"待确认","未开始"))))) -> 待确认 | H32: =IF(L32<>"",L32,IF(P32<>"",P32,IF(T32<>"",T32,X32))) -> 高级测试人员、中级测试人员 | I32: =IF(COUNT(N32,R32,V32,Z32)=0,"",MIN(N32,R32,V32,Z32)) -> 46270 | J32: =IF(COUNT(O32,S32,W32,AA32)=0,"",MAX(O32,S32,W32,AA32)) -> 46274 | K32: 46290 | X32: 高级测试人员、中级测试人员 | Y32: 待确认 | Z32: 46270 | AA32: 46274 | AB32: =IFERROR((IF(L32<>"",IF(M32="已完成",1,IF(M32="进行中",0.5,0))*15%,0)+IF(P32<>"",IF(Q32="已完成",1,IF(Q32="进行中",0.5,0))*35%,0)+IF(T32<>"",IF(U32="已完成",1,IF(U32="进行中",0.5,0))*30%,0)+IF(X32<>"",IF(Y32="已完成",1,IF(Y32="进行中",0.5,0))*20%,0))/(IF(L32<>"",15%,0)+IF(P32<>"",35%,0)+IF(T32<>"",30%,0)+IF(X32<>"",20%,0)),0) -> 0 | AC32: =IF($A32="","",IF(G32="已完成","正常",IF(G32="暂停","暂停",IF(J32="","日期缺失",IF(J32<_数据接口!$B$7,"已延期",IF(J32<=_数据接口!$B$7+7,"临近到期","正常")))))) -> 已延期 | AH32: =IF(OR($A32="",J32="",AG32=""),"",AG32-J32)
A33: T030 | D33: BI报表验证 | E33: 验证数据接入、指标模型和经营报表 | F33: MS017 | G33: =IF(OR(M33="暂停",M33="挂起",Q33="暂停",Q33="挂起",U33="暂停",U33="挂起",Y33="暂停",Y33="挂起"),"暂停",IF(COUNTA(L33,P33,T33,X33)=0,"未分配",IF(IF(L33<>"",M33="已完成",0)+IF(P33<>"",Q33="已完成",0)+IF(T33<>"",U33="已完成",0)+IF(X33<>"",Y33="已完成",0)=COUNTA(L33,P33,T33,X33),"已完成",IF(IF(L33<>"",M33="进行中",0)+IF(P33<>"",Q33="进行中",0)+IF(T33<>"",U33="进行中",0)+IF(X33<>"",Y33="进行中",0)>0,"进行中",IF(IF(L33<>"",M33="待确认",0)+IF(P33<>"",Q33="待确认",0)+IF(T33<>"",U33="待确认",0)+IF(X33<>"",Y33="待确认",0)>0,"待确认","未开始"))))) -> 待确认 | H33: =IF(L33<>"",L33,IF(P33<>"",P33,IF(T33<>"",T33,X33))) -> 高级开发人员 | I33: =IF(COUNT(N33,R33,V33,Z33)=0,"",MIN(N33,R33,V33,Z33)) -> 46275 | J33: =IF(COUNT(O33,S33,W33,AA33)=0,"",MAX(O33,S33,W33,AA33)) -> 46279 | K33: 46290 | P33: 高级开发人员 | Q33: 待确认 | R33: 46275 | S33: 46279 | AB33: =IFERROR((IF(L33<>"",IF(M33="已完成",1,IF(M33="进行中",0.5,0))*15%,0)+IF(P33<>"",IF(Q33="已完成",1,IF(Q33="进行中",0.5,0))*35%,0)+IF(T33<>"",IF(U33="已完成",1,IF(U33="进行中",0.5,0))*30%,0)+IF(X33<>"",IF(Y33="已完成",1,IF(Y33="进行中",0.5,0))*20%,0))/(IF(L33<>"",15%,0)+IF(P33<>"",35%,0)+IF(T33<>"",30%,0)+IF(X33<>"",20%,0)),0) -> 0 | AC33: =IF($A33="","",IF(G33="已完成","正常",IF(G33="暂停","暂停",IF(J33="","日期缺失",IF(J33<_数据接口!$B$7,"已延期",IF(J33<=_数据接口!$B$7+7,"临近到期","正常")))))) -> 已延期 | AH33: =IF(OR($A33="",J33="",AG33=""),"",AG33-J33)
A34: T031 | E34: 验证权限、钻取、导出和查询性能 | F34: MS017 | G34: =IF(OR(M34="暂停",M34="挂起",Q34="暂停",Q34="挂起",U34="暂停",U34="挂起",Y34="暂停",Y34="挂起"),"暂停",IF(COUNTA(L34,P34,T34,X34)=0,"未分配",IF(IF(L34<>"",M34="已完成",0)+IF(P34<>"",Q34="已完成",0)+IF(T34<>"",U34="已完成",0)+IF(X34<>"",Y34="已完成",0)=COUNTA(L34,P34,T34,X34),"已完成",IF(IF(L34<>"",M34="进行中",0)+IF(P34<>"",Q34="进行中",0)+IF(T34<>"",U34="进行中",0)+IF(X34<>"",Y34="进行中",0)>0,"进行中",IF(IF(L34<>"",M34="待确认",0)+IF(P34<>"",Q34="待确认",0)+IF(T34<>"",U34="待确认",0)+IF(X34<>"",Y34="待确认",0)>0,"待确认","未开始"))))) -> 进行中 | H34: =IF(L34<>"",L34,IF(P34<>"",P34,IF(T34<>"",T34,X34))) -> 高级测试人员、中级测试人员 | I34: =IF(COUNT(N34,R34,V34,Z34)=0,"",MIN(N34,R34,V34,Z34)) -> 46280 | J34: =IF(COUNT(O34,S34,W34,AA34)=0,"",MAX(O34,S34,W34,AA34)) -> 46284 | K34: 46290 | X34: 高级测试人员、中级测试人员 | Y34: 进行中 | Z34: 46280 | AA34: 46284 | AB34: =IFERROR((IF(L34<>"",IF(M34="已完成",1,IF(M34="进行中",0.5,0))*15%,0)+IF(P34<>"",IF(Q34="已完成",1,IF(Q34="进行中",0.5,0))*35%,0)+IF(T34<>"",IF(U34="已完成",1,IF(U34="进行中",0.5,0))*30%,0)+IF(X34<>"",IF(Y34="已完成",1,IF(Y34="进行中",0.5,0))*20%,0))/(IF(L34<>"",15%,0)+IF(P34<>"",35%,0)+IF(T34<>"",30%,0)+IF(X34<>"",20%,0)),0) -> 0.5 | AC34: =IF($A34="","",IF(G34="已完成","正常",IF(G34="暂停","暂停",IF(J34="","日期缺失",IF(J34<_数据接口!$B$7,"已延期",IF(J34<=_数据接口!$B$7+7,"临近到期","正常")))))) -> 临近到期 | AF34: 2026-W40 | AH34: =IF(OR($A34="",J34="",AG34=""),"",AG34-J34)
A35: T032 | D35: POC结论 | E35: 汇总问题清单、适配结论和产品选型建议 | F35: MS017 | G35: =IF(OR(M35="暂停",M35="挂起",Q35="暂停",Q35="挂起",U35="暂停",U35="挂起",Y35="暂停",Y35="挂起"),"暂停",IF(COUNTA(L35,P35,T35,X35)=0,"未分配",IF(IF(L35<>"",M35="已完成",0)+IF(P35<>"",Q35="已完成",0)+IF(T35<>"",U35="已完成",0)+IF(X35<>"",Y35="已完成",0)=COUNTA(L35,P35,T35,X35),"已完成",IF(IF(L35<>"",M35="进行中",0)+IF(P35<>"",Q35="进行中",0)+IF(T35<>"",U35="进行中",0)+IF(X35<>"",Y35="进行中",0)>0,"进行中",IF(IF(L35<>"",M35="待确认",0)+IF(P35<>"",Q35="待确认",0)+IF(T35<>"",U35="待确认",0)+IF(X35<>"",Y35="待确认",0)>0,"待确认","未开始"))))) -> 未开始 | H35: =IF(L35<>"",L35,IF(P35<>"",P35,IF(T35<>"",T35,X35))) -> 项目经理 | I35: =IF(COUNT(N35,R35,V35,Z35)=0,"",MIN(N35,R35,V35,Z35)) -> 46285 | J35: =IF(COUNT(O35,S35,W35,AA35)=0,"",MAX(O35,S35,W35,AA35)) -> 46290 | K35: 46290 | L35: 项目经理 | M35: 未开始 | N35: 46285 | O35: 46290 | AB35: =IFERROR((IF(L35<>"",IF(M35="已完成",1,IF(M35="进行中",0.5,0))*15%,0)+IF(P35<>"",IF(Q35="已完成",1,IF(Q35="进行中",0.5,0))*35%,0)+IF(T35<>"",IF(U35="已完成",1,IF(U35="进行中",0.5,0))*30%,0)+IF(X35<>"",IF(Y35="已完成",1,IF(Y35="进行中",0.5,0))*20%,0))/(IF(L35<>"",15%,0)+IF(P35<>"",35%,0)+IF(T35<>"",30%,0)+IF(X35<>"",20%,0)),0) -> 0 | AC35: =IF($A35="","",IF(G35="已完成","正常",IF(G35="暂停","暂停",IF(J35="","日期缺失",IF(J35<_数据接口!$B$7,"已延期",IF(J35<=_数据接口!$B$7+7,"临近到期","正常")))))) -> 正常 | AE35: 执行工具：项目启动与治理/供应商POC计划、POC评分表；输出选型建议。 | AH35: =IF(OR($A35="",J35="",AG35=""),"",AG35-J35)
A36: T033 | B36: 正式启动准备 | C36: 启动准备评审通过 | D36: 启动准备 | E36: 编制并审批项目章程 | F36: MS006 | G36: =IF(OR(M36="暂停",M36="挂起",Q36="暂停",Q36="挂起",U36="暂停",U36="挂起",Y36="暂停",Y36="挂起"),"暂停",IF(COUNTA(L36,P36,T36,X36)=0,"未分配",IF(IF(L36<>"",M36="已完成",0)+IF(P36<>"",Q36="已完成",0)+IF(T36<>"",U36="已完成",0)+IF(X36<>"",Y36="已完成",0)=COUNTA(L36,P36,T36,X36),"已完成",IF(IF(L36<>"",M36="进行中",0)+IF(P36<>"",Q36="进行中",0)+IF(T36<>"",U36="进行中",0)+IF(X36<>"",Y36="进行中",0)>0,"进行中",IF(IF(L36<>"",M36="待确认",0)+IF(P36<>"",Q36="待确认",0)+IF(T36<>"",U36="待确认",0)+IF(X36<>"",Y36="待确认",0)>0,"待确认","未开始"))))) -> 未开始 | H36: =IF(L36<>"",L36,IF(P36<>"",P36,IF(T36<>"",T36,X36))) -> 项目集经理 | I36: =IF(COUNT(N36,R36,V36,Z36)=0,"",MIN(N36,R36,V36,Z36)) -> 46296 | J36: =IF(COUNT(O36,S36,W36,AA36)=0,"",MAX(O36,S36,W36,AA36)) -> 46297 | K36: 46311 | L36: 项目集经理 | M36: 未开始 | N36: 46296 | O36: 46297 | AB36: =IFERROR((IF(L36<>"",IF(M36="已完成",1,IF(M36="进行中",0.5,0))*15%,0)+IF(P36<>"",IF(Q36="已完成",1,IF(Q36="进行中",0.5,0))*35%,0)+IF(T36<>"",IF(U36="已完成",1,IF(U36="进行中",0.5,0))*30%,0)+IF(X36<>"",IF(Y36="已完成",1,IF(Y36="进行中",0.5,0))*20%,0))/(IF(L36<>"",15%,0)+IF(P36<>"",35%,0)+IF(T36<>"",30%,0)+IF(X36<>"",20%,0)),0) -> 0 | AC36: =IF($A36="","",IF(G36="已完成","正常",IF(G36="暂停","暂停",IF(J36="","日期缺失",IF(J36<_数据接口!$B$7,"已延期",IF(J36<=_数据接口!$B$7+7,"临近到期","正常")))))) -> 正常 | AH36: =IF(OR($A36="",J36="",AG36=""),"",AG36-J36)
A37: T034 | E37: 编制范围、里程碑和主进度计划 | F37: MS006 | G37: =IF(OR(M37="暂停",M37="挂起",Q37="暂停",Q37="挂起",U37="暂停",U37="挂起",Y37="暂停",Y37="挂起"),"暂停",IF(COUNTA(L37,P37,T37,X37)=0,"未分配",IF(IF(L37<>"",M37="已完成",0)+IF(P37<>"",Q37="已完成",0)+IF(T37<>"",U37="已完成",0)+IF(X37<>"",Y37="已完成",0)=COUNTA(L37,P37,T37,X37),"已完成",IF(IF(L37<>"",M37="进行中",0)+IF(P37<>"",Q37="进行中",0)+IF(T37<>"",U37="进行中",0)+IF(X37<>"",Y37="进行中",0)>0,"进行中",IF(IF(L37<>"",M37="待确认",0)+IF(P37<>"",Q37="待确认",0)+IF(T37<>"",U37="待确认",0)+IF(X37<>"",Y37="待确认",0)>0,"待确认","未开始"))))) -> 未开始 | H37: =IF(L37<>"",L37,IF(P37<>"",P37,IF(T37<>"",T37,X37))) -> 项目经理 | I37: =IF(COUNT(N37,R37,V37,Z37)=0,"",MIN(N37,R37,V37,Z37)) -> 46298 | J37: =IF(COUNT(O37,S37,W37,AA37)=0,"",MAX(O37,S37,W37,AA37)) -> 46300 | K37: 46311 | L37: 项目经理 | M37: 未开始 | N37: 46298 | O37: 46300 | AB37: =IFERROR((IF(L37<>"",IF(M37="已完成",1,IF(M37="进行中",0.5,0))*15%,0)+IF(P37<>"",IF(Q37="已完成",1,IF(Q37="进行中",0.5,0))*35%,0)+IF(T37<>"",IF(U37="已完成",1,IF(U37="进行中",0.5,0))*30%,0)+IF(X37<>"",IF(Y37="已完成",1,IF(Y37="进行中",0.5,0))*20%,0))/(IF(L37<>"",15%,0)+IF(P37<>"",35%,0)+IF(T37<>"",30%,0)+IF(X37<>"",20%,0)),0) -> 0 | AC37: =IF($A37="","",IF(G37="已完成","正常",IF(G37="暂停","暂停",IF(J37="","日期缺失",IF(J37<_数据接口!$B$7,"已延期",IF(J37<=_数据接口!$B$7+7,"临近到期","正常")))))) -> 正常 | AH37: =IF(OR($A37="",J37="",AG37=""),"",AG37-J37)
A38: T035 | D38: 组织准备 | E38: 建立项目组织、RACI与沟通机制 | F38: MS006 | G38: =IF(OR(M38="暂停",M38="挂起",Q38="暂停",Q38="挂起",U38="暂停",U38="挂起",Y38="暂停",Y38="挂起"),"暂停",IF(COUNTA(L38,P38,T38,X38)=0,"未分配",IF(IF(L38<>"",M38="已完成",0)+IF(P38<>"",Q38="已完成",0)+IF(T38<>"",U38="已完成",0)+IF(X38<>"",Y38="已完成",0)=COUNTA(L38,P38,T38,X38),"已完成",IF(IF(L38<>"",M38="进行中",0)+IF(P38<>"",Q38="进行中",0)+IF(T38<>"",U38="进行中",0)+IF(X38<>"",Y38="进行中",0)>0,"进行中",IF(IF(L38<>"",M38="待确认",0)+IF(P38<>"",Q38="待确认",0)+IF(T38<>"",U38="待确认",0)+IF(X38<>"",Y38="待确认",0)>0,"待确认","未开始"))))) -> 未开始 | H38: =IF(L38<>"",L38,IF(P38<>"",P38,IF(T38<>"",T38,X38))) -> 项目经理 | I38: =IF(COUNT(N38,R38,V38,Z38)=0,"",MIN(N38,R38,V38,Z38)) -> 46301 | J38: =IF(COUNT(O38,S38,W38,AA38)=0,"",MAX(O38,S38,W38,AA38)) -> 46303 | K38: 46311 | L38: 项目经理 | M38: 未开始 | N38: 46301 | O38: 46303 | AB38: =IFERROR((IF(L38<>"",IF(M38="已完成",1,IF(M38="进行中",0.5,0))*15%,0)+IF(P38<>"",IF(Q38="已完成",1,IF(Q38="进行中",0.5,0))*35%,0)+IF(T38<>"",IF(U38="已完成",1,IF(U38="进行中",0.5,0))*30%,0)+IF(X38<>"",IF(Y38="已完成",1,IF(Y38="进行中",0.5,0))*20%,0))/(IF(L38<>"",15%,0)+IF(P38<>"",35%,0)+IF(T38<>"",30%,0)+IF(X38<>"",20%,0)),0) -> 0 | AC38: =IF($A38="","",IF(G38="已完成","正常",IF(G38="暂停","暂停",IF(J38="","日期缺失",IF(J38<_数据接口!$B$7,"已延期",IF(J38<=_数据接口!$B$7+7,"临近到期","正常")))))) -> 正常 | AE38: 执行工具：项目启动与治理/相关方管理；确认RACI与沟通责任人。 | AH38: =IF(OR($A38="",J38="",AG38=""),"",AG38-J38)
A39: T036 | D39: 资源准备 | E39: 确认30人团队投入与阶段资源计划 | F39: MS006 | G39: =IF(OR(M39="暂停",M39="挂起",Q39="暂停",Q39="挂起",U39="暂停",U39="挂起",Y39="暂停",Y39="挂起"),"暂停",IF(COUNTA(L39,P39,T39,X39)=0,"未分配",IF(IF(L39<>"",M39="已完成",0)+IF(P39<>"",Q39="已完成",0)+IF(T39<>"",U39="已完成",0)+IF(X39<>"",Y39="已完成",0)=COUNTA(L39,P39,T39,X39),"已完成",IF(IF(L39<>"",M39="进行中",0)+IF(P39<>"",Q39="进行中",0)+IF(T39<>"",U39="进行中",0)+IF(X39<>"",Y39="进行中",0)>0,"进行中",IF(IF(L39<>"",M39="待确认",0)+IF(P39<>"",Q39="待确认",0)+IF(T39<>"",U39="待确认",0)+IF(X39<>"",Y39="待确认",0)>0,"待确认","未开始"))))) -> 未开始 | H39: =IF(L39<>"",L39,IF(P39<>"",P39,IF(T39<>"",T39,X39))) -> 项目集经理 | I39: =IF(COUNT(N39,R39,V39,Z39)=0,"",MIN(N39,R39,V39,Z39)) -> 46304 | J39: =IF(COUNT(O39,S39,W39,AA39)=0,"",MAX(O39,S39,W39,AA39)) -> 46305 | K39: 46311 | L39: 项目集经理 | M39: 未开始 | N39: 46304 | O39: 46305 | AB39: =IFERROR((IF(L39<>"",IF(M39="已完成",1,IF(M39="进行中",0.5,0))*15%,0)+IF(P39<>"",IF(Q39="已完成",1,IF(Q39="进行中",0.5,0))*35%,0)+IF(T39<>"",IF(U39="已完成",1,IF(U39="进行中",0.5,0))*30%,0)+IF(X39<>"",IF(Y39="已完成",1,IF(Y39="进行中",0.5,0))*20%,0))/(IF(L39<>"",15%,0)+IF(P39<>"",35%,0)+IF(T39<>"",30%,0)+IF(X39<>"",20%,0)),0) -> 0 | AC39: =IF($A39="","",IF(G39="已完成","正常",IF(G39="暂停","暂停",IF(J39="","日期缺失",IF(J39<_数据接口!$B$7,"已延期",IF(J39<=_数据接口!$B$7+7,"临近到期","正常")))))) -> 正常 | AH39: =IF(OR($A39="",J39="",AG39=""),"",AG39-J39)
A40: T037 | D40: 治理准备 | E40: 建立风险、问题、变更和决策台账 | F40: MS006 | G40: =IF(OR(M40="暂停",M40="挂起",Q40="暂停",Q40="挂起",U40="暂停",U40="挂起",Y40="暂停",Y40="挂起"),"暂停",IF(COUNTA(L40,P40,T40,X40)=0,"未分配",IF(IF(L40<>"",M40="已完成",0)+IF(P40<>"",Q40="已完成",0)+IF(T40<>"",U40="已完成",0)+IF(X40<>"",Y40="已完成",0)=COUNTA(L40,P40,T40,X40),"已完成",IF(IF(L40<>"",M40="进行中",0)+IF(P40<>"",Q40="进行中",0)+IF(T40<>"",U40="进行中",0)+IF(X40<>"",Y40="进行中",0)>0,"进行中",IF(IF(L40<>"",M40="待确认",0)+IF(P40<>"",Q40="待确认",0)+IF(T40<>"",U40="待确认",0)+IF(X40<>"",Y40="待确认",0)>0,"待确认","未开始"))))) -> 未开始 | H40: =IF(L40<>"",L40,IF(P40<>"",P40,IF(T40<>"",T40,X40))) -> 项目经理 | I40: =IF(COUNT(N40,R40,V40,Z40)=0,"",MIN(N40,R40,V40,Z40)) -> 46306 | J40: =IF(COUNT(O40,S40,W40,AA40)=0,"",MAX(O40,S40,W40,AA40)) -> 46308 | K40: 46311 | L40: 项目经理 | M40: 未开始 | N40: 46306 | O40: 46308 | AB40: =IFERROR((IF(L40<>"",IF(M40="已完成",1,IF(M40="进行中",0.5,0))*15%,0)+IF(P40<>"",IF(Q40="已完成",1,IF(Q40="进行中",0.5,0))*35%,0)+IF(T40<>"",IF(U40="已完成",1,IF(U40="进行中",0.5,0))*30%,0)+IF(X40<>"",IF(Y40="已完成",1,IF(Y40="进行中",0.5,0))*20%,0))/(IF(L40<>"",15%,0)+IF(P40<>"",35%,0)+IF(T40<>"",30%,0)+IF(X40<>"",20%,0)),0) -> 0 | AC40: =IF($A40="","",IF(G40="已完成","正常",IF(G40="暂停","暂停",IF(J40="","日期缺失",IF(J40<_数据接口!$B$7,"已延期",IF(J40<=_数据接口!$B$7+7,"临近到期","正常")))))) -> 正常 | AH40: =IF(OR($A40="",J40="",AG40=""),"",AG40-J40)
...

Sheet 总控筛选视图
A1: 能源行业合同全生命周期管理系统｜总控筛选视图
A2: 只读筛选视图：数据与项目总控台账公式联动；筛选、排序可在本页执行，业务数据请回项目总控台账维护。
A3: 任务ID | B3: 一级功能 | C3: 二级功能 | D3: 三级功能 | E3: 四级功能 | F3: 批次 | G3: 总体状态 | H3: 主责人 | I3: 计划开始 | J3: 计划完成 | K3: 计划上线 | L3: 业务负责人 | M3: 业务状态 | N3: 业务开始 | O3: 业务结束 | P3: 后端负责人 | Q3: 后端状态 | R3: 后端开始 | S3: 后端结束 | T3: 前端负责人 | U3: 前端状态 | V3: 前端开始 | W3: 前端结束 | X3: 测试负责人 | Y3: 测试状态 | Z3: 测试开始 | AA3: 测试结束 | AB3: 综合进度 | AC3: 延期状态 | AD3: 当前问题/阻塞 | AE3: 备注 | AF3: 迭代周 | AG3: 预测完成日期 | AH3: 基线偏差天数
A4: =IF(项目总控台账!A4="","",项目总控台账!A4) -> T001 | B4: =项目总控台账!B4 -> 可研与原业务梳理 | C4: =项目总控台账!C4 -> 可研工作启动 | D4: =项目总控台账!D4 -> 可研启动 | E4: =IF(项目总控台账!E4="","",项目总控台账!E4) -> 明确可研目标、范围与边界 | F4: =IF(项目总控台账!F4="","",项目总控台账!F4) -> MS001 | G4: =IF(项目总控台账!G4="","",项目总控台账!G4) -> 已完成 | H4: =IF(项目总控台账!H4="","",项目总控台账!H4) -> 项目经理 | I4: =IF(项目总控台账!I4="","",项目总控台账!I4) -> 46054 | J4: =IF(项目总控台账!J4="","",项目总控台账!J4) -> 46056 | K4: =IF(项目总控台账!K4="","",项目总控台账!K4) -> 46063 | L4: =IF(项目总控台账!L4="","",项目总控台账!L4) -> 项目经理 | ... AH4: =IF(项目总控台账!AH4="","",项目总控台账!AH4)
A5: =IF(项目总控台账!A5="","",项目总控台账!A5) -> T002 | B5: =项目总控台账!B4 -> 可研与原业务梳理 | C5: =项目总控台账!C4 -> 可研工作启动 | D5: =项目总控台账!D4 -> 可研启动 | E5: =IF(项目总控台账!E5="","",项目总控台账!E5) -> 建立相关方清单与访谈计划 | F5: =IF(项目总控台账!F5="","",项目总控台账!F5) -> MS001 | G5: =IF(项目总控台账!G5="","",项目总控台账!G5) -> 已完成 | H5: =IF(项目总控台账!H5="","",项目总控台账!H5) -> 产品经理 | I5: =IF(项目总控台账!I5="","",项目总控台账!I5) -> 46057 | J5: =IF(项目总控台账!J5="","",项目总控台账!J5) -> 46059 | K5: =IF(项目总控台账!K5="","",项目总控台账!K5) -> 46063 | L5: =IF(项目总控台账!L5="","",项目总控台账!L5) -> 产品经理 | ... AH5: =IF(项目总控台账!AH5="","",项目总控台账!AH5)
A6: =IF(项目总控台账!A6="","",项目总控台账!A6) -> T003 | B6: =项目总控台账!B4 -> 可研与原业务梳理 | C6: =项目总控台账!C4 -> 可研工作启动 | D6: =项目总控台账!D4 -> 可研启动 | E6: =IF(项目总控台账!E6="","",项目总控台账!E6) -> 评审并发布可研工作方案 | F6: =IF(项目总控台账!F6="","",项目总控台账!F6) -> MS001 | G6: =IF(项目总控台账!G6="","",项目总控台账!G6) -> 已完成 | H6: =IF(项目总控台账!H6="","",项目总控台账!H6) -> 项目集经理 | I6: =IF(项目总控台账!I6="","",项目总控台账!I6) -> 46060 | J6: =IF(项目总控台账!J6="","",项目总控台账!J6) -> 46063 | K6: =IF(项目总控台账!K6="","",项目总控台账!K6) -> 46063 | L6: =IF(项目总控台账!L6="","",项目总控台账!L6) -> 项目集经理 | ... AH6: =IF(项目总控台账!AH6="","",项目总控台账!AH6)
A7: =IF(项目总控台账!A7="","",项目总控台账!A7) -> T004 | B7: =项目总控台账!B4 -> 可研与原业务梳理 | C7: =项目总控台账!C7 -> 可行性研究完成 | D7: =项目总控台账!D7 -> 可行性研究 | E7: =IF(项目总控台账!E7="","",项目总控台账!E7) -> 完成业务可行性与需求价值分析 | F7: =IF(项目总控台账!F7="","",项目总控台账!F7) -> MS002 | G7: =IF(项目总控台账!G7="","",项目总控台账!G7) -> 已完成 | H7: =IF(项目总控台账!H7="","",项目总控台账!H7) -> 产品经理 | I7: =IF(项目总控台账!I7="","",项目总控台账!I7) -> 46054 | J7: =IF(项目总控台账!J7="","",项目总控台账!J7) -> 46099 | K7: =IF(项目总控台账!K7="","",项目总控台账!K7) -> 46283 | L7: =IF(项目总控台账!L7="","",项目总控台账!L7) -> 产品经理 | ... AH7: =IF(项目总控台账!AH7="","",项目总控台账!AH7)
A8: =IF(项目总控台账!A8="","",项目总控台账!A8) -> T005 | B8: =项目总控台账!B4 -> 可研与原业务梳理 | C8: =项目总控台账!C7 -> 可行性研究完成 | D8: =项目总控台账!D7 -> 可行性研究 | E8: =IF(项目总控台账!E8="","",项目总控台账!E8) -> 完成技术路线与系统边界论证 | F8: =IF(项目总控台账!F8="","",项目总控台账!F8) -> MS002 | G8: =IF(项目总控台账!G8="","",项目总控台账!G8) -> 已完成 | H8: =IF(项目总控台账!H8="","",项目总控台账!H8) -> 技术经理 | I8: =IF(项目总控台账!I8="","",项目总控台账!I8) -> 46100 | J8: =IF(项目总控台账!J8="","",项目总控台账!J8) -> 46145 | K8: =IF(项目总控台账!K8="","",项目总控台账!K8) -> 46283 | L8: =IF(项目总控台账!L8="","",项目总控台账!L8) | ... AH8: =IF(项目总控台账!AH8="","",项目总控台账!AH8)
