Workbook

Sheet 里程碑计划
A1: 能源行业合同全生命周期管理系统｜里程碑计划
A3: 里程碑ID | B3: 里程碑名称 | C3: 阶段 | D3: 验收/完成标准 | E3: 责任角色 | F3: 计划日期 | G3: 状态 | H3: 实际日期 | I3: 偏差天数 | J3: 健康度 | K3: 交付物
A4: MS001 | B4: 可研工作启动 | C4: 可研与原业务梳理 | D4: 范围、负责人和调研计划确认 | E4: 项目经理 | F4: 46063 | G4: 计划日期已到，待确认 | I4: =IF(H4<>"",H4-F4,MAX(0,_数据接口!$B$7-F4)) -> 218 | J4: =IF(G4="已完成","绿",IF(F4<_数据接口!$B$7,"红",IF(F4<=_数据接口!$B$7+7,"黄","绿"))) -> 红 | K4: 可研工作方案
A5: MS002 | B5: 可行性研究完成 | C5: 可研与原业务梳理 | D5: 业务、技术、投资和实施可行性完成评审 | E5: 项目集经理 | F5: 46283 | G5: 未开始 | I5: =IF(H5<>"",H5-F5,MAX(0,_数据接口!$B$7-F5)) -> 0 | J5: =IF(G5="已完成","绿",IF(F5<_数据接口!$B$7,"红",IF(F5<=_数据接口!$B$7+7,"黄","绿"))) -> 黄 | K5: 项目可行性研究报告
A6: MS003 | B6: 原业务梳理完成 | C6: 可研与原业务梳理 | D6: 核心业务部门确认现状基线 | E6: 产品经理 | F6: 46203 | G6: 计划日期已到，待确认 | I6: =IF(H6<>"",H6-F6,MAX(0,_数据接口!$B$7-F6)) -> 78 | J6: =IF(G6="已完成","绿",IF(F6<_数据接口!$B$7,"红",IF(F6<=_数据接口!$B$7+7,"黄","绿"))) -> 红 | K6: 现状流程、问题及改进机会清单
A7: MS004 | B7: 项目规范基线确认 | C7: 项目规范梳理与技术架构搭建 | D7: 计划、需求、质量、变更和配置规范通过评审 | E7: 项目经理 | F7: 46265 | G7: 计划日期已到，待确认 | I7: =IF(H7<>"",H7-F7,MAX(0,_数据接口!$B$7-F7)) -> 16 | J7: =IF(G7="已完成","绿",IF(F7<_数据接口!$B$7,"红",IF(F7<=_数据接口!$B$7+7,"黄","绿"))) -> 红 | K7: 项目管理与研发规范
A8: MS005 | B8: 技术架构基线确认 | C8: 项目规范梳理与技术架构搭建 | D8: 应用、数据、集成、安全和部署架构通过评审 | E8: 技术经理 | F8: 46295 | G8: 未开始 | I8: =IF(H8<>"",H8-F8,MAX(0,_数据接口!$B$7-F8)) -> 0 | J8: =IF(G8="已完成","绿",IF(F8<_数据接口!$B$7,"红",IF(F8<=_数据接口!$B$7+7,"黄","绿"))) -> 绿 | K8: 总体技术架构和环境基础
A9: MS006 | B9: 启动准备评审通过 | C9: 正式启动准备 | D9: 范围、组织、预算、计划和治理机制具备启动条件 | E9: 项目集经理 | F9: 46311 | G9: 未开始 | I9: =IF(H9<>"",H9-F9,MAX(0,_数据接口!$B$7-F9)) -> 0 | J9: =IF(G9="已完成","绿",IF(F9<_数据接口!$B$7,"红",IF(F9<=_数据接口!$B$7+7,"黄","绿"))) -> 绿 | K9: 项目章程、实施计划和启动材料
A10: MS007 | B10: 项目正式启动 | C10: 正式实施与上线准备 | D10: 项目组织到位、职责明确、计划发布 | E10: 项目集经理 | F10: 46315 | G10: 未开始 | I10: =IF(H10<>"",H10-F10,MAX(0,_数据接口!$B$7-F10)) -> 0 | J10: =IF(G10="已完成","绿",IF(F10<_数据接口!$B$7,"红",IF(F10<=_数据接口!$B$7+7,"黄","绿"))) -> 绿 | K10: 启动会纪要与行动项
A11: MS008 | B11: 需求基线确认 | C11: 正式实施与上线准备 | D11: P0/P1/P2范围、验收标准和变更机制确认 | E11: 产品经理 | F11: 46356 | G11: 未开始 | I11: =IF(H11<>"",H11-F11,MAX(0,_数据接口!$B$7-F11)) -> 0 | J11: =IF(G11="已完成","绿",IF(F11<_数据接口!$B$7,"红",IF(F11<=_数据接口!$B$7+7,"黄","绿"))) -> 绿 | K11: 需求规格说明书与跟踪矩阵
A12: MS009 | B12: 详细设计完成 | C12: 正式实施与上线准备 | D12: 核心模块、数据、接口、权限和安全设计通过评审 | E12: 技术经理 | F12: 46387 | G12: 未开始 | I12: =IF(H12<>"",H12-F12,MAX(0,_数据接口!$B$7-F12)) -> 0 | J12: =IF(G12="已完成","绿",IF(F12<_数据接口!$B$7,"红",IF(F12<=_数据接口!$B$7+7,"黄","绿"))) -> 绿 | K12: 详细设计、数据和接口设计
A13: MS010 | B13: 核心功能开发完成 | C13: 正式实施与上线准备 | D13: P0功能完成且单元测试通过 | E13: 高级开发人员 | F13: 46461 | G13: 未开始 | I13: =IF(H13<>"",H13-F13,MAX(0,_数据接口!$B$7-F13)) -> 0 | J13: =IF(G13="已完成","绿",IF(F13<_数据接口!$B$7,"红",IF(F13<=_数据接口!$B$7+7,"黄","绿"))) -> 绿 | K13: 可测试版本
A14: MS011 | B14: 系统测试完成 | C14: 正式实施与上线准备 | D14: 阻断及严重缺陷关闭，核心集成验证通过 | E14: 测试人员 | F14: 46492 | G14: 未开始 | I14: =IF(H14<>"",H14-F14,MAX(0,_数据接口!$B$7-F14)) -> 0 | J14: =IF(G14="已完成","绿",IF(F14<_数据接口!$B$7,"红",IF(F14<=_数据接口!$B$7+7,"黄","绿"))) -> 绿 | K14: 系统测试报告
A15: MS012 | B15: UAT验收完成 | C15: 正式实施与上线准备 | D15: P0场景验收通过，遗留事项获得批准 | E15: 产品经理 | F15: 46517 | G15: 未开始 | I15: =IF(H15<>"",H15-F15,MAX(0,_数据接口!$B$7-F15)) -> 0 | J15: =IF(G15="已完成","绿",IF(F15<_数据接口!$B$7,"红",IF(F15<=_数据接口!$B$7+7,"黄","绿"))) -> 绿 | K15: UAT报告与业务确认单
... A17: MS014 | B17: 生产上线并进入试运行 | C17: 系统上线与试运行 | D17: 生产验证通过、监控启用、支持机制生效 | E17: 项目集经理 | F17: 46538 | G17: 未开始 | I17: =IF(H17<>"",H17-F17,MAX(0,_数据接口!$B$7-F17)) -> 0 | J17: =IF(G17="已完成","绿",IF(F17<_数据接口!$B$7,"红",IF(F17<=_数据接口!$B$7+7,"黄","绿"))) -> 绿 | K17: 上线确认单和试运行计划

Sheet 项目总控台账
A1: 华能交易中心港口交易平台｜项目总控台账
A2: 蓝色字段来自原开发计划；黄色字段为管理补充项；进度与延期由公式自动计算。
A3: 任务ID | B3: 一级功能 | C3: 二级功能 | D3: 三级功能 | E3: 四级功能 | F3: 批次 | G3: 总体状态 | H3: 主责人 | I3: 计划开始 | J3: 计划完成 | K3: 计划上线 | L3: 业务负责人 | M3: 业务状态 | N3: 业务开始 | O3: 业务结束 | P3: 后端负责人 | Q3: 后端状态 | R3: 后端开始 | S3: 后端结束 | T3: 前端负责人 | U3: 前端状态 | V3: 前端开始 | W3: 前端结束 | X3: 测试负责人 | Y3: 测试状态 | Z3: 测试开始 | AA3: 测试结束 | AB3: 综合进度 | AC3: 延期状态 | AD3: 当前问题/阻塞 | AE3: 备注
A4: T001 | B4: 基础数据 | C4: 车辆信息维护 | D4: 新增车辆信息 | E4: / | F4: 第一批次 | G4: =IF(OR(M4="挂起",M4="暂停",Q4="挂起",Q4="暂停",U4="挂起",U4="暂停",Y4="挂起",Y4="暂停"),"暂停","已完成") -> 已完成 | H4: =IF(L4<>"",L4,IF(P4<>"",P4,IF(T4<>"",T4,X4))) -> 郑士旺 | I4: =IF(COUNT(N4,R4,V4,Z4)=0,"",MIN(N4,R4,V4,Z4)) -> 46202 | J4: =IF(ISNUMBER(K4),K4,IF(COUNT(O4,S4,W4,AA4)=0,"",MAX(O4,S4,W4,AA4))) -> 46234 | K4: / | L4: 郑士旺 | M4: 已完成 | N4: 46202 | O4: 46206 | P4: 石军磊、刘凯 | Q4: 已完成 | R4: 46209 | S4: 46225 | T4: 贺航 | U4: 已完成 | V4: 46209 | W4: 46225 | X4: 袁丽荣 | Y4: 已完成 | Z4: 46216 | AA4: 46234 | AB4: =(IF(M4="已完成",1,IF(M4="进行中",0.5,0))*15%+IF(Q4="已完成",1,IF(Q4="进行中",0.5,0))*35%+IF(U4="已完成",1,IF(U4="进行中",0.5,0))*30%+IF(Y4="已完成",1,IF(Y4="进行中",0.5,0))*20%) -> 1 | AC4: =IF(G4="已完成","正常",IF(OR(G4="暂停",G4="挂起"),"暂停",IF(J4="","日期缺失",IF(J4<_数据接口!$B$7,"已延期",IF(J4<=_数据接口!$B$7+7,"临近到期","正常"))))) -> 正常 | AD4: 69 | AE4: 69
A5: T002 | B5: 基础数据 | C5: 车辆信息维护 | D5: 修改车辆信息 | E5: / | F5: 第一批次 | G5: =IF(OR(M5="挂起",M5="暂停",Q5="挂起",Q5="暂停",U5="挂起",U5="暂停",Y5="挂起",Y5="暂停"),"暂停","已完成") -> 已完成 | H5: =IF(L5<>"",L5,IF(P5<>"",P5,IF(T5<>"",T5,X5))) -> 郑士旺 | I5: =IF(COUNT(N5,R5,V5,Z5)=0,"",MIN(N5,R5,V5,Z5)) -> 46202 | J5: =IF(ISNUMBER(K5),K5,IF(COUNT(O5,S5,W5,AA5)=0,"",MAX(O5,S5,W5,AA5))) -> 46234 | K5: / | L5: 郑士旺 | M5: 已完成 | N5: 46202 | O5: 46206 | P5: 石军磊、刘凯 | Q5: 已完成 | R5: 46209 | S5: 46225 | T5: 贺航 | U5: 已完成 | V5: 46209 | W5: 46225 | X5: 袁丽荣 | Y5: 已完成 | Z5: 46216 | AA5: 46234 | AB5: =(IF(M5="已完成",1,IF(M5="进行中",0.5,0))*15%+IF(Q5="已完成",1,IF(Q5="进行中",0.5,0))*35%+IF(U5="已完成",1,IF(U5="进行中",0.5,0))*30%+IF(Y5="已完成",1,IF(Y5="进行中",0.5,0))*20%) -> 1 | AC5: =IF(G5="已完成","正常",IF(OR(G5="暂停",G5="挂起"),"暂停",IF(J5="","日期缺失",IF(J5<_数据接口!$B$7,"已延期",IF(J5<=_数据接口!$B$7+7,"临近到期","正常"))))) -> 正常 | AD5: 69 | AE5: 69
A6: T003 | B6: 基础数据 | C6: 车辆信息维护 | D6: 删除车辆信息 | E6: / | F6: 第一批次 | G6: =IF(OR(M6="挂起",M6="暂停",Q6="挂起",Q6="暂停",U6="挂起",U6="暂停",Y6="挂起",Y6="暂停"),"暂停","已完成") -> 已完成 | H6: =IF(L6<>"",L6,IF(P6<>"",P6,IF(T6<>"",T6,X6))) -> 郑士旺 | I6: =IF(COUNT(N6,R6,V6,Z6)=0,"",MIN(N6,R6,V6,Z6)) -> 46202 | J6: =IF(ISNUMBER(K6),K6,IF(COUNT(O6,S6,W6,AA6)=0,"",MAX(O6,S6,W6,AA6))) -> 46234 | K6: / | L6: 郑士旺 | M6: 已完成 | N6: 46202 | O6: 46206 | P6: 石军磊、刘凯 | Q6: 已完成 | R6: 46209 | S6: 46225 | T6: 贺航 | U6: 已完成 | V6: 46209 | W6: 46225 | X6: 袁丽荣 | Y6: 已完成 | Z6: 46216 | AA6: 46234 | AB6: =(IF(M6="已完成",1,IF(M6="进行中",0.5,0))*15%+IF(Q6="已完成",1,IF(Q6="进行中",0.5,0))*35%+IF(U6="已完成",1,IF(U6="进行中",0.5,0))*30%+IF(Y6="已完成",1,IF(Y6="进行中",0.5,0))*20%) -> 1 | AC6: =IF(G6="已完成","正常",IF(OR(G6="暂停",G6="挂起"),"暂停",IF(J6="","日期缺失",IF(J6<_数据接口!$B$7,"已延期",IF(J6<=_数据接口!$B$7+7,"临近到期","正常"))))) -> 正常 | AD6: 69 | AE6: 69
A7: T004 | B7: 基础数据 | C7: 车辆信息维护 | D7: 查询展示车辆信息 | E7: / | F7: 第一批次 | G7: =IF(OR(M7="挂起",M7="暂停",Q7="挂起",Q7="暂停",U7="挂起",U7="暂停",Y7="挂起",Y7="暂停"),"暂停","已完成") -> 已完成 | H7: =IF(L7<>"",L7,IF(P7<>"",P7,IF(T7<>"",T7,X7))) -> 郑士旺 | I7: =IF(COUNT(N7,R7,V7,Z7)=0,"",MIN(N7,R7,V7,Z7)) -> 46202 | J7: =IF(ISNUMBER(K7),K7,IF(COUNT(O7,S7,W7,AA7)=0,"",MAX(O7,S7,W7,AA7))) -> 46234 | K7: / | L7: 郑士旺 | M7: 已完成 | N7: 46202 | O7: 46206 | P7: 石军磊、刘凯 | Q7: 已完成 | R7: 46209 | S7: 46225 | T7: 贺航 | U7: 已完成 | V7: 46209 | W7: 46225 | X7: 袁丽荣 | Y7: 已完成 | Z7: 46216 | AA7: 46234 | AB7: =(IF(M7="已完成",1,IF(M7="进行中",0.5,0))*15%+IF(Q7="已完成",1,IF(Q7="进行中",0.5,0))*35%+IF(U7="已完成",1,IF(U7="进行中",0.5,0))*30%+IF(Y7="已完成",1,IF(Y7="进行中",0.5,0))*20%) -> 1 | AC7: =IF(G7="已完成","正常",IF(OR(G7="暂停",G7="挂起"),"暂停",IF(J7="","日期缺失",IF(J7<_数据接口!$B$7,"已延期",IF(J7<=_数据接口!$B$7+7,"临近到期","正常"))))) -> 正常 | AD7: 69 | AE7: 69
A8: T005 | B8: 基础数据 | C8: 船舶信息维护 | D8: 船舶唯一性校验 | E8: / | F8: 第二批次 | G8: =IF(OR(M8="挂起",M8="暂停",Q8="挂起",Q8="暂停",U8="挂起",U8="暂停",Y8="挂起",Y8="暂停"),"暂停","已完成") -> 已完成 | H8: =IF(L8<>"",L8,IF(P8<>"",P8,IF(T8<>"",T8,X8))) -> 郑士旺 | I8: =IF(COUNT(N8,R8,V8,Z8)=0,"",MIN(N8,R8,V8,Z8)) -> 46230 | J8: =IF(ISNUMBER(K8),K8,IF(COUNT(O8,S8,W8,AA8)=0,"",MAX(O8,S8,W8,AA8))) -> 46353 | K8: / | L8: 郑士旺 | M8: 已完成 | N8: 46230 | O8: 46241 | P8: 石军磊、刘凯 | Q8: 已完成 | R8: 46307 | S8: 46339 | T8: 贺航 | U8: 已完成 | V8: 46307 | W8: 46339 | X8: 袁丽荣 | Y8: 已完成 | Z8: 46342 | AA8: 46353 | AB8: =(IF(M8="已完成",1,IF(M8="进行中",0.5,0))*15%+IF(Q8="已完成",1,IF(Q8="进行中",0.5,0))*35%+IF(U8="已完成",1,IF(U8="进行中",0.5,0))*30%+IF(Y8="已完成",1,IF(Y8="进行中",0.5,0))*20%) -> 1 | AC8: =IF(G8="已完成","正常",IF(OR(G8="暂停",G8="挂起"),"暂停",IF(J8="","日期缺失",IF(J8<_数据接口!$B$7,"已延期",IF(J8<=_数据接口!$B$7+7,"临近到期","正常"))))) -> 正常 | AD8: 69 | AE8: 69
A9: T006 | B9: 基础数据 | C9: 收费标准信息维护 | D9: 优化收费标准（装卸费）新增 | E9: / | F9: 第一批次 | G9: =IF(OR(M9="挂起",M9="暂停",Q9="挂起",Q9="暂停",U9="挂起",U9="暂停",Y9="挂起",Y9="暂停"),"暂停","已完成") -> 已完成 | H9: =IF(L9<>"",L9,IF(P9<>"",P9,IF(T9<>"",T9,X9))) -> 郑士旺 | I9: =IF(COUNT(N9,R9,V9,Z9)=0,"",MIN(N9,R9,V9,Z9)) -> 46202 | J9: =IF(ISNUMBER(K9),K9,IF(COUNT(O9,S9,W9,AA9)=0,"",MAX(O9,S9,W9,AA9))) -> 46224 | K9: 46224 | L9: 郑士旺 | M9: 已完成 | N9: 46202 | O9: 46206 | P9: 石军磊、刘凯 | Q9: 已完成 | R9: 46209 | S9: 46227 | T9: 贺航 | U9: 已完成 | V9: 46209 | W9: 46227 | X9: 袁丽荣 | Y9: 已完成 | Z9: 46216 | AA9: 46234 | AB9: =(IF(M9="已完成",1,IF(M9="进行中",0.5,0))*15%+IF(Q9="已完成",1,IF(Q9="进行中",0.5,0))*35%+IF(U9="已完成",1,IF(U9="进行中",0.5,0))*30%+IF(Y9="已完成",1,IF(Y9="进行中",0.5,0))*20%) -> 1 | AC9: =IF(G9="已完成","正常",IF(OR(G9="暂停",G9="挂起"),"暂停",IF(J9="","日期缺失",IF(J9<_数据接口!$B$7,"已延期",IF(J9<=_数据接口!$B$7+7,"临近到期","正常"))))) -> 正常 | AD9: 69 | AE9: 69
A10: T007 | B10: 基础数据 | C10: 收费标准信息维护 | D10: 优化收费标准（装卸费）编辑 | E10: / | F10: 第一批次 | G10: =IF(OR(M10="挂起",M10="暂停",Q10="挂起",Q10="暂停",U10="挂起",U10="暂停",Y10="挂起",Y10="暂停"),"暂停","已完成") -> 已完成 | H10: =IF(L10<>"",L10,IF(P10<>"",P10,IF(T10<>"",T10,X10))) -> 郑士旺 | I10: =IF(COUNT(N10,R10,V10,Z10)=0,"",MIN(N10,R10,V10,Z10)) -> 46202 | J10: =IF(ISNUMBER(K10),K10,IF(COUNT(O10,S10,W10,AA10)=0,"",MAX(O10,S10,W10,AA10))) -> 46224 | K10: 46224 | L10: 郑士旺 | M10: 已完成 | N10: 46202 | O10: 46206 | P10: 石军磊、刘凯 | Q10: 已完成 | R10: 46209 | S10: 46227 | T10: 贺航 | U10: 已完成 | V10: 46209 | W10: 46227 | X10: 袁丽荣 | Y10: 已完成 | Z10: 46216 | AA10: 46234 | AB10: =(IF(M10="已完成",1,IF(M10="进行中",0.5,0))*15%+IF(Q10="已完成",1,IF(Q10="进行中",0.5,0))*35%+IF(U10="已完成",1,IF(U10="进行中",0.5,0))*30%+IF(Y10="已完成",1,IF(Y10="进行中",0.5,0))*20%) -> 1 | AC10: =IF(G10="已完成","正常",IF(OR(G10="暂停",G10="挂起"),"暂停",IF(J10="","日期缺失",IF(J10<_数据接口!$B$7,"已延期",IF(J10<=_数据接口!$B$7+7,"临近到期","正常"))))) -> 正常 | AD10: 69 | AE10: 69
A11: T008 | B11: 基础数据 | C11: 收费标准信息维护 | D11: 优化收费标准（装卸费）详情 | E11: / | F11: 第一批次 | G11: =IF(OR(M11="挂起",M11="暂停",Q11="挂起",Q11="暂停",U11="挂起",U11="暂停",Y11="挂起",Y11="暂停"),"暂停","已完成") -> 已完成 | H11: =IF(L11<>"",L11,IF(P11<>"",P11,IF(T11<>"",T11,X11))) -> 郑士旺 | I11: =IF(COUNT(N11,R11,V11,Z11)=0,"",MIN(N11,R11,V11,Z11)) -> 46202 | J11: =IF(ISNUMBER(K11),K11,IF(COUNT(O11,S11,W11,AA11)=0,"",MAX(O11,S11,W11,AA11))) -> 46224 | K11: 46224 | L11: 郑士旺 | M11: 已完成 | N11: 46202 | O11: 46206 | P11: 石军磊、刘凯 | Q11: 已完成 | R11: 46209 | S11: 46227 | T11: 贺航 | U11: 已完成 | V11: 46209 | W11: 46227 | X11: 袁丽荣 | Y11: 已完成 | Z11: 46216 | AA11: 46234 | AB11: =(IF(M11="已完成",1,IF(M11="进行中",0.5,0))*15%+IF(Q11="已完成",1,IF(Q11="进行中",0.5,0))*35%+IF(U11="已完成",1,IF(U11="进行中",0.5,0))*30%+IF(Y11="已完成",1,IF(Y11="进行中",0.5,0))*20%) -> 1 | AC11: =IF(G11="已完成","正常",IF(OR(G11="暂停",G11="挂起"),"暂停",IF(J11="","日期缺失",IF(J11<_数据接口!$B$7,"已延期",IF(J11<=_数据接口!$B$7+7,"临近到期","正常"))))) -> 正常 | AD11: 69 | AE11: 69
A12: T009 | B12: 基础数据 | C12: 采样方式信息维护 | D12: 优化采样方式新增 | E12: / | F12: 第一批次 | G12: =IF(OR(M12="挂起",M12="暂停",Q12="挂起",Q12="暂停",U12="挂起",U12="暂停",Y12="挂起",Y12="暂停"),"暂停","已完成") -> 已完成 | H12: =IF(L12<>"",L12,IF(P12<>"",P12,IF(T12<>"",T12,X12))) -> 郑士旺 | I12: =IF(COUNT(N12,R12,V12,Z12)=0,"",MIN(N12,R12,V12,Z12)) -> 46202 | J12: =IF(ISNUMBER(K12),K12,IF(COUNT(O12,S12,W12,AA12)=0,"",MAX(O12,S12,W12,AA12))) -> 46224 | K12: 46224 | L12: 郑士旺 | M12: 已完成 | N12: 46202 | O12: 46206 | P12: 石军磊、刘凯 | Q12: 已完成 | R12: 46209 | S12: 46227 | T12: 贺航 | U12: 已完成 | V12: 46209 | W12: 46227 | X12: 袁丽荣 | Y12: 已完成 | Z12: 46216 | AA12: 46234 | AB12: =(IF(M12="已完成",1,IF(M12="进行中",0.5,0))*15%+IF(Q12="已完成",1,IF(Q12="进行中",0.5,0))*35%+IF(U12="已完成",1,IF(U12="进行中",0.5,0))*30%+IF(Y12="已完成",1,IF(Y12="进行中",0.5,0))*20%) -> 1 | AC12: =IF(G12="已完成","正常",IF(OR(G12="暂停",G12="挂起"),"暂停",IF(J12="","日期缺失",IF(J12<_数据接口!$B$7,"已延期",IF(J12<=_数据接口!$B$7+7,"临近到期","正常"))))) -> 正常 | AD12: 69 | AE12: 69
A13: T010 | B13: 基础数据 | C13: 采样方式信息维护 | D13: 优化采样方式编辑 | E13: / | F13: 第一批次 | G13: =IF(OR(M13="挂起",M13="暂停",Q13="挂起",Q13="暂停",U13="挂起",U13="暂停",Y13="挂起",Y13="暂停"),"暂停","已完成") -> 已完成 | H13: =IF(L13<>"",L13,IF(P13<>"",P13,IF(T13<>"",T13,X13))) -> 郑士旺 | I13: =IF(COUNT(N13,R13,V13,Z13)=0,"",MIN(N13,R13,V13,Z13)) -> 46202 | J13: =IF(ISNUMBER(K13),K13,IF(COUNT(O13,S13,W13,AA13)=0,"",MAX(O13,S13,W13,AA13))) -> 46224 | K13: 46224 | L13: 郑士旺 | M13: 已完成 | N13: 46202 | O13: 46206 | P13: 石军磊、刘凯 | Q13: 已完成 | R13: 46209 | S13: 46227 | T13: 贺航 | U13: 已完成 | V13: 46209 | W13: 46227 | X13: 袁丽荣 | Y13: 已完成 | Z13: 46216 | AA13: 46234 | AB13: =(IF(M13="已完成",1,IF(M13="进行中",0.5,0))*15%+IF(Q13="已完成",1,IF(Q13="进行中",0.5,0))*35%+IF(U13="已完成",1,IF(U13="进行中",0.5,0))*30%+IF(Y13="已完成",1,IF(Y13="进行中",0.5,0))*20%) -> 1 | AC13: =IF(G13="已完成","正常",IF(OR(G13="暂停",G13="挂起"),"暂停",IF(J13="","日期缺失",IF(J13<_数据接口!$B$7,"已延期",IF(J13<=_数据接口!$B$7+7,"临近到期","正常"))))) -> 正常 | AD13: 69 | AE13: 69
A14: T011 | B14: 网上营业厅 | C14: 交易中心报单信息展示及应单入口 | D14: 获取报单数据及展示 | E14: / | F14: 第一批次 | G14: =IF(OR(M14="挂起",M14="暂停",Q14="挂起",Q14="暂停",U14="挂起",U14="暂停",Y14="挂起",Y14="暂停"),"暂停","已完成") -> 已完成 | H14: =IF(L14<>"",L14,IF(P14<>"",P14,IF(T14<>"",T14,X14))) -> 郑士旺 | I14: =IF(COUNT(N14,R14,V14,Z14)=0,"",MIN(N14,R14,V14,Z14)) -> 46202 | J14: =IF(ISNUMBER(K14),K14,IF(COUNT(O14,S14,W14,AA14)=0,"",MAX(O14,S14,W14,AA14))) -> 46224 | K14: 46224 | L14: 郑士旺 | M14: 已完成 | N14: 46202 | O14: 46206 | P14: 石军磊、刘凯 | Q14: 已完成 | R14: 46209 | S14: 46227 | T14: 贺航 | U14: 已完成 | V14: 46209 | W14: 46225 | X14: 袁丽荣 | Y14: 已完成 | Z14: 46216 | AA14: 46234 | AB14: =(IF(M14="已完成",1,IF(M14="进行中",0.5,0))*15%+IF(Q14="已完成",1,IF(Q14="进行中",0.5,0))*35%+IF(U14="已完成",1,IF(U14="进行中",0.5,0))*30%+IF(Y14="已完成",1,IF(Y14="进行中",0.5,0))*20%) -> 1 | AC14: =IF(G14="已完成","正常",IF(OR(G14="暂停",G14="挂起"),"暂停",IF(J14="","日期缺失",IF(J14<_数据接口!$B$7,"已延期",IF(J14<=_数据接口!$B$7+7,"临近到期","正常"))))) -> 正常 | AD14: 69 | AE14: 69
A15: T012 | B15: 网上营业厅 | C15: 交易中心报单信息展示及应单入口 | D15: 应单入口 | E15: / | F15: 第一批次 | G15: =IF(OR(M15="挂起",M15="暂停",Q15="挂起",Q15="暂停",U15="挂起",U15="暂停",Y15="挂起",Y15="暂停"),"暂停","已完成") -> 已完成 | H15: =IF(L15<>"",L15,IF(P15<>"",P15,IF(T15<>"",T15,X15))) -> 郑士旺 | I15: =IF(COUNT(N15,R15,V15,Z15)=0,"",MIN(N15,R15,V15,Z15)) -> 46202 | J15: =IF(ISNUMBER(K15),K15,IF(COUNT(O15,S15,W15,AA15)=0,"",MAX(O15,S15,W15,AA15))) -> 46224 | K15: 46224 | L15: 郑士旺 | M15: 已完成 | N15: 46202 | O15: 46206 | P15: 石军磊、刘凯 | Q15: 已完成 | R15: 46209 | S15: 46227 | T15: 贺航 | U15: 已完成 | V15: 46209 | W15: 46225 | X15: 袁丽荣 | Y15: 已完成 | Z15: 46216 | AA15: 46234 | AB15: =(IF(M15="已完成",1,IF(M15="进行中",0.5,0))*15%+IF(Q15="已完成",1,IF(Q15="进行中",0.5,0))*35%+IF(U15="已完成",1,IF(U15="进行中",0.5,0))*30%+IF(Y15="已完成",1,IF(Y15="进行中",0.5,0))*20%) -> 1 | AC15: =IF(G15="已完成","正常",IF(OR(G15="暂停",G15="挂起"),"暂停",IF(J15="","日期缺失",IF(J15<_数据接口!$B$7,"已延期",IF(J15<=_数据接口!$B$7+7,"临近到期","正常"))))) -> 正常 | AD15: 69 | AE15: 69
A16: T013 | B16: 网上营业厅 | C16: 结算条款管理 | D16: 新增结算条款 | E16: / | F16: 第二批次 | G16: =IF(OR(M16="挂起",M16="暂停",Q16="挂起",Q16="暂停",U16="挂起",U16="暂停",Y16="挂起",Y16="暂停"),"暂停","进行中") -> 进行中 | H16: =IF(L16<>"",L16,IF(P16<>"",P16,IF(T16<>"",T16,X16))) -> 郑士旺 | I16: =IF(COUNT(N16,R16,V16,Z16)=0,"",MIN(N16,R16,V16,Z16)) -> 46223 | J16: =IF(ISNUMBER(K16),K16,IF(COUNT(O16,S16,W16,AA16)=0,"",MAX(O16,S16,W16,AA16))) -> 46318 | L16: 郑士旺 | M16: 已完成 | N16: 46223 | O16: 46227 | P16: 石军磊、刘凯 | Q16: 进行中 | R16: 46272 | S16: 46279 | T16: 贺航 | U16: 进行中 | V16: 46272 | W16: 46279 | X16: 袁丽荣 | Y16: 未开始 | Z16: 46307 | AA16: 46318 | AB16: =(IF(M16="已完成",1,IF(M16="进行中",0.5,0))*15%+IF(Q16="已完成",1,IF(Q16="进行中",0.5,0))*35%+IF(U16="已完成",1,IF(U16="进行中",0.5,0))*30%+IF(Y16="已完成",1,IF(Y16="进行中",0.5,0))*20%) -> 0.475 | AC16: =IF(G16="已完成","正常",IF(OR(G16="暂停",G16="挂起"),"暂停",IF(J16="","日期缺失",IF(J16<_数据接口!$B$7,"已延期",IF(J16<=_数据接口!$B$7+7,"临近到期","正常"))))) -> 正常 | AD16: 69 | AE16: 69
A17: T014 | B17: 网上营业厅 | C17: 结算条款管理 | D17: 结算条款审批 | E17: / | F17: 第二批次 | G17: =IF(OR(M17="挂起",M17="暂停",Q17="挂起",Q17="暂停",U17="挂起",U17="暂停",Y17="挂起",Y17="暂停"),"暂停","进行中") -> 进行中 | H17: =IF(L17<>"",L17,IF(P17<>"",P17,IF(T17<>"",T17,X17))) -> 郑士旺 | I17: =IF(COUNT(N17,R17,V17,Z17)=0,"",MIN(N17,R17,V17,Z17)) -> 46223 | J17: =IF(ISNUMBER(K17),K17,IF(COUNT(O17,S17,W17,AA17)=0,"",MAX(O17,S17,W17,AA17))) -> 46318 | L17: 郑士旺 | M17: 已完成 | N17: 46223 | O17: 46227 | P17: 石军磊、刘凯 | Q17: 进行中 | R17: 46272 | S17: 46279 | T17: 贺航 | U17: 进行中 | V17: 46272 | W17: 46279 | X17: 袁丽荣 | Y17: 未开始 | Z17: 46307 | AA17: 46318 | AB17: =(IF(M17="已完成",1,IF(M17="进行中",0.5,0))*15%+IF(Q17="已完成",1,IF(Q17="进行中",0.5,0))*35%+IF(U17="已完成",1,IF(U17="进行中",0.5,0))*30%+IF(Y17="已完成",1,IF(Y17="进行中",0.5,0))*20%) -> 0.475 | AC17: =IF(G17="已完成","正常",IF(OR(G17="暂停",G17="挂起"),"暂停",IF(J17="","日期缺失",IF(J17<_数据接口!$B$7,"已延期",IF(J17<=_数据接口!$B$7+7,"临近到期","正常"))))) -> 正常 | AD17: 69 | AE17: 69
A18: T015 | B18: 网上营业厅 | C18: 结算条款管理 | D18: 修改结算条款 | E18: / | F18: 第二批次 | G18: =IF(OR(M18="挂起",M18="暂停",Q18="挂起",Q18="暂停",U18="挂起",U18="暂停",Y18="挂起",Y18="暂停"),"暂停","进行中") -> 进行中 | H18: =IF(L18<>"",L18,IF(P18<>"",P18,IF(T18<>"",T18,X18))) -> 郑士旺 | I18: =IF(COUNT(N18,R18,V18,Z18)=0,"",MIN(N18,R18,V18,Z18)) -> 46223 | J18: =IF(ISNUMBER(K18),K18,IF(COUNT(O18,S18,W18,AA18)=0,"",MAX(O18,S18,W18,AA18))) -> 46318 | L18: 郑士旺 | M18: 已完成 | N18: 46223 | O18: 46227 | P18: 石军磊、刘凯 | Q18: 进行中 | R18: 46272 | S18: 46279 | T18: 贺航 | U18: 进行中 | V18: 46272 | W18: 46279 | X18: 袁丽荣 | Y18: 未开始 | Z18: 46307 | AA18: 46318 | AB18: =(IF(M18="已完成",1,IF(M18="进行中",0.5,0))*15%+IF(Q18="已完成",1,IF(Q18="进行中",0.5,0))*35%+IF(U18="已完成",1,IF(U18="进行中",0.5,0))*30%+IF(Y18="已完成",1,IF(Y18="进行中",0.5,0))*20%) -> 0.475 | AC18: =IF(G18="已完成","正常",IF(OR(G18="暂停",G18="挂起"),"暂停",IF(J18="","日期缺失",IF(J18<_数据接口!$B$7,"已延期",IF(J18<=_数据接口!$B$7+7,"临近到期","正常"))))) -> 正常 | AD18: 69 | AE18: 69
A19: T016 | B19: 网上营业厅 | C19: 结算条款管理 | D19: 删除结算条款 | E19: / | F19: 第二批次 | G19: =IF(OR(M19="挂起",M19="暂停",Q19="挂起",Q19="暂停",U19="挂起",U19="暂停",Y19="挂起",Y19="暂停"),"暂停","进行中") -> 进行中 | H19: =IF(L19<>"",L19,IF(P19<>"",P19,IF(T19<>"",T19,X19))) -> 郑士旺 | I19: =IF(COUNT(N19,R19,V19,Z19)=0,"",MIN(N19,R19,V19,Z19)) -> 46223 | J19: =IF(ISNUMBER(K19),K19,IF(COUNT(O19,S19,W19,AA19)=0,"",MAX(O19,S19,W19,AA19))) -> 46318 | L19: 郑士旺 | M19: 已完成 | N19: 46223 | O19: 46227 | P19: 石军磊、刘凯 | Q19: 进行中 | R19: 46272 | S19: 46279 | T19: 贺航 | U19: 进行中 | V19: 46272 | W19: 46279 | X19: 袁丽荣 | Y19: 未开始 | Z19: 46307 | AA19: 46318 | AB19: =(IF(M19="已完成",1,IF(M19="进行中",0.5,0))*15%+IF(Q19="已完成",1,IF(Q19="进行中",0.5,0))*35%+IF(U19="已完成",1,IF(U19="进行中",0.5,0))*30%+IF(Y19="已完成",1,IF(Y19="进行中",0.5,0))*20%) -> 0.475 | AC19: =IF(G19="已完成","正常",IF(OR(G19="暂停",G19="挂起"),"暂停",IF(J19="","日期缺失",IF(J19<_数据接口!$B$7,"已延期",IF(J19<=_数据接口!$B$7+7,"临近到期","正常"))))) -> 正常 | AD19: 69 | AE19: 69
A20: T017 | B20: 网上营业厅 | C20: 结算条款管理 | D20: 查询展示结算条款 | E20: / | F20: 第二批次 | G20: =IF(OR(M20="挂起",M20="暂停",Q20="挂起",Q20="暂停",U20="挂起",U20="暂停",Y20="挂起",Y20="暂停"),"暂停","进行中") -> 进行中 | H20: =IF(L20<>"",L20,IF(P20<>"",P20,IF(T20<>"",T20,X20))) -> 郑士旺 | I20: =IF(COUNT(N20,R20,V20,Z20)=0,"",MIN(N20,R20,V20,Z20)) -> 46223 | J20: =IF(ISNUMBER(K20),K20,IF(COUNT(O20,S20,W20,AA20)=0,"",MAX(O20,S20,W20,AA20))) -> 46318 | L20: 郑士旺 | M20: 已完成 | N20: 46223 | O20: 46227 | P20: 石军磊、刘凯 | Q20: 进行中 | R20: 46272 | S20: 46279 | T20: 贺航 | U20: 进行中 | V20: 46272 | W20: 46279 | X20: 袁丽荣 | Y20: 未开始 | Z20: 46307 | AA20: 46318 | AB20: =(IF(M20="已完成",1,IF(M20="进行中",0.5,0))*15%+IF(Q20="已完成",1,IF(Q20="进行中",0.5,0))*35%+IF(U20="已完成",1,IF(U20="进行中",0.5,0))*30%+IF(Y20="已完成",1,IF(Y20="进行中",0.5,0))*20%) -> 0.475 | AC20: =IF(G20="已完成","正常",IF(OR(G20="暂停",G20="挂起"),"暂停",IF(J20="","日期缺失",IF(J20<_数据接口!$B$7,"已延期",IF(J20<=_数据接口!$B$7+7,"临近到期","正常"))))) -> 正常 | AD20: 69 | AE20: 69
A21: T018 | B21: 网上营业厅 | C21: 结算条款管理 | D21: 结算条款推送法务系统 | E21: / | F21: 第二批次 | G21: =IF(OR(M21="挂起",M21="暂停",Q21="挂起",Q21="暂停",U21="挂起",U21="暂停",Y21="挂起",Y21="暂停"),"暂停","未开始") -> 未开始 | H21: =IF(L21<>"",L21,IF(P21<>"",P21,IF(T21<>"",T21,X21))) -> 郑士旺 | I21: =IF(COUNT(N21,R21,V21,Z21)=0,"",MIN(N21,R21,V21,Z21)) -> 46223 | J21: =IF(ISNUMBER(K21),K21,IF(COUNT(O21,S21,W21,AA21)=0,"",MAX(O21,S21,W21,AA21))) -> 46318 | L21: 郑士旺 | M21: 未开始 | N21: 46223 | O21: 46227 | P21: 石军磊、刘凯 | Q21: 未开始 | R21: 46272 | S21: 46304 | T21: 贺航 | U21: 未开始 | V21: 46272 | W21: 46304 | X21: 袁丽荣 | Y21: 未开始 | Z21: 46307 | AA21: 46318 | AB21: =(IF(M21="已完成",1,IF(M21="进行中",0.5,0))*15%+IF(Q21="已完成",1,IF(Q21="进行中",0.5,0))*35%+IF(U21="已完成",1,IF(U21="进行中",0.5,0))*30%+IF(Y21="已完成",1,IF(Y21="进行中",0.5,0))*20%) -> 0 | AC21: =IF(G21="已完成","正常",IF(OR(G21="暂停",G21="挂起"),"暂停",IF(J21="","日期缺失",IF(J21<_数据接口!$B$7,"已延期",IF(J21<=_数据接口!$B$7+7,"临近到期","正常"))))) -> 正常 | AD21: 69 | AE21: 69
A22: T019 | B22: 网上营业厅 | C22: 卸船作业 | D22: 卸船计划 | E22: 对接卸船计划 | F22: 第二批次 | G22: =IF(OR(M22="挂起",M22="暂停",Q22="挂起",Q22="暂停",U22="挂起",U22="暂停",Y22="挂起",Y22="暂停"),"暂停","进行中") -> 进行中 | H22: =IF(L22<>"",L22,IF(P22<>"",P22,IF(T22<>"",T22,X22))) -> 郑士旺 | I22: =IF(COUNT(N22,R22,V22,Z22)=0,"",MIN(N22,R22,V22,Z22)) -> 46230 | J22: =IF(ISNUMBER(K22),K22,IF(COUNT(O22,S22,W22,AA22)=0,"",MAX(O22,S22,W22,AA22))) -> 46353 | L22: 郑士旺 | M22: 已完成 | N22: 46230 | O22: 46241 | P22: 石军磊、刘凯 | Q22: 未开始 | R22: 46307 | S22: 46339 | T22: 贺航 | U22: 未开始 | V22: 46307 | W22: 46339 | X22: 袁丽荣 | Y22: 未开始 | Z22: 46342 | AA22: 46353 | AB22: =(IF(M22="已完成",1,IF(M22="进行中",0.5,0))*15%+IF(Q22="已完成",1,IF(Q22="进行中",0.5,0))*35%+IF(U22="已完成",1,IF(U22="进行中",0.5,0))*30%+IF(Y22="已完成",1,IF(Y22="进行中",0.5,0))*20%) -> 0.15 | AC22: =IF(G22="已完成","正常",IF(OR(G22="暂停",G22="挂起"),"暂停",IF(J22="","日期缺失",IF(J22<_数据接口!$B$7,"已延期",IF(J22<=_数据接口!$B$7+7,"临近到期","正常"))))) -> 正常 | AD22: 69 | AE22: 69
A23: T020 | B23: 网上营业厅 | C23: 卸船作业 | D23: 卸船计划 | E23: 查询卸车计划 | F23: 第二批次 | G23: =IF(OR(M23="挂起",M23="暂停",Q23="挂起",Q23="暂停",U23="挂起",U23="暂停",Y23="挂起",Y23="暂停"),"暂停","进行中") -> 进行中 | H23: =IF(L23<>"",L23,IF(P23<>"",P23,IF(T23<>"",T23,X23))) -> 郑士旺 | I23: =IF(COUNT(N23,R23,V23,Z23)=0,"",MIN(N23,R23,V23,Z23)) -> 46230 | J23: =IF(ISNUMBER(K23),K23,IF(COUNT(O23,S23,W23,AA23)=0,"",MAX(O23,S23,W23,AA23))) -> 46353 | L23: 郑士旺 | M23: 已完成 | N23: 46230 | O23: 46241 | P23: 石军磊、刘凯 | Q23: 已完成 | R23: 46266 | S23: 46272 | T23: 贺航 | U23: 已完成 | V23: 46266 | W23: 46272 | X23: 袁丽荣 | Y23: 进行中 | Z23: 46342 | AA23: 46353 | AB23: =(IF(M23="已完成",1,IF(M23="进行中",0.5,0))*15%+IF(Q23="已完成",1,IF(Q23="进行中",0.5,0))*35%+IF(U23="已完成",1,IF(U23="进行中",0.5,0))*30%+IF(Y23="已完成",1,IF(Y23="进行中",0.5,0))*20%) -> 0.9 | AC23: =IF(G23="已完成","正常",IF(OR(G23="暂停",G23="挂起"),"暂停",IF(J23="","日期缺失",IF(J23<_数据接口!$B$7,"已延期",IF(J23<=_数据接口!$B$7+7,"临近到期","正常"))))) -> 正常 | AD23: 69 | AE23: 69
A24: T021 | B24: 网上营业厅 | C24: 卸船作业 | D24: 卸船计划 | E24: 外部客户确认 | F24: 第二批次 | G24: =IF(OR(M24="挂起",M24="暂停",Q24="挂起",Q24="暂停",U24="挂起",U24="暂停",Y24="挂起",Y24="暂停"),"暂停","进行中") -> 进行中 | H24: =IF(L24<>"",L24,IF(P24<>"",P24,IF(T24<>"",T24,X24))) -> 郑士旺 | I24: =IF(COUNT(N24,R24,V24,Z24)=0,"",MIN(N24,R24,V24,Z24)) -> 46230 | J24: =IF(ISNUMBER(K24),K24,IF(COUNT(O24,S24,W24,AA24)=0,"",MAX(O24,S24,W24,AA24))) -> 46353 | L24: 郑士旺 | M24: 已完成 | N24: 46230 | O24: 46241 | P24: 石军磊、刘凯 | Q24: 已完成 | R24: 46266 | S24: 46272 | T24: 贺航 | U24: 已完成 | V24: 46266 | W24: 46272 | X24: 袁丽荣 | Y24: 进行中 | Z24: 46342 | AA24: 46353 | AB24: =(IF(M24="已完成",1,IF(M24="进行中",0.5,0))*15%+IF(Q24="已完成",1,IF(Q24="进行中",0.5,0))*35%+IF(U24="已完成",1,IF(U24="进行中",0.5,0))*30%+IF(Y24="已完成",1,IF(Y24="进行中",0.5,0))*20%) -> 0.9 | AC24: =IF(G24="已完成","正常",IF(OR(G24="暂停",G24="挂起"),"暂停",IF(J24="","日期缺失",IF(J24<_数据接口!$B$7,"已延期",IF(J24<=_数据接口!$B$7+7,"临近到期","正常"))))) -> 正常 | AD24: 69 | AE24: 69
A25: T022 | B25: 网上营业厅 | C25: 卸船作业 | D25: 卸船作业信息管理 | E25: 对接卸船作业信息 | F25: 第二批次 | G25: =IF(OR(M25="挂起",M25="暂停",Q25="挂起",Q25="暂停",U25="挂起",U25="暂停",Y25="挂起",Y25="暂停"),"暂停","未开始") -> 未开始 | H25: =IF(L25<>"",L25,IF(P25<>"",P25,IF(T25<>"",T25,X25))) -> 郑士旺 | I25: =IF(COUNT(N25,R25,V25,Z25)=0,"",MIN(N25,R25,V25,Z25)) -> 46230 | J25: =IF(ISNUMBER(K25),K25,IF(COUNT(O25,S25,W25,AA25)=0,"",MAX(O25,S25,W25,AA25))) -> 46353 | L25: 郑士旺 | M25: 未开始 | N25: 46230 | O25: 46241 | P25: 石军磊、刘凯 | Q25: 未开始 | R25: 46307 | S25: 46339 | T25: 贺航 | U25: 未开始 | V25: 46307 | W25: 46339 | X25: 袁丽荣 | Y25: 未开始 | Z25: 46342 | AA25: 46353 | AB25: =(IF(M25="已完成",1,IF(M25="进行中",0.5,0))*15%+IF(Q25="已完成",1,IF(Q25="进行中",0.5,0))*35%+IF(U25="已完成",1,IF(U25="进行中",0.5,0))*30%+IF(Y25="已完成",1,IF(Y25="进行中",0.5,0))*20%) -> 0 | AC25: =IF(G25="已完成","正常",IF(OR(G25="暂停",G25="挂起"),"暂停",IF(J25="","日期缺失",IF(J25<_数据接口!$B$7,"已延期",IF(J25<=_数据接口!$B$7+7,"临近到期","正常"))))) -> 正常 | AD25: 69 | AE25: 69
A26: T023 | B26: 网上营业厅 | C26: 卸船作业 | D26: 卸船作业信息管理 | E26: 查询卸船作业信息 | F26: 第二批次 | G26: =IF(OR(M26="挂起",M26="暂停",Q26="挂起",Q26="暂停",U26="挂起",U26="暂停",Y26="挂起",Y26="暂停"),"暂停","未开始") -> 未开始 | H26: =IF(L26<>"",L26,IF(P26<>"",P26,IF(T26<>"",T26,X26))) -> 郑士旺 | I26: =IF(COUNT(N26,R26,V26,Z26)=0,"",MIN(N26,R26,V26,Z26)) -> 46230 | J26: =IF(ISNUMBER(K26),K26,IF(COUNT(O26,S26,W26,AA26)=0,"",MAX(O26,S26,W26,AA26))) -> 46353 | L26: 郑士旺 | M26: 未开始 | N26: 46230 | O26: 46241 | P26: 石军磊、刘凯 | Q26: 未开始 | R26: 46307 | S26: 46339 | T26: 贺航 | U26: 未开始 | V26: 46307 | W26: 46339 | X26: 袁丽荣 | Y26: 未开始 | Z26: 46342 | AA26: 46353 | AB26: =(IF(M26="已完成",1,IF(M26="进行中",0.5,0))*15%+IF(Q26="已完成",1,IF(Q26="进行中",0.5,0))*35%+IF(U26="已完成",1,IF(U26="进行中",0.5,0))*30%+IF(Y26="已完成",1,IF(Y26="进行中",0.5,0))*20%) -> 0 | AC26: =IF(G26="已完成","正常",IF(OR(G26="暂停",G26="挂起"),"暂停",IF(J26="","日期缺失",IF(J26<_数据接口!$B$7,"已延期",IF(J26<=_数据接口!$B$7+7,"临近到期","正常"))))) -> 正常 | AD26: 69 | AE26: 69
A27: T024 | B27: 网上营业厅 | C27: 卸船作业 | D27: 卸船查询 | E27: 卸船查询列表 | F27: 第二批次 | G27: =IF(OR(M27="挂起",M27="暂停",Q27="挂起",Q27="暂停",U27="挂起",U27="暂停",Y27="挂起",Y27="暂停"),"暂停","未开始") -> 未开始 | H27: =IF(L27<>"",L27,IF(P27<>"",P27,IF(T27<>"",T27,X27))) -> 郑士旺 | I27: =IF(COUNT(N27,R27,V27,Z27)=0,"",MIN(N27,R27,V27,Z27)) -> 46230 | J27: =IF(ISNUMBER(K27),K27,IF(COUNT(O27,S27,W27,AA27)=0,"",MAX(O27,S27,W27,AA27))) -> 46353 | L27: 郑士旺 | M27: 未开始 | N27: 46230 | O27: 46241 | P27: 石军磊、刘凯 | Q27: 未开始 | R27: 46307 | S27: 46339 | T27: 贺航 | U27: 未开始 | V27: 46307 | W27: 46339 | X27: 袁丽荣 | Y27: 未开始 | Z27: 46342 | AA27: 46353 | AB27: =(IF(M27="已完成",1,IF(M27="进行中",0.5,0))*15%+IF(Q27="已完成",1,IF(Q27="进行中",0.5,0))*35%+IF(U27="已完成",1,IF(U27="进行中",0.5,0))*30%+IF(Y27="已完成",1,IF(Y27="进行中",0.5,0))*20%) -> 0 | AC27: =IF(G27="已完成","正常",IF(OR(G27="暂停",G27="挂起"),"暂停",IF(J27="","日期缺失",IF(J27<_数据接口!$B$7,"已延期",IF(J27<=_数据接口!$B$7+7,"临近到期","正常"))))) -> 正常 | AD27: 69 | AE27: 69
A28: T025 | B28: 网上营业厅 | C28: 卸船作业 | D28: 卸船查询 | E28: 卸船查询详情 | F28: 第二批次 | G28: =IF(OR(M28="挂起",M28="暂停",Q28="挂起",Q28="暂停",U28="挂起",U28="暂停",Y28="挂起",Y28="暂停"),"暂停","未开始") -> 未开始 | H28: =IF(L28<>"",L28,IF(P28<>"",P28,IF(T28<>"",T28,X28))) -> 郑士旺 | I28: =IF(COUNT(N28,R28,V28,Z28)=0,"",MIN(N28,R28,V28,Z28)) -> 46230 | J28: =IF(ISNUMBER(K28),K28,IF(COUNT(O28,S28,W28,AA28)=0,"",MAX(O28,S28,W28,AA28))) -> 46261 | K28: 46261 | L28: 郑士旺 | M28: 未开始 | N28: 46230 | O28: 46241 | P28: 石军磊、刘凯 | Q28: 未开始 | R28: 46307 | S28: 46339 | T28: 贺航 | U28: 未开始 | V28: 46307 | W28: 46339 | X28: 袁丽荣 | Y28: 未开始 | Z28: 46342 | AA28: 46353 | AB28: =(IF(M28="已完成",1,IF(M28="进行中",0.5,0))*15%+IF(Q28="已完成",1,IF(Q28="进行中",0.5,0))*35%+IF(U28="已完成",1,IF(U28="进行中",0.5,0))*30%+IF(Y28="已完成",1,IF(Y28="进行中",0.5,0))*20%) -> 0 | AC28: =IF(G28="已完成","正常",IF(OR(G28="暂停",G28="挂起"),"暂停",IF(J28="","日期缺失",IF(J28<_数据接口!$B$7,"已延期",IF(J28<=_数据接口!$B$7+7,"临近到期","正常"))))) -> 已延期 | AD28: 69 | AE28: 69
A29: T026 | B29: 网上营业厅 | C29: 卸船作业 | D29: 卸船作业委托 | E29: 创建卸船作业委托信息 | F29: 第二批次 | G29: =IF(OR(M29="挂起",M29="暂停",Q29="挂起",Q29="暂停",U29="挂起",U29="暂停",Y29="挂起",Y29="暂停"),"暂停","进行中") -> 进行中 | H29: =IF(L29<>"",L29,IF(P29<>"",P29,IF(T29<>"",T29,X29))) -> 郑士旺 | I29: =IF(COUNT(N29,R29,V29,Z29)=0,"",MIN(N29,R29,V29,Z29)) -> 46230 | J29: =IF(ISNUMBER(K29),K29,IF(COUNT(O29,S29,W29,AA29)=0,"",MAX(O29,S29,W29,AA29))) -> 46261 | K29: 46261 | L29: 郑士旺 | M29: 已完成 | N29: 46230 | O29: 46241 | P29: 石军磊、刘凯 | Q29: 已完成 | R29: 46266 | S29: 46272 | T29: 贺航 | U29: 已完成 | V29: 46266 | W29: 46272 | X29: 袁丽荣 | Y29: 进行中 | Z29: 46342 | AA29: 46353 | AB29: =(IF(M29="已完成",1,IF(M29="进行中",0.5,0))*15%+IF(Q29="已完成",1,IF(Q29="进行中",0.5,0))*35%+IF(U29="已完成",1,IF(U29="进行中",0.5,0))*30%+IF(Y29="已完成",1,IF(Y29="进行中",0.5,0))*20%) -> 0.9 | AC29: =IF(G29="已完成","正常",IF(OR(G29="暂停",G29="挂起"),"暂停",IF(J29="","日期缺失",IF(J29<_数据接口!$B$7,"已延期",IF(J29<=_数据接口!$B$7+7,"临近到期","正常"))))) -> 已延期 | AD29: 69 | AE29: 69
A30: T027 | B30: 网上营业厅 | C30: 卸船作业 | D30: 卸船作业委托 | E30: 修改卸船作业委托信息 | F30: 第二批次 | G30: =IF(OR(M30="挂起",M30="暂停",Q30="挂起",Q30="暂停",U30="挂起",U30="暂停",Y30="挂起",Y30="暂停"),"暂停","进行中") -> 进行中 | H30: =IF(L30<>"",L30,IF(P30<>"",P30,IF(T30<>"",T30,X30))) -> 郑士旺 | I30: =IF(COUNT(N30,R30,V30,Z30)=0,"",MIN(N30,R30,V30,Z30)) -> 46230 | J30: =IF(ISNUMBER(K30),K30,IF(COUNT(O30,S30,W30,AA30)=0,"",MAX(O30,S30,W30,AA30))) -> 46261 | K30: 46261 | L30: 郑士旺 | M30: 已完成 | N30: 46230 | O30: 46241 | P30: 石军磊、刘凯 | Q30: 已完成 | R30: 46266 | S30: 46272 | T30: 贺航 | U30: 已完成 | V30: 46266 | W30: 46272 | X30: 袁丽荣 | Y30: 进行中 | Z30: 46342 | AA30: 46353 | AB30: =(IF(M30="已完成",1,IF(M30="进行中",0.5,0))*15%+IF(Q30="已完成",1,IF(Q30="进行中",0.5,0))*35%+IF(U30="已完成",1,IF(U30="进行中",0.5,0))*30%+IF(Y30="已完成",1,IF(Y30="进行中",0.5,0))*20%) -> 0.9 | AC30: =IF(G30="已完成","正常",IF(OR(G30="暂停",G30="挂起"),"暂停",IF(J30="","日期缺失",IF(J30<_数据接口!$B$7,"已延期",IF(J30<=_数据接口!$B$7+7,"临近到期","正常"))))) -> 已延期 | AD30: 69 | AE30: 69
A31: T028 | B31: 网上营业厅 | C31: 卸船作业 | D31: 卸船作业委托 | E31: 作废卸船作业委托信息 | F31: 第二批次 | G31: =IF(OR(M31="挂起",M31="暂停",Q31="挂起",Q31="暂停",U31="挂起",U31="暂停",Y31="挂起",Y31="暂停"),"暂停","进行中") -> 进行中 | H31: =IF(L31<>"",L31,IF(P31<>"",P31,IF(T31<>"",T31,X31))) -> 郑士旺 | I31: =IF(COUNT(N31,R31,V31,Z31)=0,"",MIN(N31,R31,V31,Z31)) -> 46230 | J31: =IF(ISNUMBER(K31),K31,IF(COUNT(O31,S31,W31,AA31)=0,"",MAX(O31,S31,W31,AA31))) -> 46261 | K31: 46261 | L31: 郑士旺 | M31: 进行中 | N31: 46230 | O31: 46241 | P31: 石军磊、刘凯 | Q31: 未开始 | R31: 46307 | S31: 46339 | T31: 贺航 | U31: 未开始 | V31: 46307 | W31: 46339 | X31: 袁丽荣 | Y31: 未开始 | Z31: 46342 | AA31: 46353 | AB31: =(IF(M31="已完成",1,IF(M31="进行中",0.5,0))*15%+IF(Q31="已完成",1,IF(Q31="进行中",0.5,0))*35%+IF(U31="已完成",1,IF(U31="进行中",0.5,0))*30%+IF(Y31="已完成",1,IF(Y31="进行中",0.5,0))*20%) -> 0.075 | AC31: =IF(G31="已完成","正常",IF(OR(G31="暂停",G31="挂起"),"暂停",IF(J31="","日期缺失",IF(J31<_数据接口!$B$7,"已延期",IF(J31<=_数据接口!$B$7+7,"临近到期","正常"))))) -> 已延期 | AD31: 69 | AE31: 69
A32: T029 | B32: 网上营业厅 | C32: 卸船作业 | D32: 卸船作业委托 | E32: 推送卸船作业委托信息 | F32: 第二批次 | G32: =IF(OR(M32="挂起",M32="暂停",Q32="挂起",Q32="暂停",U32="挂起",U32="暂停",Y32="挂起",Y32="暂停"),"暂停","进行中") -> 进行中 | H32: =IF(L32<>"",L32,IF(P32<>"",P32,IF(T32<>"",T32,X32))) -> 郑士旺 | I32: =IF(COUNT(N32,R32,V32,Z32)=0,"",MIN(N32,R32,V32,Z32)) -> 46230 | J32: =IF(ISNUMBER(K32),K32,IF(COUNT(O32,S32,W32,AA32)=0,"",MAX(O32,S32,W32,AA32))) -> 46261 | K32: 46261 | L32: 郑士旺 | M32: 进行中 | N32: 46230 | O32: 46241 | P32: 石军磊、刘凯 | Q32: 未开始 | R32: 46307 | S32: 46339 | T32: 贺航 | U32: 未开始 | V32: 46307 | W32: 46339 | X32: 袁丽荣 | Y32: 未开始 | Z32: 46342 | AA32: 46353 | AB32: =(IF(M32="已完成",1,IF(M32="进行中",0.5,0))*15%+IF(Q32="已完成",1,IF(Q32="进行中",0.5,0))*35%+IF(U32="已完成",1,IF(U32="进行中",0.5,0))*30%+IF(Y32="已完成",1,IF(Y32="进行中",0.5,0))*20%) -> 0.075 | AC32: =IF(G32="已完成","正常",IF(OR(G32="暂停",G32="挂起"),"暂停",IF(J32="","日期缺失",IF(J32<_数据接口!$B$7,"已延期",IF(J32<=_数据接口!$B$7+7,"临近到期","正常"))))) -> 已延期 | AD32: 69 | AE32: 69
A33: T030 | B33: 网上营业厅 | C33: 卸船作业 | D33: 卸船作业委托 | E33: 查询卸船作业委托信息 | F33: 第二批次 | G33: =IF(OR(M33="挂起",M33="暂停",Q33="挂起",Q33="暂停",U33="挂起",U33="暂停",Y33="挂起",Y33="暂停"),"暂停","进行中") -> 进行中 | H33: =IF(L33<>"",L33,IF(P33<>"",P33,IF(T33<>"",T33,X33))) -> 郑士旺 | I33: =IF(COUNT(N33,R33,V33,Z33)=0,"",MIN(N33,R33,V33,Z33)) -> 46230 | J33: =IF(ISNUMBER(K33),K33,IF(COUNT(O33,S33,W33,AA33)=0,"",MAX(O33,S33,W33,AA33))) -> 46261 | K33: 46261 | L33: 郑士旺 | M33: 已完成 | N33: 46230 | O33: 46241 | P33: 石军磊、刘凯 | Q33: 已完成 | R33: 46266 | S33: 46272 | T33: 贺航 | U33: 已完成 | V33: 46266 | W33: 46272 | X33: 袁丽荣 | Y33: 进行中 | Z33: 46342 | AA33: 46353 | AB33: =(IF(M33="已完成",1,IF(M33="进行中",0.5,0))*15%+IF(Q33="已完成",1,IF(Q33="进行中",0.5,0))*35%+IF(U33="已完成",1,IF(U33="进行中",0.5,0))*30%+IF(Y33="已完成",1,IF(Y33="进行中",0.5,0))*20%) -> 0.9 | AC33: =IF(G33="已完成","正常",IF(OR(G33="暂停",G33="挂起"),"暂停",IF(J33="","日期缺失",IF(J33<_数据接口!$B$7,"已延期",IF(J33<=_数据接口!$B$7+7,"临近到期","正常"))))) -> 已延期 | AD33: 69 | AE33: 69
A34: T031 | B34: 网上营业厅 | C34: 卸船作业 | D34: 外轮转内贸业务 | E34: 创建外轮转内贸业务信息 | F34: 第二批次 | G34: =IF(OR(M34="挂起",M34="暂停",Q34="挂起",Q34="暂停",U34="挂起",U34="暂停",Y34="挂起",Y34="暂停"),"暂停","未开始") -> 未开始 | H34: =IF(L34<>"",L34,IF(P34<>"",P34,IF(T34<>"",T34,X34))) -> 郑士旺 | I34: =IF(COUNT(N34,R34,V34,Z34)=0,"",MIN(N34,R34,V34,Z34)) -> 46230 | J34: =IF(ISNUMBER(K34),K34,IF(COUNT(O34,S34,W34,AA34)=0,"",MAX(O34,S34,W34,AA34))) -> 46353 | L34: 郑士旺 | M34: 未开始 | N34: 46230 | O34: 46241 | P34: 常浩 | Q34: 未开始 | R34: 46286 | S34: 46289 | T34: 常浩 | U34: 未开始 | V34: 46286 | W34: 46289 | X34: 袁丽荣 | Y34: 未开始 | Z34: 46342 | AA34: 46353 | AB34: =(IF(M34="已完成",1,IF(M34="进行中",0.5,0))*15%+IF(Q34="已完成",1,IF(Q34="进行中",0.5,0))*35%+IF(U34="已完成",1,IF(U34="进行中",0.5,0))*30%+IF(Y34="已完成",1,IF(Y34="进行中",0.5,0))*20%) -> 0 | AC34: =IF(G34="已完成","正常",IF(OR(G34="暂停",G34="挂起"),"暂停",IF(J34="","日期缺失",IF(J34<_数据接口!$B$7,"已延期",IF(J34<=_数据接口!$B$7+7,"临近到期","正常"))))) -> 正常 | AD34: 69 | AE34: 69
A35: T032 | B35: 网上营业厅 | C35: 卸船作业 | D35: 外轮转内贸业务 | E35: 作废外轮转内贸业务信息 | F35: 第二批次 | G35: =IF(OR(M35="挂起",M35="暂停",Q35="挂起",Q35="暂停",U35="挂起",U35="暂停",Y35="挂起",Y35="暂停"),"暂停","未开始") -> 未开始 | H35: =IF(L35<>"",L35,IF(P35<>"",P35,IF(T35<>"",T35,X35))) -> 郑士旺 | I35: =IF(COUNT(N35,R35,V35,Z35)=0,"",MIN(N35,R35,V35,Z35)) -> 46230 | J35: =IF(ISNUMBER(K35),K35,IF(COUNT(O35,S35,W35,AA35)=0,"",MAX(O35,S35,W35,AA35))) -> 46353 | L35: 郑士旺 | M35: 未开始 | N35: 46230 | O35: 46241 | P35: 常浩 | Q35: 未开始 | R35: 46286 | S35: 46289 | T35: 常浩 | U35: 未开始 | V35: 46286 | W35: 46289 | X35: 袁丽荣 | Y35: 未开始 | Z35: 46342 | AA35: 46353 | AB35: =(IF(M35="已完成",1,IF(M35="进行中",0.5,0))*15%+IF(Q35="已完成",1,IF(Q35="进行中",0.5,0))*35%+IF(U35="已完成",1,IF(U35="进行中",0.5,0))*30%+IF(Y35="已完成",1,IF(Y35="进行中",0.5,0))*20%) -> 0 | AC35: =IF(G35="已完成","正常",IF(OR(G35="暂停",G35="挂起"),"暂停",IF(J35="","日期缺失",IF(J35<_数据接口!$B$7,"已延期",IF(J35<=_数据接口!$B$7+7,"临近到期","正常"))))) -> 正常 | AD35: 69 | AE35: 69
A36: T033 | B36: 网上营业厅 | C36: 卸船作业 | D36: 外轮转内贸业务 | E36: 查询外轮转内贸业务信息 | F36: 第二批次 | G36: =IF(OR(M36="挂起",M36="暂停",Q36="挂起",Q36="暂停",U36="挂起",U36="暂停",Y36="挂起",Y36="暂停"),"暂停","未开始") -> 未开始 | H36: =IF(L36<>"",L36,IF(P36<>"",P36,IF(T36<>"",T36,X36))) -> 郑士旺 | I36: =IF(COUNT(N36,R36,V36,Z36)=0,"",MIN(N36,R36,V36,Z36)) -> 46230 | J36: =IF(ISNUMBER(K36),K36,IF(COUNT(O36,S36,W36,AA36)=0,"",MAX(O36,S36,W36,AA36))) -> 46353 | L36: 郑士旺 | M36: 未开始 | N36: 46230 | O36: 46241 | P36: 常浩 | Q36: 未开始 | R36: 46286 | S36: 46289 | T36: 常浩 | U36: 未开始 | V36: 46286 | W36: 46289 | X36: 袁丽荣 | Y36: 未开始 | Z36: 46342 | AA36: 46353 | AB36: =(IF(M36="已完成",1,IF(M36="进行中",0.5,0))*15%+IF(Q36="已完成",1,IF(Q36="进行中",0.5,0))*35%+IF(U36="已完成",1,IF(U36="进行中",0.5,0))*30%+IF(Y36="已完成",1,IF(Y36="进行中",0.5,0))*20%) -> 0 | AC36: =IF(G36="已完成","正常",IF(OR(G36="暂停",G36="挂起"),"暂停",IF(J36="","日期缺失",IF(J36<_数据接口!$B$7,"已延期",IF(J36<=_数据接口!$B$7+7,"临近到期","正常"))))) -> 正常 | AD36: 69 | AE36: 69
A37: T034 | B37: 网上营业厅 | C37: 卸船作业 | D37: 船舶靠泊通知单 | E37: 新增船舶靠泊通知单 | F37: 第二批次 | G37: =IF(OR(M37="挂起",M37="暂停",Q37="挂起",Q37="暂停",U37="挂起",U37="暂停",Y37="挂起",Y37="暂停"),"暂停","进行中") -> 进行中 | H37: =IF(L37<>"",L37,IF(P37<>"",P37,IF(T37<>"",T37,X37))) -> 郑士旺 | I37: =IF(COUNT(N37,R37,V37,Z37)=0,"",MIN(N37,R37,V37,Z37)) -> 46230 | J37: =IF(ISNUMBER(K37),K37,IF(COUNT(O37,S37,W37,AA37)=0,"",MAX(O37,S37,W37,AA37))) -> 46353 | L37: 郑士旺 | M37: 已完成 | N37: 46230 | O37: 46241 | P37: 石军磊、刘凯 | Q37: 已完成 | R37: 46266 | S37: 46272 | T37: 贺航 | U37: 已完成 | V37: 46266 | W37: 46272 | X37: 袁丽荣 | Y37: 进行中 | Z37: 46342 | AA37: 46353 | AB37: =(IF(M37="已完成",1,IF(M37="进行中",0.5,0))*15%+IF(Q37="已完成",1,IF(Q37="进行中",0.5,0))*35%+IF(U37="已完成",1,IF(U37="进行中",0.5,0))*30%+IF(Y37="已完成",1,IF(Y37="进行中",0.5,0))*20%) -> 0.9 | AC37: =IF(G37="已完成","正常",IF(OR(G37="暂停",G37="挂起"),"暂停",IF(J37="","日期缺失",IF(J37<_数据接口!$B$7,"已延期",IF(J37<=_数据接口!$B$7+7,"临近到期","正常"))))) -> 正常 | AD37: 69 | AE37: 69
A38: T035 | B38: 网上营业厅 | C38: 卸船作业 | D38: 船舶靠泊通知单 | E38: 审批船舶靠泊通知单 | F38: 第二批次 | G38: =IF(OR(M38="挂起",M38="暂停",Q38="挂起",Q38="暂停",U38="挂起",U38="暂停",Y38="挂起",Y38="暂停"),"暂停","进行中") -> 进行中 | H38: =IF(L38<>"",L38,IF(P38<>"",P38,IF(T38<>"",T38,X38))) -> 郑士旺 | I38: =IF(COUNT(N38,R38,V38,Z38)=0,"",MIN(N38,R38,V38,Z38)) -> 46230 | J38: =IF(ISNUMBER(K38),K38,IF(COUNT(O38,S38,W38,AA38)=0,"",MAX(O38,S38,W38,AA38))) -> 46353 | L38: 郑士旺 | M38: 已完成 | N38: 46230 | O38: 46241 | P38: 石军磊、刘凯 | Q38: 已完成 | R38: 46266 | S38: 46272 | T38: 贺航 | U38: 已完成 | V38: 46266 | W38: 46272 | X38: 袁丽荣 | Y38: 进行中 | Z38: 46342 | AA38: 46353 | AB38: =(IF(M38="已完成",1,IF(M38="进行中",0.5,0))*15%+IF(Q38="已完成",1,IF(Q38="进行中",0.5,0))*35%+IF(U38="已完成",1,IF(U38="进行中",0.5,0))*30%+IF(Y38="已完成",1,IF(Y38="进行中",0.5,0))*20%) -> 0.9 | AC38: =IF(G38="已完成","正常",IF(OR(G38="暂停",G38="挂起"),"暂停",IF(J38="","日期缺失",IF(J38<_数据接口!$B$7,"已延期",IF(J38<=_数据接口!$B$7+7,"临近到期","正常"))))) -> 正常 | AD38: 69 | AE38: 69
A39: T036 | B39: 网上营业厅 | C39: 卸船作业 | D39: 船舶靠泊通知单 | E39: 查询船舶靠泊通知单 | F39: 第二批次 | G39: =IF(OR(M39="挂起",M39="暂停",Q39="挂起",Q39="暂停",U39="挂起",U39="暂停",Y39="挂起",Y39="暂停"),"暂停","进行中") -> 进行中 | H39: =IF(L39<>"",L39,IF(P39<>"",P39,IF(T39<>"",T39,X39))) -> 郑士旺 | I39: =IF(COUNT(N39,R39,V39,Z39)=0,"",MIN(N39,R39,V39,Z39)) -> 46230 | J39: =IF(ISNUMBER(K39),K39,IF(COUNT(O39,S39,W39,AA39)=0,"",MAX(O39,S39,W39,AA39))) -> 46353 | L39: 郑士旺 | M39: 已完成 | N39: 46230 | O39: 46241 | P39: 石军磊、刘凯 | Q39: 已完成 | R39: 46266 | S39: 46272 | T39: 贺航 | U39: 已完成 | V39: 46266 | W39: 46272 | X39: 袁丽荣 | Y39: 进行中 | Z39: 46342 | AA39: 46353 | AB39: =(IF(M39="已完成",1,IF(M39="进行中",0.5,0))*15%+IF(Q39="已完成",1,IF(Q39="进行中",0.5,0))*35%+IF(U39="已完成",1,IF(U39="进行中",0.5,0))*30%+IF(Y39="已完成",1,IF(Y39="进行中",0.5,0))*20%) -> 0.9 | AC39: =IF(G39="已完成","正常",IF(OR(G39="暂停",G39="挂起"),"暂停",IF(J39="","日期缺失",IF(J39<_数据接口!$B$7,"已延期",IF(J39<=_数据接口!$B$7+7,"临近到期","正常"))))) -> 正常 | AD39: 69 | AE39: 69
A40: T037 | B40: 网上营业厅 | C40: 卸车流程跟踪 | D40: 创建卸车流程 | E40: / | F40: 第一批次 | G40: =IF(OR(M40="挂起",M40="暂停",Q40="挂起",Q40="暂停",U40="挂起",U40="暂停",Y40="挂起",Y40="暂停"),"暂停","已完成") -> 已完成 | H40: =IF(L40<>"",L40,IF(P40<>"",P40,IF(T40<>"",T40,X40))) -> 郑士旺 | I40: =IF(COUNT(N40,R40,V40,Z40)=0,"",MIN(N40,R40,V40,Z40)) -> 46209 | J40: =IF(ISNUMBER(K40),K40,IF(COUNT(O40,S40,W40,AA40)=0,"",MAX(O40,S40,W40,AA40))) -> 46261 | K40: 46261 | L40: 郑士旺 | M40: 已完成 | N40: 46209 | O40: 46213 | P40: 石军磊、刘凯 | Q40: 已完成 | R40: 46230 | S40: 46262 | T40: 贺航 | U40: 已完成 | V40: 46230 | W40: 46262 | X40: 袁丽荣 | Y40: 已完成 | Z40: 46253 | AA40: 46269 | AB40: =(IF(M40="已完成",1,IF(M40="进行中",0.5,0))*15%+IF(Q40="已完成",1,IF(Q40="进行中",0.5,0))*35%+IF(U40="已完成",1,IF(U40="进行中",0.5,0))*30%+IF(Y40="已完成",1,IF(Y40="进行中",0.5,0))*20%) -> 1 | AC40: =IF(G40="已完成","正常",IF(OR(G40="暂停",G40="挂起"),"暂停",IF(J40="","日期缺失",IF(J40<_数据接口!$B$7,"已延期",IF(J40<=_数据接口!$B$7+7,"临近到期","正常"))))) -> 正常 | AD40: 69 | AE40: 69
...

Sheet 资源计划
A1: 资源计划
A2: 汇总业务、后端、前端和测试任务分配。黄色区域用于填写可用工时、任务投入工时和资源调整说明。
A4: 人员 | B4: 角色 | C4: 任务数 | D4: 未完成任务 | E4: 最早开始 | F4: 最晚结束 | G4: 周可用工时 | H4: 计划投入工时 | I4: 负荷率 | J4: 负荷判断 | K4: 资源建议 | L4: 备注
A5: 刘凯 | B5: 后端 | C5: 125 | D5: 125 | E5: 46195 | F5: 46339 | G5: 40 | H5: 840 | I5: 1 | J5: 高负荷 | K5: 确认优先级并预留缓冲
A6: 常浩 | B6: 全栈、后端 | C6: 14 | D6: 14 | E6: 46212 | F6: 46339 | G6: 40 | H6: 720 | I6: 0.94736842 | J6: 高负荷 | K6: 确认优先级并预留缓冲
A7: 石军磊 | B7: 后端 | C7: 125 | D7: 125 | E7: 46195 | F7: 46339 | G7: 40 | H7: 840 | I7: 1 | J7: 高负荷 | K7: 确认优先级并预留缓冲
A8: 袁丽荣 | B8: 测试 | C8: 139 | D8: 139 | E8: 46202 | F8: 46353 | G8: 40 | H8: 520 | I8: 0.59090909 | J8: 正常 | K8: 按计划跟踪
A9: 贺航 | B9: 前端 | C9: 129 | D9: 129 | E9: 46195 | F9: 46339 | G9: 40 | H9: 840 | I9: 1 | J9: 高负荷 | K9: 确认优先级并预留缓冲
A10: 郑士旺 | B10: 业务 | C10: 139 | D10: 139 | E10: 46202 | F10: 46241 | G10: 40 | H10: 240 | I10: 1 | J10: 高负荷 | K10: 确认优先级并预留缓冲
A13: 资源周计划
A14: 任务名称、状态和日期直接引用总控台账；新增任务或调整责任人后，重新执行V2更新以扩展明细行。
A15: 人员 | B15: 周开始 | C15: 周结束 | D15: 是否有任务 | E15: 任务数 | F15: 周计划工时 | G15: 负荷率 | H15: 负荷判断 | I15: 任务清单
A16: 刘凯 | B16: 46195 | C16: 46201 | D16: 有 | E16: 4 | F16: 40 | G16: 1 | H16: 高负荷 | I16: T058 OCR识别及编辑；T069 新增、详情、修改页内容调整；T070 生成报告；T071 装船作业信息录入优化（太仓） | L16: 刘凯
B17: 46202 | C17: 46208 | D17: 有 | E17: 4 | F17: 40 | G17: 1 | H17: 高负荷 | I17: T058 OCR识别及编辑；T069 新增、详情、修改页内容调整；T070 生成报告；T071 装船作业信息录入优化（太仓） | L17: 刘凯
B18: 46209 | C18: 46215 | D18: 有 | E18: 22 | F18: 40 | G18: 1 | H18: 高负荷 | I18: T001 新增车辆信息；T002 修改车辆信息；T003 删除车辆信息；T004 查询展示车辆信息；T006 优化收费标准（装卸费）新增；T007 优化收费标准（装卸费）编辑；T008 优化收费标准（装卸费）详情；T009 优化采样方式新增；T010 优化采样方式编辑；T011 获取报单数据及展示；T012 应单入口；T060 货权录入；T061 货权修改；T062 获取查询；T063 卸船作业货权跟踪；T064 卸船作业货权跟踪；T065 装船作业货权跟踪；T066 装船作业货权跟踪；T067 装船作业货权跟踪；T068 装船作业货权跟踪；T072 OCR识别；T096 自动生成装船港杂费 | L18: 刘凯
B19: 46216 | C19: 46222 | D19: 有 | E19: 22 | F19: 40 | G19: 1 | H19: 高负荷 | I19: T001 新增车辆信息；T002 修改车辆信息；T003 删除车辆信息；T004 查询展示车辆信息；T006 优化收费标准（装卸费）新增；T007 优化收费标准（装卸费）编辑；T008 优化收费标准（装卸费）详情；T009 优化采样方式新增；T010 优化采样方式编辑；T011 获取报单数据及展示；T012 应单入口；T060 货权录入；T061 货权修改；T062 获取查询；T063 卸船作业货权跟踪；T064 卸船作业货权跟踪；T065 装船作业货权跟踪；T066 装船作业货权跟踪；T067 装船作业货权跟踪；T068 装船作业货权跟踪；T072 OCR识别；T096 自动生成装船港杂费 | L19: 刘凯
B20: 46223 | C20: 46229 | D20: 有 | E20: 30 | F20: 40 | G20: 1 | H20: 高负荷 | I20: T001 新增车辆信息；T002 修改车辆信息；T003 删除车辆信息；T004 查询展示车辆信息；T006 优化收费标准（装卸费）新增；T007 优化收费标准（装卸费）编辑；T008 优化收费标准（装卸费）详情；T009 优化采样方式新增；T010 优化采样方式编辑；T011 获取报单数据及展示；T012 应单入口；T060 货权录入；T061 货权修改；T062 获取查询；T063 卸船作业货权跟踪；T064 卸船作业货权跟踪；T065 装船作业货权跟踪；T066 装船作业货权跟踪；T067 装船作业货权跟踪；T068 装船作业货权跟踪；T072 OCR识别；T096 自动生成装船港杂费；T073 采样作业信息录入新增；T074 采样作业信息录入编辑；T075 采样作业信息录入详情；T076 采样作业信息录入删除；T077 采样作业信息录入列表；T097 自动生成租赁费；T098 优化装卸费新增；T099 优化装卸费编辑 | L20: 刘凯
B21: 46230 | C21: 46236 | D21: 有 | E21: 28 | F21: 40 | G21: 1 | H21: 高负荷 | I21: T037 创建卸车流程；T038 查询卸车流程；T039 修改卸车流程；T040 创建装船流程；T041 查询装船流程；T042 修改装船流程；T043 创建卸船流程；T044 查询卸船流程；T045 修改卸船流程；T059 优化新增装车作业信息；T100 创建行业资讯数据；T101 修改行业资讯数据；T102 删除行业资讯数据；T103 展示行业资讯数据；T104 吞吐量统计（曹妃甸）；T105 泊位占用率分析（曹妃甸）；T106 堆存库存统计（曹妃甸）；T107 分货主实时统计表（曹妃甸）；T108 综合装船效率分析（曹妃甸）；T109 综合卸车效率分析（曹妃甸）；T110 综合卸船效率分析（曹妃甸）；T117 经营任务情况分析报告；T118 客户月报报告；T119 月度客户情况报告；T120 商务计划周报；T138 查询卸车流程；T139 查询装船流程；T140 查询卸船流程 | L21: 刘凯
B22: 46237 | C22: 46243 | D22: 有 | E22: 31 | F22: 40 | G22: 1 | H22: 高负荷 | I22: T037 创建卸车流程；T038 查询卸车流程；T039 修改卸车流程；T040 创建装船流程；T041 查询装船流程；T042 修改装船流程；T043 创建卸船流程；T044 查询卸船流程；T045 修改卸船流程；T059 优化新增装车作业信息；T100 创建行业资讯数据；T101 修改行业资讯数据；T102 删除行业资讯数据；T103 展示行业资讯数据；T104 吞吐量统计（曹妃甸）；T105 泊位占用率分析（曹妃甸）；T106 堆存库存统计（曹妃甸）；T107 分货主实时统计表（曹妃甸）；T108 综合装船效率分析（曹妃甸）；T109 综合卸车效率分析（曹妃甸）；T110 综合卸船效率分析（曹妃甸）；T117 经营任务情况分析报告；T118 客户月报报告；T119 月度客户情况报告；T120 商务计划周报；T138 查询卸车流程；T139 查询装船流程；T140 查询卸船流程；T143 图片上传；T144 图片上传；T145 图片上传 | L22: 刘凯
B23: 46244 | C23: 46250 | D23: 有 | E23: 30 | F23: 40 | G23: 1 | H23: 高负荷 | I23: T037 创建卸车流程；T038 查询卸车流程；T039 修改卸车流程；T040 创建装船流程；T041 查询装船流程；T042 修改装船流程；T043 创建卸船流程；T044 查询卸船流程；T045 修改卸船流程；T100 创建行业资讯数据；T101 修改行业资讯数据；T102 删除行业资讯数据；T103 展示行业资讯数据；T104 吞吐量统计（曹妃甸）；T105 泊位占用率分析（曹妃甸）；T106 堆存库存统计（曹妃甸）；T107 分货主实时统计表（曹妃甸）；T108 综合装船效率分析（曹妃甸）；T109 综合卸车效率分析（曹妃甸）；T110 综合卸船效率分析（曹妃甸）；T117 经营任务情况分析报告；T118 客户月报报告；T119 月度客户情况报告；T120 商务计划周报；T138 查询卸车流程；T139 查询装船流程；T140 查询卸船流程；T143 图片上传；T144 图片上传；T145 图片上传 | L23: 刘凯
B24: 46251 | C24: 46257 | D24: 有 | E24: 30 | F24: 40 | G24: 1 | H24: 高负荷 | I24: T037 创建卸车流程；T038 查询卸车流程；T039 修改卸车流程；T040 创建装船流程；T041 查询装船流程；T042 修改装船流程；T043 创建卸船流程；T044 查询卸船流程；T045 修改卸船流程；T100 创建行业资讯数据；T101 修改行业资讯数据；T102 删除行业资讯数据；T103 展示行业资讯数据；T104 吞吐量统计（曹妃甸）；T105 泊位占用率分析（曹妃甸）；T106 堆存库存统计（曹妃甸）；T107 分货主实时统计表（曹妃甸）；T108 综合装船效率分析（曹妃甸）；T109 综合卸车效率分析（曹妃甸）；T110 综合卸船效率分析（曹妃甸）；T117 经营任务情况分析报告；T118 客户月报报告；T119 月度客户情况报告；T120 商务计划周报；T138 查询卸车流程；T139 查询装船流程；T140 查询卸船流程；T143 图片上传；T144 图片上传；T145 图片上传 | L24: 刘凯
B25: 46258 | C25: 46264 | D25: 有 | E25: 27 | F25: 40 | G25: 1 | H25: 高负荷 | I25: T037 创建卸车流程；T038 查询卸车流程；T039 修改卸车流程；T040 创建装船流程；T041 查询装船流程；T042 修改装船流程；T043 创建卸船流程；T044 查询卸船流程；T045 修改卸船流程；T100 创建行业资讯数据；T101 修改行业资讯数据；T102 删除行业资讯数据；T103 展示行业资讯数据；T104 吞吐量统计（曹妃甸）；T105 泊位占用率分析（曹妃甸）；T106 堆存库存统计（曹妃甸）；T107 分货主实时统计表（曹妃甸）；T108 综合装船效率分析（曹妃甸）；T109 综合卸车效率分析（曹妃甸）；T110 综合卸船效率分析（曹妃甸）；T117 经营任务情况分析报告；T118 客户月报报告；T119 月度客户情况报告；T120 商务计划周报；T138 查询卸车流程；T139 查询装船流程；T140 查询卸船流程 | L25: 刘凯
B26: 46265 | C26: 46271 | D26: 有 | E26: 13 | F26: 40 | G26: 1 | H26: 高负荷 | I26: T121 船舶供应服务查询；T122 船舶预到（内贸）查询；T123 台账查询；T124 停泊费（内贸）查询；T125 船舶供应服务费（内贸）查询；T020 查询卸车计划；T021 外部客户确认；T026 创建卸船作业委托信息；T027 修改卸船作业委托信息；T030 查询卸船作业委托信息；T034 新增船舶靠泊通知单；T035 审批船舶靠泊通知单；T036 查询船舶靠泊通知单 | L26: 刘凯
B27: 46272 | C27: 46278 | D27: 有 | E27: 23 | F27: 40 | G27: 1 | H27: 高负荷 | I27: T020 查询卸车计划；T021 外部客户确认；T026 创建卸船作业委托信息；T027 修改卸船作业委托信息；T030 查询卸船作业委托信息；T034 新增船舶靠泊通知单；T035 审批船舶靠泊通知单；T036 查询船舶靠泊通知单；T013 新增结算条款；T014 结算条款审批；T015 修改结算条款；T016 删除结算条款；T017 查询展示结算条款；T018 结算条款推送法务系统；T053 接入港口侧视频监控；T054 视频查看权限申请；T055 视频查看权限审批；T056 视频查看权限有效期控制；T057 外网PC端视频监控查询；T078 业务数据合同签订校验；T079 结算数据合同签订校验；T080 合同校验结果查询；T141 视频监控查询 | L27: 刘凯
B28: 46279 | C28: 46285 | D28: 有 | E28: 15 | F28: 40 | G28: 1 | H28: 高负荷 | I28: T013 新增结算条款；T014 结算条款审批；T015 修改结算条款；T016 删除结算条款；T017 查询展示结算条款；T018 结算条款推送法务系统；T053 接入港口侧视频监控；T054 视频查看权限申请；T055 视频查看权限审批；T056 视频查看权限有效期控制；T057 外网PC端视频监控查询；T078 业务数据合同签订校验；T079 结算数据合同签订校验；T080 合同校验结果查询；T141 视频监控查询 | L28: 刘凯
... B36: 46335 | C36: 46341 | D36: 有 | E36: 32 | F36: 40 | G36: 1 | H36: 高负荷 | I36: T005 船舶唯一性校验；T019 对接卸船计划；T022 对接卸船作业信息；T023 查询卸船作业信息；T024 卸船查询列表；T025 卸船查询详情；T028 作废卸船作业委托信息；T029 推送卸船作业委托信息；T046 新增船舶预到（外贸）；T047 退回船舶预到（外贸）；T048 退回船舶预到（外贸）；T049 申请采样申请（外贸）；T081 数据对接；T082 数据展示；T083 数据对接；T084 数据产生；T089 新增采样服务费（外贸）；T090 审批采样服务费（外贸）；T091 单据签章；T092 数据推送；T093 数据对接；T094 数据展示；T126 停泊费（外贸）查询；T127 锚泊费（外贸）查询；T130 采样服务费（外贸）查询；T131 船舶供应服务费（外贸）查询；T132 新增船舶靠泊通知单；T133 查询船舶靠泊通知单；T134 卸船计划查询；T135 卸船查询；T136 卸船作业委托；T142 审批船舶靠泊通知单 | L36: 刘凯
B37: 46342 | C37: 46348 | D37: 无 | E37: 0 | F37: 0 | G37: 0 | H37: 无任务 | L37: 刘凯
B38: 46349 | C38: 46355 | D38: 无 | E38: 0 | F38: 0 | G38: 0 | H38: 无任务 | L38: 刘凯
A39: 常浩 | B39: 46195 | C39: 46201 | D39: 无 | E39: 0 | F39: 0 | G39: 0 | H39: 无任务 | L39: 常浩
B40: 46202 | C40: 46208 | D40: 无 | E40: 0 | F40: 0 | G40: 0 | H40: 无任务 | L40: 常浩
B41: 46209 | C41: 46215 | D41: 有 | E41: 3 | F41: 40 | G41: 1 | H41: 高负荷 | I41: T050 维护需跟踪船舶清单；T051 根据船舶清单更新第三方系统推送数据船舶清单；T052 船舶轨迹跟踪 | L41: 常浩
B42: 46216 | C42: 46222 | D42: 有 | E42: 3 | F42: 40 | G42: 1 | H42: 高负荷 | I42: T050 维护需跟踪船舶清单；T051 根据船舶清单更新第三方系统推送数据船舶清单；T052 船舶轨迹跟踪 | L42: 常浩
B43: 46223 | C43: 46229 | D43: 有 | E43: 3 | F43: 40 | G43: 1 | H43: 高负荷 | I43: T050 维护需跟踪船舶清单；T051 根据船舶清单更新第三方系统推送数据船舶清单；T052 船舶轨迹跟踪 | L43: 常浩
B44: 46230 | C44: 46236 | D44: 有 | E44: 3 | F44: 40 | G44: 1 | H44: 高负荷 | I44: T050 维护需跟踪船舶清单；T051 根据船舶清单更新第三方系统推送数据船舶清单；T052 船舶轨迹跟踪 | L44: 常浩
B45: 46237 | C45: 46243 | D45: 有 | E45: 3 | F45: 40 | G45: 1 | H45: 高负荷 | I45: T050 维护需跟踪船舶清单；T051 根据船舶清单更新第三方系统推送数据船舶清单；T052 船舶轨迹跟踪 | L45: 常浩
B46: 46244 | C46: 46250 | D46: 有 | E46: 3 | F46: 40 | G46: 1 | H46: 高负荷 | I46: T050 维护需跟踪船舶清单；T051 根据船舶清单更新第三方系统推送数据船舶清单；T052 船舶轨迹跟踪 | L46: 常浩
B47: 46251 | C47: 46257 | D47: 有 | E47: 3 | F47: 40 | G47: 1 | H47: 高负荷 | I47: T050 维护需跟踪船舶清单；T051 根据船舶清单更新第三方系统推送数据船舶清单；T052 船舶轨迹跟踪 | L47: 常浩
B48: 46258 | C48: 46264 | D48: 有 | E48: 3 | F48: 40 | G48: 1 | H48: 高负荷 | I48: T050 维护需跟踪船舶清单；T051 根据船舶清单更新第三方系统推送数据船舶清单；T052 船舶轨迹跟踪 | L48: 常浩
B49: 46265 | C49: 46271 | D49: 有 | E49: 4 | F49: 40 | G49: 1 | H49: 高负荷 | I49: T095 自动生成堆存费；T050 维护需跟踪船舶清单；T051 根据船舶清单更新第三方系统推送数据船舶清单；T052 船舶轨迹跟踪 | L49: 常浩
B50: 46272 | C50: 46278 | D50: 有 | E50: 1 | F50: 40 | G50: 1 | H50: 高负荷 | I50: T095 自动生成堆存费 | L50: 常浩
...

Sheet 周迭代计划
A1: 周迭代计划与完成跟踪
A2: 上方汇总承诺完成、延期和暂停；下方按总控任务四阶段展开。周目标和复盘人工填写，其余内容更新V2时重建。
A4: 迭代周 | B4: 开始日期 | C4: 结束日期 | D4: 周目标 | E4: 原周计划摘要 | F4: 计划完成阶段数 | G4: 实际完成阶段数 | H4: 承诺完成率 | I4: 延期数 | J4: 暂停数 | K4: 周状态 | L4: 复盘结论 | O4: _key
A5: 1 | B5: 46195 | C5: 46199 | E5: 功能设计：装船计划编制及推送、卸船作业信息录入优化（太仓）、装船作业信息录入优化（太仓） 前端：装船计划编制及推送、卸船作业信息录入优化（太仓）、装船作业信息录入优化（太仓） 后端：装船计划编制及推送、卸船作业信息录入优化（太仓）、装船作业信息录入优化（太仓） | F5: 0 | G5: 0 | H5: 无计划任务 | I5: 0 | J5: 0 | K5: 已结束 | O5: W001
A6: 2 | B6: 46202 | C6: 46206 | D6: 完成42个计划阶段 | E6: 功能设计：车辆信息维护、交易中心报单信息展示及应单入口、船舶轨迹跟踪、货权跟踪、货权提醒、船舶预到优化（太仓）、堆存费优化（太仓）、港杂费优化(太仓）、收费标准信息维护、采样方式信息维护、装卸费结算、租赁费结算、采样作业信息录入 测试：装船计划编制及推送、卸船作业信息录入优化（太仓）、装船作业信息录入优化（太仓） | F6: 42 | G6: 42 | H6: 1 | I6: 0 | J6: 0 | K6: 已结束 | L6: 人工复盘保留验证 | O6: W002
A7: 3 | B7: 46209 | C7: 46213 | E7: 功能设计：卸车流程跟踪、装船流程跟踪、卸船流程跟踪、行业资讯、统计分析 前端：车辆信息维护、交易中心报单信息展示及应单入口、船舶轨迹跟踪、货权跟踪、货权提醒、船舶预到优化（太仓）、堆存费优化（太仓）、港杂费优化(太仓）、收费标准信息维护、采样方式信息维护、装卸费结算、租赁费结算、采样作业信息录入 后端：车辆信息维护、交易中心报单信息展示及应单入口、船舶轨迹跟踪、货权跟踪、货权提醒、船舶预到优化（太仓）、堆存费优化（太仓）、港杂费优化(太仓）、收费标准信息维护、采样方式信息维护、装卸费结算、租赁费结算、采样作业信息录入 | F7: 29 | G7: 29 | H7: 1 | I7: 0 | J7: 0 | K7: 已结束 | O7: W003
A8: 4 | B8: 46216 | C8: 46220 | E8: 功能设计：APP：船舶供应服务查询、船舶预到（内贸）查询、台账查询、停泊费（内贸）查询、船舶供应服务费（内贸）查询 测试：车辆信息维护、交易中心报单信息展示及应单入口、船舶轨迹跟踪、货权跟踪、货权提醒、船舶预到优化（太仓）、堆存费优化（太仓）、港杂费优化（太仓）、收费标准信息维护、采样方式信息维护、装卸费结算、租赁费结算、采样作业信息录入 | F8: 5 | G8: 5 | H8: 1 | I8: 0 | J8: 0 | K8: 已结束 | O8: W004
A9: 5 | B9: 46223 | C9: 46227 | E9: 功能设计：结算条款管理、协同视览、费用合同签订校验 | F9: 75 | G9: 68 | H9: 0.90666667 | I9: 7 | J9: 0 | K9: 已结束 | O9: W005
A10: 6 | B10: 46230 | C10: 46234 | E10: 功能设计：船舶唯一性校验、卸船作业、船舶预到（外贸）、退回船舶预到（外贸）、采样申请（外贸）、停泊费（外贸）、锚泊费（外贸）、堆存费（外贸）、卸船费（外贸）、采样服务费（外贸）、船舶供应服务费（外贸） 前端：卸车流程跟踪、装船流程跟踪、卸船流程跟踪、行业资讯、统计分析、自动报告 后端：卸车流程跟踪、装船流程跟踪、卸船流程跟踪、行业资讯、统计分析、自动报告 | F10: 35 | G10: 31 | H10: 0.88571429 | I10: 4 | J10: 0 | K10: 已结束 | O10: W006
A11: 7 | B11: 46237 | C11: 46241 | F11: 53 | G11: 15 | H11: 0.28301887 | I11: 38 | J11: 0 | K11: 已结束 | O11: W007
A12: 8 | B12: 46244 | C12: 46248 | F12: 0 | G12: 0 | H12: 无计划任务 | I12: 0 | J12: 0 | K12: 已结束 | O12: W008
A13: 9 | B13: 46251 | C13: 46255 | E13: 测试：卸车流程跟踪、装船流程跟踪、卸船流程跟踪、行业资讯、统计分析、自动报告 | F13: 6 | G13: 6 | H13: 1 | I13: 0 | J13: 0 | K13: 已结束 | O13: W009
A14: 10 | B14: 46258 | C14: 46262 | F14: 54 | G14: 54 | H14: 1 | I14: 0 | J14: 0 | K14: 已结束 | O14: W010
A15: 11 | B15: 46265 | C15: 46269 | E15: 前端：APP：船舶供应服务查询、船舶预到（内贸）查询、台账查询、停泊费（内贸）查询、船舶供应服务费（内贸）查询 后端：APP：船舶供应服务查询、船舶预到（内贸）查询、台账查询、停泊费（内贸）查询、船舶供应服务费（内贸）查询 | F15: 43 | G15: 43 | H15: 1 | I15: 0 | J15: 0 | K15: 进行中 | O15: W011
A16: 12 | B16: 46272 | C16: 46276 | E16: 前端：结算条款管理、协同视览、费用合同签订校验 后端：结算条款管理、协同视览、费用合同签订校验 测试：APP：船舶供应服务查询、船舶预到（内贸）查询、台账查询、停泊费（内贸）查询、船舶供应服务费（内贸）查询 | F16: 23 | G16: 23 | I16: 0 | J16: 0 | K16: 未开始 | O16: W012
A17: 13 | B17: 46279 | C17: 46283 | F17: 16 | G17: 0 | I17: 0 | J17: 0 | K17: 未开始 | O17: W013
A18: 14 | B18: 46286 | C18: 46290 | F18: 6 | G18: 0 | I18: 0 | J18: 0 | K18: 未开始 | O18: W014
A19: 15 | B19: 46293 | C19: 46297 | F19: 0 | G19: 0 | I19: 0 | J19: 0 | K19: 未开始 | O19: W015
A20: 16 | B20: 46300 | C20: 46304 | F20: 14 | G20: 0 | I20: 0 | J20: 0 | K20: 未开始 | O20: W016
A21: 17 | B21: 46307 | C21: 46311 | E21: 前端：船舶唯一性校验、卸船作业、船舶预到（外贸）、退回船舶预到（外贸）、采样申请（外贸）、停泊费（外贸）、锚泊费（外贸）、堆存费（外贸）、卸船费（外贸）、采样服务费（外贸）、船舶供应服务费（外贸） 后端：船舶唯一性校验、卸船作业、船舶预到（外贸）、退回船舶预到（外贸）、采样申请（外贸）、停泊费（外贸）、锚泊费（外贸）、堆存费（外贸）、卸船费（外贸）、采样服务费（外贸）、船舶供应服务费（外贸） 测试：结算条款管理、协同视览、费用合同签订校验 | F21: 8 | G21: 0 | I21: 0 | J21: 0 | K21: 未开始 | O21: W017
A22: 18 | B22: 46314 | C22: 46318 | F22: 16 | G22: 1 | I22: 0 | J22: 0 | K22: 未开始 | O22: W018
A23: 19 | B23: 46321 | C23: 46325 | F23: 0 | G23: 0 | I23: 0 | J23: 0 | K23: 未开始 | O23: W019
A24: 20 | B24: 46328 | C24: 46332 | F24: 0 | G24: 0 | I24: 0 | J24: 0 | K24: 未开始 | O24: W020
A25: 21 | B25: 46335 | C25: 46339 | F25: 70 | G25: 6 | I25: 0 | J25: 0 | K25: 未开始 | O25: W021
A26: 22 | B26: 46342 | C26: 46346 | E26: 测试：船舶唯一性校验、卸船作业、船舶预到（外贸）、退回船舶预到（外贸）、采样申请（外贸）、停泊费（外贸）、锚泊费（外贸）、堆存费（外贸）、卸船费（外贸）、采样服务费（外贸）、船舶供应服务费（外贸） | F26: 0 | G26: 0 | I26: 0 | J26: 0 | K26: 未开始 | O26: W022
A27: 23 | B27: 46349 | C27: 46353 | F27: 53 | G27: 6 | I27: 0 | J27: 0 | K27: 未开始 | O27: W023
A29: 周任务明细
A30: 迭代周 | B30: 任务ID | C30: 任务名称 | D30: 批次 | E30: 专业阶段 | F30: 负责人 | G30: 计划开始 | H30: 计划完成 | I30: 阶段状态 | J30: 总体状态 | K30: 实际完成日期 | L30: 是否延期 | M30: 异常提示 | N30: 复盘说明 | O30: _detail_key
A31: 2 | B31: T001 | C31: 新增车辆信息 | D31: 第一批次 | E31: 业务 | F31: 郑士旺 | G31: 46202 | H31: 46206 | I31: 已完成 | J31: 已完成 | L31: 否 | M31: 完成日期待补充 | O31: W002|tsk-33c582966f67#001|业务
A32: 2 | B32: T002 | C32: 修改车辆信息 | D32: 第一批次 | E32: 业务 | F32: 郑士旺 | G32: 46202 | H32: 46206 | I32: 已完成 | J32: 已完成 | L32: 否 | M32: 完成日期待补充 | O32: W002|tsk-23275116439b#001|业务
A33: 2 | B33: T003 | C33: 删除车辆信息 | D33: 第一批次 | E33: 业务 | F33: 郑士旺 | G33: 46202 | H33: 46206 | I33: 已完成 | J33: 已完成 | L33: 否 | M33: 完成日期待补充 | O33: W002|tsk-f668411c7176#001|业务
A34: 2 | B34: T004 | C34: 查询展示车辆信息 | D34: 第一批次 | E34: 业务 | F34: 郑士旺 | G34: 46202 | H34: 46206 | I34: 已完成 | J34: 已完成 | L34: 否 | M34: 完成日期待补充 | O34: W002|tsk-9344390f42cf#001|业务
A35: 2 | B35: T006 | C35: 优化收费标准（装卸费）新增 | D35: 第一批次 | E35: 业务 | F35: 郑士旺 | G35: 46202 | H35: 46206 | I35: 已完成 | J35: 已完成 | K35: 46224 | L35: 否 | O35: W002|tsk-ed149daad87d#001|业务
A36: 2 | B36: T007 | C36: 优化收费标准（装卸费）编辑 | D36: 第一批次 | E36: 业务 | F36: 郑士旺 | G36: 46202 | H36: 46206 | I36: 已完成 | J36: 已完成 | K36: 46224 | L36: 否 | O36: W002|tsk-97a98e6009e6#001|业务
A37: 2 | B37: T008 | C37: 优化收费标准（装卸费）详情 | D37: 第一批次 | E37: 业务 | F37: 郑士旺 | G37: 46202 | H37: 46206 | I37: 已完成 | J37: 已完成 | K37: 46224 | L37: 否 | O37: W002|tsk-a12265c00afb#001|业务
A38: 2 | B38: T009 | C38: 优化采样方式新增 | D38: 第一批次 | E38: 业务 | F38: 郑士旺 | G38: 46202 | H38: 46206 | I38: 已完成 | J38: 已完成 | K38: 46224 | L38: 否 | O38: W002|tsk-e3cb05a8752f#001|业务
A39: 2 | B39: T010 | C39: 优化采样方式编辑 | D39: 第一批次 | E39: 业务 | F39: 郑士旺 | G39: 46202 | H39: 46206 | I39: 已完成 | J39: 已完成 | K39: 46224 | L39: 否 | O39: W002|tsk-b7577ba49e91#001|业务
A40: 2 | B40: T011 | C40: 获取报单数据及展示 | D40: 第一批次 | E40: 业务 | F40: 郑士旺 | G40: 46202 | H40: 46206 | I40: 已完成 | J40: 已完成 | K40: 46224 | L40: 否 | O40: W002|tsk-7f2aa4709d11#001|业务
A41: 2 | B41: T012 | C41: 应单入口 | D41: 第一批次 | E41: 业务 | F41: 郑士旺 | G41: 46202 | H41: 46206 | I41: 已完成 | J41: 已完成 | K41: 46224 | L41: 否 | O41: W002|tsk-702fd2cdf48f#001|业务
A42: 2 | B42: T050 | C42: 维护需跟踪船舶清单 | D42: 第一批次 | E42: 业务 | F42: 郑士旺 | G42: 46202 | H42: 46206 | I42: 已完成 | J42: 进行中 | L42: 否 | M42: 完成日期待补充 | O42: W002|tsk-d0de99d77921#001|业务
...

Sheet _数据接口
A1: 字段 | B1: 值
A2: Project_ID | B2: ECM-2026
A3: 项目名称 | B3: 能源行业合同全生命周期管理系统
A4: 模块编码 | B4: 02
A5: 生成日期 | B5: 2026-09-16
A6: 中央数据库 | B6: ../90_项目数据中心/ai_pmo.db
A7: 数据日期 | B7: 46281
A8: 可研完成日期 | B8: 46283
