Workbook

Sheet 使用说明
A1: AI PMO中心-20260920-V1 使用说明
A2: 用途 | B2: 整合项目驾驶舱、AI诊断、数据质量、督办和周报，形成项目组合级监控入口。
A3: 适用对象 | B3: 项目集经理、项目经理、PMO、治理委员会和数据维护人
A4: 更新频率 | B4: 上游台账更新并核对当前版本登记后刷新；全量与成本分别运行，默认仅预览；周报发布前检查数据质量。
A5: 颜色约定 | B5: 浅蓝为表头；黄色为人工输入；图表和汇总来自上游或运行结果。
A7: 推荐使用流程
A8: 1 | B8: 先在各领域权威台账维护事实和人工审批结论；数据库与本工作簿不替代源台账。
A9: 2 | B9: 执行标准刷新程序 sync_all_to_ai_pmo.py，将进度、门禁、风险、决策、相关方、前 5 项里程碑及管理关注点同步至本工作簿_data接口；成本指标请使用单独成本同步程序
A10: 3 | B10: 核对当前版本登记、刷新日期和数据质量检查；存在缺失、重复、状态日期异常时先回源处理。
A11: 4 | B11: 查看项目驾驶舱和AI项目诊断，识别红黄项
A12: 5 | B12: 形成两周督办及PMO周报，明确责任人和期限
A13: 6 | B13: 正式刷新在安全检查与备份后追加运行记录；人工确认意见在源台账或约定人工区维护，不由程序代填。
A15: 工作表 | B15: 用途 | C15: 维护提示
A16: 项目驾驶舱 | B16: 查看进度、风险、资源、质量和成本等综合指标。 | C16: 全量与成本分别刷新后，核对统计日期、来源文件、关键指标和图表。
A17: AI项目诊断 | B17: 汇总项目异常、成因、影响和建议动作。 | C17: 诊断结论须由项目经理确认。
A18: 数据质量检查 | B18: 检查缺失字段、非法状态、重复编号和跨表不一致。 | C18: 先处理阻断级错误，再处理提示项。
A19: 两周督办 | B19: 聚焦未来两周到期、逾期和关键门禁事项。 | C19: 每项必须有责任人、期限和状态。
A20: PMO周报 | B20: 形成治理层周度汇报。 | C20: 发布前核对数据日期、结论和待决策事项。
A21: AI运行日志 | B21: 记录刷新时间、输入文件、结果、异常和处理状态。 | C21: 自动刷新后必须新增一条日志，不覆盖历史。
A22: _数据接口 | B22: 供Python程序读取PMO状态和版本信息。 | C22: 仅供程序读取和刷新；不作为人工事实的唯一录入点。
A24: 维护与检查规则
A25: 1 | B25: 上游模块是事实来源，AI PMO中心不替代业务台账。
A26: 2 | B26: 运行日志必须写入，失败运行也要记录错误原因。
A27: 3 | B27: 发现数据日期落后、文件缺失或字段变化时停止发布周报。
A28: 4 | B28: 图表、诊断和督办项必须能追溯至来源模块和记录编号。
A29: 5 | B29: 周报发布前检查公式错误、空责任人、逾期事项和未决策事项。
A30: 6 | B30: 版本升级后将被替换文件移入本模块_archive目录。

Sheet 项目驾驶舱
A1: 能源行业合同全生命周期管理系统｜AI PMO项目驾驶舱
A3: 统计日期 | B3: 46311
A5: 总任务数 | B5: 已完成 | C5: 进行中 | D5: 未开始/待确认 | E5: 暂停/挂起 | F5: 平均进度 | G5: 已延期 | H5: 14天内到期 | I5: 重大风险 | J5: 高风险 | K5: 未关闭门禁 | L5: 待决策 | M5: 里程碑完成 | N5: 项目健康度
A6: ='_数据接口'!B11 -> 135 | B6: ='_数据接口'!B22 | C6: ='_数据接口'!B23 | D6: ='_数据接口'!B24 | E6: ='_数据接口'!B25 -> 0 | F6: ='_数据接口'!B26 | G6: ='_数据接口'!B27 | H6: ='_数据接口'!B28 -> 5 | I6: ='_数据接口'!B33 -> 1 | J6: ='_数据接口'!B34 -> 8 | K6: ='_数据接口'!B35 -> 20 | L6: ='_数据接口'!B14 -> 4 | M6: ='_数据接口'!B37&"/"&'_数据接口'!B36 -> 3/17 | N6: ='_数据接口'!B38 -> 红
A8: 综合进度 | B8: 计划投入人天 | C8: 计划人工成本 | D8: 人日单价 | E8: 必过门禁未通过 | F8: 重点相关方 | G8: 不支持相关方 | H8: 沟通逾期 | I8: 已量化总预算 | J8: 迭代承诺完成率 | K8: 迭代负载率 | L8: 预测超基线任务 | M8: 平均偏差天数 | N8: 当前迭代周
A9: ='_数据接口'!B26 | B9: ='_数据接口'!B17 -> 4337 | C9: ='_数据接口'!B18 -> 6070900 | D9: ='_数据接口'!B19 -> 1399.7925 | E9: ='_数据接口'!B29 -> 17 | F9: ='_数据接口'!B30 -> 4 | G9: ='_数据接口'!B31 -> 0 | H9: ='_数据接口'!B32 -> 34 | I9: ='_数据接口'!B43 -> 15252170 | J9: ='_数据接口'!B44 -> 0.25 | K9: ='_数据接口'!B45 -> 1.3333 | L9: ='_数据接口'!B46 -> 0 | M9: ='_数据接口'!B47 | N9: ='_数据接口'!B48 -> 2026-W40
A11: 任务状态 | B11: 数量 | C11: 管理判断 | E11: 风险与门禁 | F11: 数量 | G11: 管理判断 | I11: 里程碑 | J11: 计划完成 | K11: 状态 | L11: 健康度 | M11: 责任人
A12: 已完成 | B12: ='_数据接口'!B22 | C12: 以验收证据为准 | E12: 重大剩余风险 | F12: ='_数据接口'!B33 -> 1 | G12: 立即升级指导委员会 | I12: 可研工作启动 | J12: 46063 | K12: 已完成 | L12: 绿 | M12: 项目经理
A13: 进行中 | B13: ='_数据接口'!B23 | C13: 跟踪承诺日期 | E13: 高剩余风险 | F13: ='_数据接口'!B34 -> 8 | G13: 每周检查应对证据 | I13: 可行性研究完成 | J13: 46283 | K13: 已完成 | L13: 绿 | M13: 项目经理
A14: 未开始/待确认 | B14: ='_数据接口'!B24 | C14: 确认历史任务实际状态 | E14: 趋势上升风险 | F14: 1 | G14: 触发专项评审 | I14: 原业务梳理完成 | J14: 46295 | K14: 进行中 | L14: 绿 | M14: 产品经理
A15: 暂停/挂起 | B15: ='_数据接口'!B25 -> 0 | C15: 必须记录恢复条件 | E15: 必过门禁未通过 | F15: ='_数据接口'!B29 -> 17 | G15: 未关闭不得正式启动 | I15: 项目规范基线确认 | J15: 46265 | K15: 已完成 | L15: 绿 | M15: 项目经理
A16: 已延期 | B16: ='_数据接口'!B27 | C16: 制定纠偏或基线变更 | E16: 待决策事项 | F16: ='_数据接口'!B14 -> 4 | G16: 按需要日期完成决策 | I16: 技术架构基线确认 | J16: 46295 | K16: 进行中 | L16: 绿 | M16: 技术经理
A18: 管理关注点 | I18: 迁移来源线索 | J18: 已盘点来源 | K18: G15目标日期 | L18: 迁移门禁
A19: 序号 | B19: 关注事项 | C19: 下一步 | D19: 责任人 | E19: 等级 | I19: ='_数据接口'!B39 | J19: ='_数据接口'!B40 | K19: ='_数据接口'!B41 -> 2026-10-13 | L19: ='_数据接口'!B42
A20: 1 | B20: CA、电子文档、BI产品选型 | C20: 2026-09-25 前完成决策：按产品类别择优入围，安全合规不通过即淘汰 | D20: 项目指导委员会 | E20: 重大
A21: 2 | B21: 项目预算与采购路径 | C21: 2026-10-08 前完成决策：按产品分项验收，付款绑定可验证交付物 | D21: 项目发起人 | E21: 重大
A22: 3 | B22: 一期范围与P0需求基线 | C22: 2026-10-09 前完成决策：以P0业务闭环为一期基线，P1/P2进入后续版本 | D22: 业务负责人/项目发起人 | E22: 重大
A23: 4 | B23: 安全合规基线未形成或外部产品不满足要求 | C23: 最迟 2026-10-13 完成应对（策略：规避） | D23: 技术经理 | E23: 重大
A24: 5 | B24: 2026年10月20日正式启动决策 | C24: 2026-10-16 前完成决策：必过项全部关闭后通过；例外须有书面批准和补救期限 | D24: 项目指导委员会 | E24: 重大

Sheet AI项目诊断
A1: AI项目诊断
A2: ="数据截止"&'_数据接口'!B5&"。客观状态根据总控、风险和启动门禁快照形成，管理结论须由项目经理确认。" -> 数据截止2026-10-16。客观状态根据总控、风险和启动门禁快照形成，管理结论须由项目经理确认。
A4: 数据日期 | B4: ='_数据接口'!B5 -> 2026-10-16 | D4: 项目经理判断 | E4: 待确认 | G4: 总体判断 | H4: 项目当前为红色：正式启动前的基线、POC、风险和门禁证据尚未闭环。
A6: 任务总数 | B6: 已完成任务 | C6: 逾期任务 | D6: 14天内到期 | E6: 重大风险 | F6: 高风险 | G6: 必过门禁未通过 | H6: 待决策事项
A7: ='_数据接口'!B11 -> 135 | B7: ='_数据接口'!B22 -> 12 | C7: ='_数据接口'!B27 -> 17 | D7: ='_数据接口'!B28 -> 5 | E7: ='_数据接口'!B33 -> 1 | F7: ='_数据接口'!B34 -> 8 | G7: ='_数据接口'!B29 -> 17 | H7: ='_数据接口'!B14 -> 4
A10: 维度 | B10: 状态 | C10: 客观判断 | D10: 触发规则 | E10: 建议动作 | F10: 责任角色 | H10: 状态 | I10: 数量
A11: 进度 | B11: 红 | C11: ='_数据接口'!B27&"项任务已延期或计划完成日已过" -> 17项任务已延期或计划完成日已过 | D11: 红色需升级；黄色需纠偏；绿色保持监控 | E11: 先确认历史任务实际状态，再形成纠偏或基线变更 | F11: 项目经理 | H11: 绿 | I11: 1
A12: 风险 | B12: 红 | C12: ='_数据接口'!B33&"项重大、"&'_数据接口'!B34&"项高剩余风险" -> 1项重大、8项高剩余风险 | D12: 红色需升级；黄色需纠偏；绿色保持监控 | E12: 重大风险提请指导委员会审议 | F12: 风险责任人 | H12: 黄 | I12: 0
A13: 启动准备 | B13: 红 | C13: ='_数据接口'!B29&"项必过门禁尚未通过" -> 17项必过门禁尚未通过 | D13: 红色需升级；黄色需纠偏；绿色保持监控 | E13: 按10月16日门禁评审倒排证据提交 | F13: 项目集经理 | H13: 红 | I13: 5
A14: 决策 | B14: 红 | C14: ='_数据接口'!B14&"项事项等待管理层决策" -> 4项事项等待管理层决策 | D14: 红色需升级；黄色需纠偏；绿色保持监控 | E14: 按需要日期准备方案和推荐意见 | F14: 项目集经理 | H14: 灰 | I14: 0
A15: 数据 | B15: 红 | C15: 28项历史任务缺少实际状态或问题说明 | D15: 红色需升级；黄色需纠偏；绿色保持监控 | E15: 在源总控台账补齐状态、实际日期和说明 | F15: 台账维护人
A16: 相关方 | B16: 绿 | C16: ='_数据接口'!B30&"名重点管理相关方，"&'_数据接口'!B31&"名不支持" -> 4名重点管理相关方，0名不支持 | D16: 红色需升级；黄色需纠偏；绿色保持监控 | E16: 持续执行分层沟通并记录结果 | F16: 项目经理

Sheet 数据质量检查
A1: 数据质量检查
A2: 自动检查模块文件、模块编号、重复ID、状态、负责人、日期及逾期任务执行证据。请在源台账修正后重新运行刷新。
A4: 来源 | B4: 记录ID | C4: 任务名称 | D4: 责任人 | E4: 计划开始 | F4: 计划完成 | G4: 发现的问题 | H4: 检查状态 | I4: 建议动作 | J4: 源行号
A5: G15-会前签认跟踪-20260924-V1.xlsx | B5: MODULE-CODE | C5: 模块编号检查 | D5: 项目经理 | G5: 缺少_data接口工作表 | H5: 阻断 | I5: 补充_data接口并填写模块编号 | J5: -
A6: 安全合规会签清单-20260924-V1.xlsx | B6: MODULE-CODE | C6: 模块编号检查 | D6: 项目经理 | G6: 缺少_data接口工作表 | H6: 阻断 | I6: 补充_data接口并填写模块编号 | J6: -
A7: 厂商报价对比-20260924-V1.xlsx | B7: MODULE-CODE | C7: 模块编号检查 | D7: 项目经理 | G7: 缺少_data接口工作表 | H7: 阻断 | I7: 补充_data接口并填写模块编号 | J7: -
A8: POC评分表-20260924-V1.xlsx | B8: MODULE-CODE | C8: 模块编号检查 | D8: 项目经理 | G8: 缺少_data接口工作表 | H8: 阻断 | I8: 补充_data接口并填写模块编号 | J8: -
A9: 开发前检查清单-20261008-V1.xlsx | B9: MODULE-CODE | C9: 模块编号检查 | D9: 项目经理 | G9: 缺少_data接口工作表 | H9: 阻断 | I9: 补充_data接口并填写模块编号 | J9: -
A10: 项目总控台账 | B10: T011 | C10: 盘点既有系统、接口与数据 | D10: 技术经理 | E10: 46120 | F10: 46147 | G10: 计划完成日已过，执行状态和实际证据未确认 | H10: 需整改 | I10: 补充实际状态、实际日期、问题/阻塞及完成证据 | J10: 14
A11: 项目总控台账 | B11: T014 | C11: 制定项目治理、会议与报告机制 | D11: 项目经理 | E11: 46204 | F11: 46215 | G11: 计划完成日已过，执行状态和实际证据未确认 | H11: 需整改 | I11: 补充实际状态、实际日期、问题/阻塞及完成证据 | J11: 17
A12: 项目总控台账 | B12: T015 | C12: 制定需求分级、跟踪与变更规范 | D12: 产品经理 | E12: 46216 | F12: 46227 | G12: 计划完成日已过，执行状态和实际证据未确认 | H12: 需整改 | I12: 补充实际状态、实际日期、问题/阻塞及完成证据 | J12: 18
A13: 项目总控台账 | B13: T016 | C13: 制定设计、编码与代码评审规范 | D13: 技术经理 | E13: 46228 | F13: 46240 | G13: 计划完成日已过，执行状态和实际证据未确认 | H13: 需整改 | I13: 补充实际状态、实际日期、问题/阻塞及完成证据 | J13: 19
A14: 项目总控台账 | B14: T017 | C14: 制定测试、缺陷与质量门禁规范 | D14: 高级测试人员、中级测试人员 | E14: 46241 | F14: 46252 | G14: 计划完成日已过，执行状态和实际证据未确认 | H14: 需整改 | I14: 补充实际状态、实际日期、问题/阻塞及完成证据 | J14: 20
A15: 项目总控台账 | B15: T018 | C15: 制定配置、发布与文档归档规范 | D15: 配置人员 | E15: 46253 | F15: 46265 | G15: 计划完成日已过，执行状态和实际证据未确认 | H15: 需整改 | I15: 补充实际状态、实际日期、问题/阻塞及完成证据 | J15: 21
A16: 项目总控台账 | B16: T019 | C16: 完成系统分层、模块与服务边界设计 | D16: 技术经理 | E16: 46204 | F16: 46218 | G16: 计划完成日已过，执行状态和实际证据未确认 | H16: 需整改 | I16: 补充实际状态、实际日期、问题/阻塞及完成证据 | J16: 22
A17: 项目总控台账 | B17: T020 | C17: 完成主数据、交易数据与分析数据架构 | D17: 技术经理 | E17: 46219 | F17: 46233 | G17: 计划完成日已过，执行状态和实际证据未确认 | H17: 需整改 | I17: 补充实际状态、实际日期、问题/阻塞及完成证据 | J17: 23
A18: 项目总控台账 | B18: T021 | C18: 完成内部及外部接口总体架构 | D18: 高级开发人员 | E18: 46234 | F18: 46249 | G18: 计划完成日已过，执行状态和实际证据未确认 | H18: 需整改 | I18: 补充实际状态、实际日期、问题/阻塞及完成证据 | J18: 24
A19: 项目总控台账 | B19: T022 | C19: 完成身份、权限、审计与数据安全设计 | D19: 技术经理 | E19: 46250 | F19: 46264 | G19: 计划完成日已过，执行状态和实际证据未确认 | H19: 需整改 | I19: 补充实际状态、实际日期、问题/阻塞及完成证据 | J19: 25
A20: 项目总控台账 | B20: T023 | C20: 完成环境、网络、容灾和DevOps设计 | D20: 配置人员 | E20: 46265 | F20: 46279 | G20: 计划完成日已过，执行状态和实际证据未确认 | H20: 需整改 | I20: 补充实际状态、实际日期、问题/阻塞及完成证据 | J20: 26
A21: 项目总控台账 | B21: T024 | C21: 汇编总体技术架构并完成基线评审 | D21: 技术经理 | E21: 46280 | F21: 46295 | G21: 计划完成日已过，执行状态和实际证据未确认 | H21: 需整改 | I21: 补充实际状态、实际日期、问题/阻塞及完成证据 | J21: 27
... A34: 项目总控台账 | B34: T037 | C34: 建立风险、问题、变更和决策台账 | D34: 项目经理 | E34: 46306 | F34: 46308 | G34: 计划完成日已过，执行状态和实际证据未确认 | H34: 需整改 | I34: 补充实际状态、实际日期、问题/阻塞及完成证据 | J34: 40

Sheet 两周督办
A1: 两周督办
A2: 纳入已延期任务及未来14天到期的未完成任务；承诺日期和完成证据由责任人维护。
A4: 是否纳入 | B4: 任务ID | C4: 任务名称 | D4: 里程碑 | E4: 总体状态 | F4: 主责人 | G4: 计划完成 | H4: 距截止天数 | I4: 延期状态 | J4: 当前问题/阻塞 | K4: 建议动作 | L4: 承诺完成 | M4: 完成证据
A5: 是 | B5: T011 | C5: 盘点既有系统、接口与数据 | D5: MS003 | E5: 进行中 | F5: 技术经理 | G5: 46147 | H5: -164 | I5: 已延期 | K5: 确认实际状态；完成、纠偏或提交基线变更
A6: 是 | B6: T014 | C6: 制定项目治理、会议与报告机制 | D6: MS004 | E6: 待确认 | F6: 项目经理 | G6: 46215 | H6: -96 | I6: 已延期 | K6: 确认实际状态；完成、纠偏或提交基线变更
A7: 是 | B7: T019 | C7: 完成系统分层、模块与服务边界设计 | D7: MS005 | E7: 待确认 | F7: 技术经理 | G7: 46218 | H7: -93 | I7: 已延期 | K7: 确认实际状态；完成、纠偏或提交基线变更
A8: 是 | B8: T015 | C8: 制定需求分级、跟踪与变更规范 | D8: MS004 | E8: 待确认 | F8: 产品经理 | G8: 46227 | H8: -84 | I8: 已延期 | K8: 确认实际状态；完成、纠偏或提交基线变更
A9: 是 | B9: T020 | C9: 完成主数据、交易数据与分析数据架构 | D9: MS005 | E9: 待确认 | F9: 技术经理 | G9: 46233 | H9: -78 | I9: 已延期 | K9: 确认实际状态；完成、纠偏或提交基线变更
A10: 是 | B10: T016 | C10: 制定设计、编码与代码评审规范 | D10: MS004 | E10: 待确认 | F10: 技术经理 | G10: 46240 | H10: -71 | I10: 已延期 | K10: 确认实际状态；完成、纠偏或提交基线变更
A11: 是 | B11: T021 | C11: 完成内部及外部接口总体架构 | D11: MS005 | E11: 待确认 | F11: 高级开发人员 | G11: 46249 | H11: -62 | I11: 已延期 | K11: 确认实际状态；完成、纠偏或提交基线变更
A12: 是 | B12: T017 | C12: 制定测试、缺陷与质量门禁规范 | D12: MS004 | E12: 待确认 | F12: 高级测试人员、中级测试人员 | G12: 46252 | H12: -59 | I12: 已延期 | K12: 确认实际状态；完成、纠偏或提交基线变更
A13: 是 | B13: T025 | C13: 编制CA、电子文档、BI报表POC方案与评分标准 | D13: MS017 | E13: 待确认 | F13: 技术经理 | G13: 46253 | H13: -58 | I13: 已延期 | K13: 确认实际状态；完成、纠偏或提交基线变更
A14: 是 | B14: T026 | C14: 验证证书签发、身份认证和证书管理 | D14: MS017 | E14: 待确认 | F14: 高级开发人员 | G14: 46258 | H14: -53 | I14: 已延期 | K14: 确认实际状态；完成、纠偏或提交基线变更
A15: 是 | B15: T027 | C15: 验证电子签名、验签、时间戳和审计追溯 | D15: MS017 | E15: 待确认 | F15: 高级测试人员、中级测试人员 | G15: 46263 | H15: -48 | I15: 已延期 | K15: 确认实际状态；完成、纠偏或提交基线变更
A16: 是 | B16: T022 | C16: 完成身份、权限、审计与数据安全设计 | D16: MS005 | E16: 待确认 | F16: 技术经理 | G16: 46264 | H16: -47 | I16: 已延期 | K16: 确认实际状态；完成、纠偏或提交基线变更
... A34: 是 | B34: T042 | C34: 开展业务场景与用户需求工作坊 | D34: MS008 | E34: 未开始 | F34: 产品经理 | G34: 46321 | H34: 10 | I34: 正常 | K34: 按计划提交可验收证据

Sheet PMO周报
A1: PMO周报
A2: ="数据截止"&_数据接口!B5&"。面向项目领导，重点呈现状态、风险、决策和未来两周行动。"
B3: ='_数据接口'!B5 -> 2026-10-16
A4: 报告日期 | B4: 46281
A5: 项目状态 | B5: 红
A6: 状态说明 | B6: 正式启动前仍有17项必过门禁未通过、1项重大剩余风险和4项待决策事项。
A8: 一、本周总体判断
A9: 项目总体为红色。最大失控点是历史计划执行状态未及时回写，同时POC选型、技术架构、预算资源和启动门禁尚未形成批准证据。
A12: 二、本周完成事项
A13: 完成相关方管理整合、POC评分工具、启动门禁清单以及风险问题闭环工具，并同步形成12项风险和4项待决策事项。
A16: 三、未来两周重点
A17: 完成POC评分与选型建议；关闭架构评审意见；确认30人团队到位计划；完成章程、范围、预算和风险治理材料。
A20: 四、主要风险与问题
A21: 重大剩余风险1项，高剩余风险8项。重点关注安全合规基线、外部接口联调窗口、POC选型和项目正式授权。
A24: 五、待决策与需协调事项
A25: 需决定CA/电子文档/BI产品选型、一期P0范围、项目预算与采购路径，以及2026年10月20日正式启动结论。
A28: 自动指标 | B28: 本期值 | C28: 管理含义
A29: 任务完成率 | B29: =IF('_数据接口'!B11=0,0,'_数据接口'!B22/'_数据接口'!B11) -> 0.088888889 | C29: 观察总体交付进展
A30: 逾期任务数 | B30: ='_数据接口'!B27 -> 17 | C30: 确认实际状态并制定纠偏
A31: 重大/高剩余风险 | B31: ='_数据接口'!B33+'_数据接口'!B34 -> 9 | C31: 确认应对责任和升级需求
A32: 必过门禁未通过 | B32: ='_数据接口'!B29 -> 17 | C32: 未关闭不得正式启动
A33: 待决策事项 | B33: ='_数据接口'!B14 -> 4 | C33: 明确决策人和最迟日期
A34: 数据质量问题 | B34: ='_数据接口'!B27 -> 17 | C34: 提高AI诊断可信度
A35: 迭代承诺完成率 | B35: ='_数据接口'!B44 -> 0.25 | C35: 周承诺兑现情况
A36: 迭代负载率 | B36: ='_数据接口'!B45 -> 1.3333 | C36: 超100%为排产超负荷
A37: 预测超基线任务 | B37: ='_数据接口'!B46 -> 0 | C37: 预测完成晚于基线的任务数

Sheet AI运行日志
A1: AI运行日志
A2: 记录每次AI分析的输入范围、发现、建议、人工确认和处理结果，便于追踪与复盘。
A4: 运行ID | B4: 运行时间 | C4: 分析类型 | D4: 数据日期 | E4: 分析范围 | F4: 主要发现 | G4: 风险等级 | H4: AI建议 | I4: 人工结论 | J4: 处理人 | K4: 处理状态 | L4: 完成时间
A5: RUN-20260916-001 | B5: 46281 | C5: 项目综合诊断 | D5: 46281 | E5: 里程碑、总控、资源、相关方、门禁、风险和决策 | F5: 项目健康度为红；必过门禁、重大风险和待决策事项尚未闭环 | G5: 高 | H5: 按9月25日、9月30日和10月16日三个节点推进POC、架构和启动门禁 | I5: 待项目经理确认 | J5: 项目经理 | K5: 待处理
A6: RUN-20260918-001 | B6: 46283.676 | C6: 全量刷新与质检 | D6: 46283 | E6: 里程碑、总控、门禁、风险、决策、相关方、成本及模块完整性 | F6: 发现28项数据质量问题，其中0项阻断、28项需整改；28项任务已延期 | G6: 高 | H6: 优先处理阻断项，并由任务负责人补齐逾期任务的实际状态、日期和完成证据 | I6: 待项目经理确认 | J6: 项目经理
A7: RUN-20260918-002 | B7: 46283.694 | C7: 全量刷新与质检 | D7: 46283 | E7: 里程碑、总控、门禁、风险、决策、相关方、成本及模块完整性 | F7: 发现28项数据质量问题，其中0项阻断、28项需整改；28项任务已延期 | G7: 高 | H7: 优先处理阻断项，并由任务负责人补齐逾期任务的实际状态、日期和完成证据 | I7: 待项目经理确认 | J7: 项目经理
A8: RUN-20260922-001 | B8: 46287.361 | C8: 全量刷新与质检 | D8: 46287 | E8: 里程碑、总控、门禁、风险、决策、相关方及模块完整性 | F8: 发现31项数据质量问题，其中1项阻断、30项需整改；28项任务已延期 | G8: 高 | H8: 优先处理阻断项，并由任务负责人补齐逾期任务的实际状态、日期和完成证据 | I8: 待项目经理确认 | J8: 项目经理
A9: RUN-20260923-001 | B9: 46288.472 | C9: 全量刷新与质检 | D9: 46288 | E9: 里程碑、总控、门禁、风险、决策、相关方及模块完整性 | F9: 发现21项数据质量问题，其中0项阻断、21项需整改；19项任务已延期 | G9: 高 | H9: 优先处理需整改事项，并由任务负责人补齐逾期任务的实际状态、日期和完成证据 | I9: 待项目经理确认 | J9: 项目经理
A10: RUN-20260923-002 | B10: 46288.482 | C10: 全量刷新与质检 | D10: 46288 | E10: 里程碑、总控、门禁、风险、决策、相关方及模块完整性 | F10: 发现21项数据质量问题，其中0项阻断、21项需整改；19项任务已延期 | G10: 高 | H10: 优先处理需整改事项，并由任务负责人补齐逾期任务的实际状态、日期和完成证据 | I10: 待项目经理确认 | J10: 项目经理
A11: RUN-20260923-003 | B11: 46288.855 | C11: 全量刷新与质检 | D11: 46288 | E11: 里程碑、总控、门禁、风险、决策、相关方及模块完整性 | F11: 发现21项数据质量问题，其中0项阻断、21项需整改；19项任务已延期 | G11: 高 | H11: 优先处理需整改事项，并由任务负责人补齐逾期任务的实际状态、日期和完成证据 | I11: 待项目经理确认 | J11: 项目经理
A12: RUN-20260923-004 | B12: 46288.858 | C12: 全量刷新与质检 | D12: 46288 | E12: 里程碑、总控、门禁、风险、决策、相关方及模块完整性 | F12: 发现21项数据质量问题，其中0项阻断、21项需整改；19项任务已延期 | G12: 高 | H12: 优先处理需整改事项，并由任务负责人补齐逾期任务的实际状态、日期和完成证据 | I12: 待项目经理确认 | J12: 项目经理
A13: RUN-20260923-005 | B13: 46288.871 | C13: 全量刷新与质检 | D13: 46288 | E13: 里程碑、总控、门禁、风险、决策、相关方及模块完整性 | F13: 发现21项数据质量问题，其中0项阻断、21项需整改；19项任务已延期 | G13: 高 | H13: 优先处理需整改事项，并由任务负责人补齐逾期任务的实际状态、日期和完成证据 | I13: 待项目经理确认 | J13: 项目经理
A14: RUN-20260924-001 | B14: 46289.456 | C14: 全量刷新与质检 | D14: 46289 | E14: 里程碑、总控、门禁、风险、决策、相关方及模块完整性 | F14: 发现25项数据质量问题，其中4项阻断、21项需整改；19项任务已延期 | G14: 高 | H14: 优先处理阻断项，并由任务负责人补齐逾期任务的实际状态、日期和完成证据 | I14: 待项目经理确认 | J14: 项目经理
A15: RUN-20261016-001 | B15: 46311.636 | C15: 全量刷新与质检 | D15: 46311 | E15: 里程碑、总控、门禁、风险、决策、相关方及模块完整性 | F15: 发现30项数据质量问题，其中5项阻断、25项需整改；17项任务已延期 | G15: 高 | H15: 优先处理阻断项，并由任务负责人补齐逾期任务的实际状态、日期和完成证据 | I15: 待项目经理确认 | J15: 项目经理
A101: =IF(B101="","","AI-"&TEXT(ROW()-4,"0000"))
A102: =IF(B102="","","AI-"&TEXT(ROW()-4,"0000"))
A103: =IF(B103="","","AI-"&TEXT(ROW()-4,"0000"))
A104: =IF(B104="","","AI-"&TEXT(ROW()-4,"0000"))

Sheet _数据接口
A1: 字段 | B1: 值
A2: Project_ID | B2: ECM-2026
A3: 项目名称 | B3: 能源行业合同全生命周期管理系统
A4: 模块编码 | B4: 11
A5: 数据日期 | B5: 2026-10-16
A6: 数据模式 | B6: 跨工作簿快照（刷新程序联动）
A7: 里程碑来源 | B7: 02_计划与进度管理/计划与进度管理-20260921-V1.xlsx
A8: 启动门禁来源 | B8: 01_项目启动与治理/项目启动与治理-20260917-V1.xlsx
A9: 风险来源 | B9: 06_风险问题与变更/风险管理-20260918-V1.xlsx
A10: 刷新说明 | B10: 源台账更新后运行 automation/scripts/sync_all_to_ai_pmo.py
A11: 总任务数 | B11: 135
A12: 风险总数 | B12: 12
A13: 启动门禁数 | B13: 20
A14: 待决策数 | B14: 4
A15: 生成日期 | B15: 2026-10-16
A16: 成本来源文件 | B16: 05_成本与合同管理/成本与合同管理-20260918-V5.xlsx
A17: 计划人天 | B17: 4337
A18: 计划人工成本 | B18: 6070900
A19: 平均人日单价 | B19: 1399.7925
A20: 成本数据日期 | B20: 2026-09-24
A21: 成本联动状态 | B21: 已同步
A22: 已完成任务 | B22: 12
A23: 进行中任务 | B23: 3
A24: 未开始/待确认任务 | B24: 120
A25: 暂停/挂起任务 | B25: 0
A26: 平均进度 | B26: 0.1
A27: 已延期任务 | B27: 17
A28: 14天内到期 | B28: 5
A29: 必过门禁未通过 | B29: 17
A30: 重点相关方 | B30: 4
A31: 不支持相关方 | B31: 0
A32: 沟通逾期 | B32: 34
A33: 重大剩余风险 | B33: 1
... A37: 已完成里程碑 | B37: 3
A38: 项目健康度 | B38: 红
A39: 迁移来源线索数
A40: 已盘点来源系统数
A41: G15目标日期 | B41: 2026-10-13
A42: 迁移门禁数
A43: 已量化总预算 | B43: 15252170
...
